Workbook

Sheet Dashboard
A1: GHEE PRODUCTION & AVERAGE DASHBOARD
BA2: Date | BB2: Shift | BC2: Nira Bhima | BD2: Bhodani + Alephata + Jalgaon | BE2: Gagargaon | BF2: Indapur / Madha | BG2: Kalewadi | BH2: Total Milk | BI2: FAT | BJ2: SNF | BK2: Consumed Milk | BL2: Waste | BM2: Butter / Culture | BN2: Milk for Ghee Process | BO2: Ghee Produced | BP2: Ghee Average | BR2: Date | BS2: Shift | BT2: Nira Bhima | BU2: Bhodani + Alephata + Jalgaon | BV2: Gagargaon | BW2: Indapur / Madha | BX2: Kalewadi | BY2: Total Milk | BZ2: FAT | CA2: SNF | CB2: Consumed Milk | CC2: Waste | CD2: Butter / Culture | CE2: Milk for Ghee Process | CF2: Ghee Produced | CG2: Ghee Average | EI2: Date | EJ2: Daily Milk | EL2: Date | EM2: M Milk | EN2: E Milk | EP2: Date | EQ2: Ghee Produced | ES2: Date | ET2: Ghee Average | EV2: Date | EW2: Milk for Ghee | EX2: Ghee Produced | EZ2: Location | FA2: Milk | FC2: Shift | FD2: Ghee Produced | FF2: Month | FG2: Total Milk | FI2: Month | FJ2: Ghee Produced | FL2: Month | FM2: Avg Ghee Average
BA3: {=_xlfn.LET(_xlpm.lr,MAX(_xlfn.XMATCH(TRUE,'Ghee Avarage'!A:A<>"",0,-1),_xlfn.XMATCH(TRUE,'Ghee Avarage'!B:B<>"",0,-1),_xlfn.XMATCH(TRUE,'Ghee Avarage'!P:P<>"",0,-1)),_xlpm.src,'Ghee Avarage'!A3:INDEX('Ghee Avarage'!Q:Q,_xlpm.lr),_xlpm.rd,_xlfn.CHOOSECOLS(_xlpm.src,1),_xlpm.sh,UPPER(TRIM(_xlfn.CHOOSECOLS(_xlpm.src,2)&"")),_xlpm.dt,_xlfn.SCAN("",_xlpm.rd,_xlfn.LAMBDA(_xlpm.a,_xlpm.x,IF(ISNUMBER(_xlpm.x),_xlpm.x,_xlpm.a))),_xlpm.core,_xlfn.CHOOSECOLS(_xlpm.src,3,4,5,6,7,8,9,10,12,13,14,15,16,17),_xlpm.cl,IF(ISBLANK(_xlpm.core),"",IFERROR(_xlpm.core,"")),_xlpm.ok,IFERROR(ISNUMBER(_xlpm.dt)*(_xlpm.dt>30000)*ISNUMBER(_xlfn.XMATCH(_xlpm.sh,{"M","E"}))*_xlfn.BYROW(_xlpm.cl,_xlfn.LAMBDA(_xlpm.r,SUM(--ISNUMBER(_xlpm.r)*--IFERROR(_xlpm.r<>0,FALSE))>0)),FALSE),_xlfn._xlws.FILTER(_xlfn.HSTACK(_xlpm.dt,_xlpm.sh,_xlpm.cl),_xlpm.ok))} -> 46023 | BB3: M | BC3: 232.6 | BD3: 1446.1 | BE3: 424.2 | BF3: 2307.3 | BH3: 4410.2 | BK3: 15 | BN3: 14084.7 | BO3: 573.56 | BP3: 24.556629 | BR3: {=_xlfn.LET(_xlpm.x,_xlfn.ANCHORARRAY($BA$3),_xlpm.dt,_xlfn.CHOOSECOLS(_xlpm.x,1),_xlpm.sh,_xlfn.CHOOSECOLS(_xlpm.x,2),_xlpm.keep,(_xlpm.dt>=$A$5)*(_xlpm.dt<=$C$5)*IF($E$5="All",1,YEAR(_xlpm.dt)=--$E$5)*IF($G$5="All",1,TEXT(_xlpm.dt,"mmm")=$G$5)*IF($I$5="All",1,WEEKNUM(_xlpm.dt,2)=--$I$5)*IF($K$5="All",1,_xlpm.sh=$K$5),_xlfn._xlws.FILTER(_xlpm.x,_xlpm.keep,_xlfn.EXPAND("",1,16,"")))} -> 46023 | BS3: M | BT3: 232.6 | BU3: 1446.1 | BV3: 424.2 | BW3: 2307.3 | BY3: 4410.2 | CB3: 15 | CE3: 14084.7 | CF3: 573.56 | CG3: 24.556629 | EI3: {=_xlfn.CHOOSECOLS(_xlfn.ANCHORARRAY($R$61),1,2)} -> 46023 | EJ3: 9426.2 | EL3: {=_xlfn.LET(_xlpm.v,_xlfn.ANCHORARRAY($BR$3),_xlpm.dt,_xlfn.CHOOSECOLS(_xlpm.v,1),_xlpm.sh,_xlfn.CHOOSECOLS(_xlpm.v,2),_xlpm.m,_xlfn.CHOOSECOLS(_xlpm.v,8),_xlpm.u,_xlfn._xlws.SORT(_xlfn.UNIQUE(_xlfn._xlws.FILTER(_xlpm.dt,_xlpm.dt>0))),_xlfn.HSTACK(_xlpm.u,_xlfn.MAP(_xlpm.u,_xlfn.LAMBDA(_xlpm.x,SUM(_xlfn._xlws.FILTER(_xlpm.m,(_xlpm.dt=_xlpm.x)*(_xlpm.sh="M"),0)))),_xlfn.MAP(_xlpm.u,_xlfn.LAMBDA(_xlpm.x,SUM(_xlfn._xlws.FILTER(_xlpm.m,(_xlpm.dt=_xlpm.x)*(_xlpm.sh="E"),0))))))} -> 46023 | EM3: 4410.2 | EN3: 5016 | EP3: {=_xlfn.CHOOSECOLS(_xlfn.ANCHORARRAY($R$61),1,4)} -> 46023 | EQ3: 573.56 | ES3: {=_xlfn.CHOOSECOLS(_xlfn.ANCHORARRAY($R$61),1,5)} -> 46023 | ET3: 24.556629 | EV3: {=_xlfn.CHOOSECOLS(_xlfn.ANCHORARRAY($R$61),1,3,4)} -> 46023 | EW3: 14084.7 | EX3: 573.56 | EZ3: Nira Bhima | FA3: =$E$10 -> 145525.7 | FC3: M | FD3: =$I$26 -> 19156.95 | FF3: {=_xlfn.CHOOSECOLS(_xlfn.ANCHORARRAY($AI$61),1,2)} -> 46023 | FG3: 309600.2 | FI3: {=_xlfn.CHOOSECOLS(_xlfn.ANCHORARRAY($AI$61),1,4)} -> 46023 | FJ3: 12732.84 | FL3: {=_xlfn.CHOOSECOLS(_xlfn.ANCHORARRAY($AI$61),1,5)} -> 46023 | FM3: 24.635239
A4: Start Date | C4: End Date | E4: Year | G4: Month | I4: Week | K4: Shift | M4: Location View | O4: Source Through | BA4: 46023 | BB4: E | BC4: 196 | BD4: 1915.6 | BE4: 361.6 | BF4: 2542.8 | BH4: 5016 | BR4: 46023 | BS4: E | BT4: 196 | BU4: 1915.6 | BV4: 361.6 | BW4: 2542.8 | BY4: 5016 | EI4: 46024 | EJ4: 9217.6 | EL4: 46024 | EM4: 4673.5 | EN4: 4544.1 | EP4: 46024 | EQ4: 376.88 | ES4: 46024 | ET4: 24.510985 | EV4: 46024 | EW4: 9237.7 | EX4: 376.88 | EZ4: Bhodani + Alephata + Jalgaon | FA4: =$I$10 -> 1443550.6 | FC4: E | FD4: =$M$26 -> 82866.25 | FF4: 46054 | FG4: 261219 | FI4: 46054 | FJ4: 10161.63 | FL4: 46054 | FM4: 25.261879
A5: =MIN(_xlfn.TAKE(_xlfn.ANCHORARRAY($BA$3),,1)) -> 46023 | C5: =MAX(_xlfn.TAKE(_xlfn.ANCHORARRAY($BA$3),,1)) -> 46308 | E5: 2026 | G5: All | I5: All | K5: All | M5: All | O5: =MAX(_xlfn.TAKE(_xlfn.ANCHORARRAY($BA$3),,1)) -> 46308 | BA5: 46024 | BB5: M | BC5: 232.1 | BD5: 1679.7 | BE5: 434.4 | BF5: 2327.3 | BH5: 4673.5 | BR5: 46024 | BS5: M | BT5: 232.1 | BU5: 1679.7 | BV5: 434.4 | BW5: 2327.3 | BY5: 4673.5 | EI5: 46025 | EJ5: 9542.3 | EL5: 46025 | EM5: 4708.6 | EN5: 4833.7 | EP5: 46025 | EQ5: 380.93 | ES5: 46025 | ET5: 24.602945 | EV5: 46025 | EW5: 9372 | EX5: 380.93 | EZ5: Gagargaon | FA5: =$M$10 -> 240764.61 | FF5: 46082 | FG5: 211282.2 | FI5: 46082 | FJ5: 8123.76 | FL5: 46082 | FM5: 26.01557
BA6: 46024 | BB6: E | BC6: 204.4 | BD6: 1516.6 | BE6: 342.8 | BF6: 2480.3 | BH6: 4544.1 | BK6: 15 | BN6: 9237.7 | BO6: 376.88 | BP6: 24.510985 | BR6: 46024 | BS6: E | BT6: 204.4 | BU6: 1516.6 | BV6: 342.8 | BW6: 2480.3 | BY6: 4544.1 | CB6: 15 | CE6: 9237.7 | CF6: 376.88 | CG6: 24.510985 | EI6: 46026 | EJ6: 9316.9 | EL6: 46026 | EM6: 4553.3 | EN6: 4763.6 | EP6: 46026 | EQ6: 389.3 | ES6: 46026 | ET6: 24.700488 | EV6: 46026 | EW6: 9615.9 | EX6: 389.3 | EZ6: Indapur / Madha | FA6: =$A$14 -> 728807.22 | FF6: 46113 | FG6: 309089.9 | FI6: 46113 | FJ6: 11952.95 | FL6: 46113 | FM6: 25.749331
BA7: 46025 | BB7: M | BC7: 223 | BD7: 1765.4 | BE7: 434.4 | BF7: 2285.8 | BH7: 4708.6 | BR7: 46025 | BS7: M | BT7: 223 | BU7: 1765.4 | BV7: 434.4 | BW7: 2285.8 | BY7: 4708.6 | EI7: 46027 | EJ7: 9544.4 | EL7: 46027 | EM7: 4867.3 | EN7: 4677.1 | EP7: 46027 | EQ7: 387.93 | ES7: 46027 | ET7: 24.627123 | EV7: 46027 | EW7: 9553.6 | EX7: 387.93 | EZ7: Kalewadi | FA7: =$E$14 -> 2444.7 | FF7: 46143 | FG7: 282429.22 | FI7: 46143 | FJ7: 11175.73 | FL7: 46143 | FM7: 25.699136
BA8: 46025 | BB8: E | BC8: 203.6 | BD8: 1641.7 | BE8: 361.5 | BF8: 2626.9 | BH8: 4833.7 | BK8: 15 | BN8: 9372 | BO8: 380.93 | BP8: 24.602945 | BR8: 46025 | BS8: E | BT8: 203.6 | BU8: 1641.7 | BV8: 361.5 | BW8: 2626.9 | BY8: 4833.7 | CB8: 15 | CE8: 9372 | CF8: 380.93 | CG8: 24.602945 | EI8: 46028 | EJ8: 9623.9 | EL8: 46028 | EM8: 4891.5 | EN8: 4732.4 | EP8: 46028 | EQ8: 616.75 | ES8: 46028 | ET8: 24.505067 | EV8: 46028 | EW8: 15113.5 | EX8: 616.75 | FF8: 46174 | FG8: 252306.61 | FI8: 46174 | FJ8: 9798.86 | FL8: 46174 | FM8: 25.727898
A9: Total Milk Collected | E9: Nira Bhima Total | I9: Bhodani + Alephata + Jalgaon | M9: Gagargaon Total | BA9: 46026 | BB9: M | BC9: 211 | BD9: 1682.9 | BE9: 432.5 | BF9: 2226.9 | BH9: 4553.3 | BR9: 46026 | BS9: M | BT9: 211 | BU9: 1682.9 | BV9: 432.5 | BW9: 2226.9 | BY9: 4553.3 | EI9: 46029 | EJ9: 15199.3 | EL9: 46029 | EM9: 10396.1 | EN9: 4803.2 | EP9: 46029 | EQ9: 395.94 | ES9: 46029 | ET9: 24.511037 | EV9: 46029 | EW9: 9704.9 | EX9: 395.94 | FF9: 46204 | FG9: 251546.7 | FI9: 46204 | FJ9: 10334.87 | FL9: 46204 | FM9: 24.167149
A10: =SUM(_xlfn.CHOOSECOLS(_xlfn.ANCHORARRAY($BR$3),8)) -> 2554374.1 | E10: =SUM(_xlfn.CHOOSECOLS(_xlfn.ANCHORARRAY($BR$3),3)) -> 145525.7 | I10: =SUM(_xlfn.CHOOSECOLS(_xlfn.ANCHORARRAY($BR$3),4)) -> 1443550.6 | M10: =SUM(_xlfn.CHOOSECOLS(_xlfn.ANCHORARRAY($BR$3),5)) -> 240764.61 | BA10: 46026 | BB10: E | BC10: 208.1 | BD10: 1644.3 | BE10: 349 | BF10: 2562.2 | BH10: 4763.6 | BK10: 15 | BN10: 9615.9 | BO10: 389.3 | BP10: 24.700488 | BR10: 46026 | BS10: E | BT10: 208.1 | BU10: 1644.3 | BV10: 349 | BW10: 2562.2 | BY10: 4763.6 | CB10: 15 | CE10: 9615.9 | CF10: 389.3 | CG10: 24.700488 | EI10: 46030 | EJ10: 9581.2 | EL10: 46030 | EM10: 4916.7 | EN10: 4664.5 | EP10: 46030 | EQ10: 396.2 | ES10: 46030 | ET10: 24.385916 | EV10: 46030 | EW10: 9661.7 | EX10: 396.2 | FF10: 46235 | FG10: 283470.3 | FI10: 46235 | FJ10: 12180.26 | FL10: 46235 | FM10: 23.143155
BA11: 46027 | BB11: M | BC11: 219.8 | BD11: 1766 | BE11: 441.3 | BF11: 2440.2 | BH11: 4867.3 | BR11: 46027 | BS11: M | BT11: 219.8 | BU11: 1766 | BV11: 441.3 | BW11: 2440.2 | BY11: 4867.3 | EI11: 46031 | EJ11: 9895.2 | EL11: 46031 | EM11: 5012.2 | EN11: 4883 | EP11: 46031 | EQ11: 392.19 | ES11: 46031 | ET11: 24.73648 | EV11: 46031 | EW11: 9701.4 | EX11: 392.19 | FF11: 46266 | FG11: 263972.1 | FI11: 46266 | FJ11: 11773.44 | FL11: 46266 | FM11: 23.133762
A12: litres | E12: litres | I12: litres | M12: litres | BA12: 46027 | BB12: E | BC12: 228.3 | BD12: 1518.5 | BE12: 373.3 | BF12: 2557 | BH12: 4677.1 | BK12: 15 | BN12: 9553.6 | BO12: 387.93 | BP12: 24.627123 | BR12: 46027 | BS12: E | BT12: 228.3 | BU12: 1518.5 | BV12: 373.3 | BW12: 2557 | BY12: 4677.1 | CB12: 15 | CE12: 9553.6 | CF12: 387.93 | CG12: 24.627123 | EI12: 46032 | EJ12: 9615.3 | EL12: 46032 | EM12: 4833.4 | EN12: 4781.9 | EP12: 46032 | EQ12: 401.4 | ES12: 46032 | ET12: 24.500498 | EV12: 46032 | EW12: 9834.5 | EX12: 401.4 | FF12: 46296 | FG12: 129457.9 | FI12: 46296 | FJ12: 3788.86 | FL12: 46296 | FM12: 22.751132
A13: Indapur / Madha Total | E13: Kalewadi Total | I13: Average Daily Milk | M13: Highest Daily Milk | BA13: 46028 | BB13: M | BC13: 238.3 | BD13: 1724.6 | BE13: 468 | BF13: 2460.6 | BH13: 4891.5 | BR13: 46028 | BS13: M | BT13: 238.3 | BU13: 1724.6 | BV13: 468 | BW13: 2460.6 | BY13: 4891.5 | EI13: 46033 | EJ13: 9962.4 | EL13: 46033 | EM13: 9962.4 | EN13: 0 | EP13: 46033 | EQ13: 404.67 | ES13: 46033 | ET13: 24.600539 | EV13: 46033 | EW13: 9955.1 | EX13: 404.67
A14: =SUM(_xlfn.CHOOSECOLS(_xlfn.ANCHORARRAY($BR$3),6)) -> 728807.22 | E14: =SUM(_xlfn.CHOOSECOLS(_xlfn.ANCHORARRAY($BR$3),7)) -> 2444.7 | I14: =IFERROR(AVERAGE(_xlfn.CHOOSECOLS(_xlfn.ANCHORARRAY($R$61),2)),0) -> 8931.3781 | M14: =IFERROR(MAX(_xlfn.CHOOSECOLS(_xlfn.ANCHORARRAY($R$61),2)),0) -> 19638.8 | BA14: 46028 | BB14: E | BC14: 215.1 | BD14: 1629.9 | BE14: 359.2 | BF14: 2528.2 | BH14: 4732.4 | BK14: 15 | BN14: 15113.5 | BO14: 616.75 | BP14: 24.505067 | BR14: 46028 | BS14: E | BT14: 215.1 | BU14: 1629.9 | BV14: 359.2 | BW14: 2528.2 | BY14: 4732.4 | CB14: 15 | CE14: 15113.5 | CF14: 616.75 | CG14: 24.505067 | EI14: 46034 | EJ14: 9915 | EL14: 46034 | EM14: 4839.7 | EN14: 5075.3 | EP14: 46034 | EQ14: 397 | ES14: 46034 | ET14: 24.603778 | EV14: 46034 | EW14: 9767.7 | EX14: 397
BA15: 46029 | BB15: M | BC15: 233.2 | BD15: 7532.4 | BE15: 459.7 | BF15: 2170.8 | BH15: 10396.1 | BR15: 46029 | BS15: M | BT15: 233.2 | BU15: 7532.4 | BV15: 459.7 | BW15: 2170.8 | BY15: 10396.1 | EI15: 46035 | EJ15: 9966.1 | EL15: 46035 | EM15: 4898.1 | EN15: 5068 | EP15: 46035 | EQ15: 401.4 | ES15: 46035 | ET15: 24.701794 | EV15: 46035 | EW15: 9915.3 | EX15: 401.4
A16: litres | E16: litres | I16: litres / day | M16: litres / day | BA16: 46029 | BB16: E | BC16: 222.2 | BD16: 1746.2 | BE16: 377.3 | BF16: 2457.5 | BH16: 4803.2 | BK16: 15 | BN16: 9704.9 | BO16: 395.94 | BP16: 24.511037 | BR16: 46029 | BS16: E | BT16: 222.2 | BU16: 1746.2 | BV16: 377.3 | BW16: 2457.5 | BY16: 4803.2 | CB16: 15 | CE16: 9704.9 | CF16: 395.94 | CG16: 24.511037 | EI16: 46036 | EJ16: 10070.9 | EL16: 46036 | EM16: 5038.7 | EN16: 5032.2 | EP16: 46036 | EQ16: 404.48 | ES16: 46036 | ET16: 24.700109 | EV16: 46036 | EW16: 9990.7 | EX16: 404.48
A17: Consumed Milk | E17: Waste | I17: Milk for Ghee Process | M17: Process / Collected Ratio | BA17: 46030 | BB17: M | BC17: 239.8 | BD17: 1761.4 | BE17: 480.4 | BF17: 2435.1 | BH17: 4916.7 | BR17: 46030 | BS17: M | BT17: 239.8 | BU17: 1761.4 | BV17: 480.4 | BW17: 2435.1 | BY17: 4916.7 | EI17: 46037 | EJ17: 10049.6 | EL17: 46037 | EM17: 5082.6 | EN17: 4967 | EP17: 46037 | EQ17: 403.41 | ES17: 46037 | ET17: 24.60053 | EV17: 46037 | EW17: 9924.1 | EX17: 403.41
A18: =SUM(_xlfn.CHOOSECOLS(_xlfn.ANCHORARRAY($BR$3),11)) -> 9883.6 | E18: {=_xlfn.LET(_xlpm.w,_xlfn.CHOOSECOLS(_xlfn.ANCHORARRAY($BR$3),12),IF(COUNT(_xlpm.w)=0,"No valid data",SUM(_xlpm.w)))} -> No valid data | I18: =SUM(_xlfn.CHOOSECOLS(_xlfn.ANCHORARRAY($BR$3),14)) -> 2541271 | M18: =IFERROR(SUM(_xlfn.CHOOSECOLS(_xlfn.ANCHORARRAY($BR$3),14))/SUM(_xlfn.CHOOSECOLS(_xlfn.ANCHORARRAY($BR$3),8)),0) -> 0.99487033 | BA18: 46030 | BB18: E | BC18: 230.1 | BD18: 1491.8 | BE18: 391 | BF18: 2551.6 | BH18: 4664.5 | BK18: 15 | BN18: 9661.7 | BO18: 396.2 | BP18: 24.385916 | BR18: 46030 | BS18: E | BT18: 230.1 | BU18: 1491.8 | BV18: 391 | BW18: 2551.6 | BY18: 4664.5 | CB18: 15 | CE18: 9661.7 | CF18: 396.2 | CG18: 24.385916 | EI18: 46038 | EJ18: 9517.1 | EL18: 46038 | EM18: 4660.6 | EN18: 4856.5 | EP18: 46038 | EQ18: 388.43 | ES18: 46038 | ET18: 24.700461 | EV18: 46038 | EW18: 9594.4 | EX18: 388.43
BA19: 46031 | BB19: M | BC19: 263 | BD19: 1763.8 | BE19: 486.8 | BF19: 2498.6 | BH19: 5012.2 | BR19: 46031 | BS19: M | BT19: 263 | BU19: 1763.8 | BV19: 486.8 | BW19: 2498.6 | BY19: 5012.2 | EI19: 46039 | EJ19: 9916.8 | EL19: 46039 | EM19: 4968 | EN19: 4948.8 | EP19: 46039 | EQ19: 397.37 | ES19: 46039 | ET19: 24.600498 | EV19: 46039 | EW19: 9775.5 | EX19: 397.37
A20: litres | E20: source values | I20: litres | M20: indicative | BA20: 46031 | BB20: E | BC20: 215.7 | BD20: 1653.1 | BE20: 389.7 | BF20: 2624.5 | BH20: 4883 | BK20: 15 | BN20: 9701.4 | BO20: 392.19 | BP20: 24.73648 | BR20: 46031 | BS20: E | BT20: 215.7 | BU20: 1653.1 | BV20: 389.7 | BW20: 2624.5 | BY20: 4883 | CB20: 15 | CE20: 9701.4 | CF20: 392.19 | CG20: 24.73648 | EI20: 46040 | EJ20: 9863.8 | EL20: 46040 | EM20: 5041.3 | EN20: 4822.5 | EP20: 46040 | EQ20: 409.13 | ES20: 46040 | ET20: 24.700462 | EV20: 46040 | EW20: 10105.7 | EX20: 409.13
A21: Total Ghee Produced | E21: Average Ghee per Shift | I21: Average Ghee Average | M21: Highest Ghee Average | BA21: 46032 | BB21: M | BC21: 248.9 | BD21: 1687.7 | BE21: 487.3 | BF21: 2409.5 | BH21: 4833.4 | BR21: 46032 | BS21: M | BT21: 248.9 | BU21: 1687.7 | BV21: 487.3 | BW21: 2409.5 | BY21: 4833.4 | EI21: 46041 | EJ21: 10138.6 | EL21: 46041 | EM21: 5059.2 | EN21: 5079.4 | EP21: 46041 | EQ21: 405.69 | ES21: 46041 | ET21: 24.600557 | EV21: 46041 | EW21: 9980.2 | EX21: 405.69
A22: =SUM(_xlfn.CHOOSECOLS(_xlfn.ANCHORARRAY($BR$3),15)) -> 102023.2 | E22: {=_xlfn.LET(_xlpm.g,_xlfn.CHOOSECOLS(_xlfn.ANCHORARRAY($BR$3),15),IFERROR(AVERAGE(_xlfn._xlws.FILTER(_xlpm.g,ISNUMBER(_xlpm.g))),0))} -> 361.7844 | I22: {=_xlfn.LET(_xlpm.g,_xlfn.CHOOSECOLS(_xlfn.ANCHORARRAY($BR$3),16),IFERROR(AVERAGE(_xlfn._xlws.FILTER(_xlpm.g,ISNUMBER(_xlpm.g))),0))} -> 24.762246 | M22: {=_xlfn.LET(_xlpm.g,_xlfn.CHOOSECOLS(_xlfn.ANCHORARRAY($BR$3),16),IFERROR(MAX(_xlfn._xlws.FILTER(_xlpm.g,ISNUMBER(_xlpm.g))),0))} -> 27.160467 | BA22: 46032 | BB22: E | BC22: 213.4 | BD22: 1646.6 | BE22: 393.7 | BF22: 2528.2 | BH22: 4781.9 | BK22: 15 | BN22: 9834.5 | BO22: 401.4 | BP22: 24.500498 | BR22: 46032 | BS22: E | BT22: 213.4 | BU22: 1646.6 | BV22: 393.7 | BW22: 2528.2 | BY22: 4781.9 | CB22: 15 | CE22: 9834.5 | CF22: 401.4 | CG22: 24.500498 | EI22: 46042 | EJ22: 7000.1 | EL22: 46042 | EM22: 1939.1 | EN22: 5061 | EP22: 46042 | EQ22: 284.79 | ES22: 46042 | ET22: 24.50086 | EV22: 46042 | EW22: 6977.6 | EX22: 284.79
BA23: 46033 | BB23: M | BC23: 245.8 | BD23: 1882 | BE23: 475.1 | BF23: 2464.7 | BH23: 5067.6 | BR23: 46033 | BS23: M | BT23: 245.8 | BU23: 1882 | BV23: 475.1 | BW23: 2464.7 | BY23: 5067.6 | EI23: 46043 | EJ23: 9829.7 | EL23: 46043 | EM23: 9829.7 | EN23: 0 | EP23: 46043 | EQ23: 397 | ES23: 46043 | ET23: 24.575567 | EV23: 46043 | EW23: 9756.5 | EX23: 397
A24: kg | E24: kg / numeric record | I24: unweighted valid values | M24: valid average | BA24: 46033 | BB24: M | BC24: 248.4 | BD24: 1599.4 | BE24: 398.7 | BF24: 2648.3 | BH24: 4894.8 | BK24: 15 | BN24: 9955.1 | BO24: 404.67 | BP24: 24.600539 | BR24: 46033 | BS24: M | BT24: 248.4 | BU24: 1599.4 | BV24: 398.7 | BW24: 2648.3 | BY24: 4894.8 | CB24: 15 | CE24: 9955.1 | CF24: 404.67 | CG24: 24.600539 | EI24: 46044 | EJ24: 9931 | EL24: 46044 | EM24: 4935.7 | EN24: 4995.3 | EP24: 46044 | EQ24: 402.63 | ES24: 46044 | ET24: 24.50041 | EV24: 46044 | EW24: 9864.6 | EX24: 402.63
A25: Lowest Ghee Average | E25: Valid Production Records | I25: Morning Ghee Produced | M25: Evening Ghee Produced | BA25: 46034 | BB25: E | BC25: 242.9 | BD25: 1777.8 | BE25: 534.6 | BF25: 2520 | BH25: 5075.3 | BR25: 46034 | BS25: E | BT25: 242.9 | BU25: 1777.8 | BV25: 534.6 | BW25: 2520 | BY25: 5075.3 | EI25: 46045 | EJ25: 9937.8 | EL25: 46045 | EM25: 4993.9 | EN25: 4943.9 | EP25: 46045 | EQ25: 392.13 | ES25: 46045 | ET25: 24.600515 | EV25: 46045 | EW25: 9646.6 | EX25: 392.13
A26: {=_xlfn.LET(_xlpm.g,_xlfn.CHOOSECOLS(_xlfn.ANCHORARRAY($BR$3),16),IFERROR(MIN(_xlfn._xlws.FILTER(_xlpm.g,ISNUMBER(_xlpm.g))),0))} -> 21.891517 | E26: =COUNT(_xlfn.CHOOSECOLS(_xlfn.ANCHORARRAY($BR$3),15)) -> 282 | I26: {=SUM(_xlfn._xlws.FILTER(_xlfn.CHOOSECOLS(_xlfn.ANCHORARRAY($BR$3),15),_xlfn.CHOOSECOLS(_xlfn.ANCHORARRAY($BR$3),2)="M",0))} -> 19156.95 | M26: {=SUM(_xlfn._xlws.FILTER(_xlfn.CHOOSECOLS(_xlfn.ANCHORARRAY($BR$3),15),_xlfn.CHOOSECOLS(_xlfn.ANCHORARRAY($BR$3),2)="E",0))} -> 82866.25 | BA26: 46034 | BB26: M | BC26: 231.8 | BD26: 1700.2 | BE26: 401.7 | BF26: 2506 | BH26: 4839.7 | BK26: 140 | BN26: 9767.7 | BO26: 397 | BP26: 24.603778 | BR26: 46034 | BS26: M | BT26: 231.8 | BU26: 1700.2 | BV26: 401.7 | BW26: 2506 | BY26: 4839.7 | CB26: 140 | CE26: 9767.7 | CF26: 397 | CG26: 24.603778 | EI26: 46046 | EJ26: 9784.9 | EL26: 46046 | EM26: 5117.2 | EN26: 4667.7 | EP26: 46046 | EQ26: 408.54 | ES26: 46046 | ET26: 24.600039 | EV26: 46046 | EW26: 10050.1 | EX26: 408.54
A27: valid average | E27: numeric ghee values | I27: kg | M27: kg | BA27: 46035 | BB27: E | BC27: 261 | BD27: 1795.2 | BE27: 523.9 | BF27: 2487.9 | BH27: 5068 | BR27: 46035 | BS27: E | BT27: 261 | BU27: 1795.2 | BV27: 523.9 | BW27: 2487.9 | BY27: 5068 | EI27: 46047 | EJ27: 10170.2 | EL27: 46047 | EM27: 5222.3 | EN27: 4947.9 | EP27: 46047 | EQ27: 414.96 | ES27: 46047 | ET27: 24.800222 | EV27: 46047 | EW27: 10291.1 | EX27: 414.96
BA28: 46035 | BB28: M | BC28: 238.3 | BD28: 1577.2 | BE28: 442.5 | BF28: 2640.1 | BH28: 4898.1 | BK28: 15 | BN28: 9915.3 | BO28: 401.4 | BP28: 24.701794 | BR28: 46035 | BS28: M | BT28: 238.3 | BU28: 1577.2 | BV28: 442.5 | BW28: 2640.1 | BY28: 4898.1 | CB28: 15 | CE28: 9915.3 | CF28: 401.4 | CG28: 24.701794 | EI28: 46048 | EJ28: 10221.2 | EL28: 46048 | EM28: 5137.4 | EN28: 5083.8 | EP28: 46048 | EQ28: 405.55 | ES28: 46048 | ET28: 24.70053 | EV28: 46048 | EW28: 10017.3 | EX28: 405.55
A29: M − E Ghee Difference | E29: Selected Location Milk | I29: Filtered Shift Rows | M29: Milk Reconciliation Flags | BA29: 46036 | BB29: E | BC29: 255.4 | BD29: 1788.9 | BE29: 553.3 | BF29: 2434.6 | BH29: 5032.2 | BR29: 46036 | BS29: E | BT29: 255.4 | BU29: 1788.9 | BV29: 553.3 | BW29: 2434.6 | BY29: 5032.2 | EI29: 46049 | EJ29: 10340.7 | EL29: 46049 | EM29: 5320.8 | EN29: 5019.9 | EP29: 46049 | EQ29: 423 | ES29: 46049 | ET29: 24.708511 | EV29: 46049 | EW29: 10451.7 | EX29: 423
A30: =I26-M26 -> -63709.3 | E30: {=_xlfn.LET(_xlpm.v,_xlfn.ANCHORARRAY($BR$3),_xlpm.n,$M$5,_xlpm.c,_xlfn.SWITCH(_xlpm.n,"Nira Bhima",3,"Bhodani + Alephata + Jalgaon",4,"Gagargaon",5,"Indapur / Madha",6,"Kalewadi",7,8),SUM(_xlfn.CHOOSECOLS(_xlpm.v,_xlpm.c)))} -> 2554374.1 | I30: =ROWS(_xlfn.ANCHORARRAY($BR$3)) -> 572 | M30: {=_xlfn.LET(_xlpm.v,_xlfn.ANCHORARRAY($BR$3),_xlpm.tot,IFERROR(--_xlfn.CHOOSECOLS(_xlpm.v,8),0),_xlpm.cmp,IFERROR(--_xlfn.CHOOSECOLS(_xlpm.v,3),0)+IFERROR(--_xlfn.CHOOSECOLS(_xlpm.v,4),0)+IFERROR(--_xlfn.CHOOSECOLS(_xlpm.v,5),0)+IFERROR(--_xlfn.CHOOSECOLS(_xlpm.v,6),0)+IFERROR(--_xlfn.CHOOSECOLS(_xlpm.v,7),0),SUM(--(ABS(_xlpm.tot-_xlpm.cmp)>0.11)))} -> 1 | BA30: 46036 | BB30: M | BC30: 247.2 | BD30: 1677.9 | BE30: 434.9 | BF30: 2678.7 | BH30: 5038.7 | BK30: 15 | BN30: 9990.7 | BO30: 404.48 | BP30: 24.700109 | BR30: 46036 | BS30: M | BT30: 247.2 | BU30: 1677.9 | BV30: 434.9 | BW30: 2678.7 | BY30: 5038.7 | CB30: 15 | CE30: 9990.7 | CF30: 404.48 | CG30: 24.700109 | EI30: 46050 | EJ30: 10376.1 | EL30: 46050 | EM30: 5230.2 | EN30: 5145.9 | EP30: 46050 | EQ30: 422.61 | ES30: 46050 | ET30: 24.958472 | EV30: 46050 | EW30: 10547.7 | EX30: 422.61
A31: kg (M minus E) | E31: litres | I31: rows | M31: count | BA31: 46037 | BB31: E | BC31: 277 | BD31: 1799 | BE31: 544.7 | BF31: 2346.3 | BH31: 4967 | BR31: 46037 | BS31: E | BT31: 277 | BU31: 1799 | BV31: 544.7 | BW31: 2346.3 | BY31: 4967 | EI31: 46051 | EJ31: 10354.4 | EL31: 46051 | EM31: 5021.9 | EN31: 5332.5 | EP31: 46051 | EQ31: 398.5 | ES31: 46051 | ET31: 24.601255 | EV31: 46051 | EW31: 9803.6 | EX31: 398.5
BA32: 46037 | BB32: M | BC32: 242.9 | BD32: 1740.7 | BE32: 450.5 | BF32: 2648.5 | BH32: 5082.6 | BK32: 15 | BN32: 9924.1 | BO32: 403.41 | BP32: 24.60053 | BR32: 46037 | BS32: M | BT32: 242.9 | BU32: 1740.7 | BV32: 450.5 | BW32: 2648.5 | BY32: 5082.6 | CB32: 15 | CE32: 9924.1 | CF32: 403.41 | CG32: 24.60053 | EI32: 46052 | EJ32: 9824 | EL32: 46052 | EM32: 5027.3 | EN32: 4796.7 | EP32: 46052 | EQ32: 421.36 | ES32: 46052 | ET32: 24.700019 | EV32: 46052 | EW32: 10407.6 | EX32: 421.36
BA33: 46038 | BB33: E | BC33: 255 | BD33: 1790 | BE33: 491.2 | BF33: 2320.3 | BH33: 4856.5 | BR33: 46038 | BS33: E | BT33: 255 | BU33: 1790 | BV33: 491.2 | BW33: 2320.3 | BY33: 4856.5 | EI33: 46053 | EJ33: 11467.5 | EL33: 46053 | EM33: 5985.6 | EN33: 5481.9 | EP33: 46053 | EQ33: 439.11 | ES33: 46053 | ET33: 25.000114 | EV33: 46053 | EW33: 10977.8 | EX33: 439.11
BA34: 46038 | BB34: M | BC34: 231.1 | BD34: 1569.7 | BE34: 380.8 | BF34: 2479 | BH34: 4660.6 | BK34: 15 | BN34: 9594.4 | BO34: 388.43 | BP34: 24.700461 | BR34: 46038 | BS34: M | BT34: 231.1 | BU34: 1569.7 | BV34: 380.8 | BW34: 2479 | BY34: 4660.6 | CB34: 15 | CE34: 9594.4 | CF34: 388.43 | CG34: 24.700461 | EI34: 46054 | EJ34: 10216.3 | EL34: 46054 | EM34: 10216.3 | EN34: 0 | EP34: 46054 | EQ34: 411.7 | ES34: 46054 | ET34: 24.904299 | EV34: 46054 | EW34: 10253.1 | EX34: 411.7
BA35: 46039 | BB35: E | BC35: 259.7 | BD35: 1759.8 | BE35: 505.4 | BF35: 2423.9 | BH35: 4948.8 | BR35: 46039 | BS35: E | BT35: 259.7 | BU35: 1759.8 | BV35: 505.4 | BW35: 2423.9 | BY35: 4948.8 | EI35: 46055 | EJ35: 10108.8 | EL35: 46055 | EM35: 5049.8 | EN35: 5059 | EP35: 46055 | EQ35: 405.74 | ES35: 46055 | ET35: 24.756001 | EV35: 46055 | EW35: 10044.5 | EX35: 405.74
BA36: 46039 | BB36: M | BC36: 235.4 | BD36: 1679.3 | BE36: 441.6 | BF36: 2611.7 | BH36: 4968 | BK36: 15 | BN36: 9775.5 | BO36: 397.37 | BP36: 24.600498 | BR36: 46039 | BS36: M | BT36: 235.4 | BU36: 1679.3 | BV36: 441.6 | BW36: 2611.7 | BY36: 4968 | CB36: 15 | CE36: 9775.5 | CF36: 397.37 | CG36: 24.600498 | EI36: 46056 | EJ36: 10170.7 | EL36: 46056 | EM36: 5036 | EN36: 5134.7 | EP36: 46056 | EQ36: 380.95 | ES36: 46056 | ET36: 26.260402 | EV36: 46056 | EW36: 10003.9 | EX36: 380.95
BA37: 46040 | BB37: E | BC37: 277.1 | BD37: 1682.8 | BE37: 500.2 | BF37: 2362.4 | BH37: 4822.5 | BR37: 46040 | BS37: E | BT37: 277.1 | BU37: 1682.8 | BV37: 500.2 | BW37: 2362.4 | BY37: 4822.5 | EI37: 46057 | EJ37: 9993.4 | EL37: 46057 | EM37: 5010.5 | EN37: 4982.9 | EP37: 46057 | EQ37: 385.94 | ES37: 46057 | ET37: 24.940146 | EV37: 46057 | EW37: 9625.4 | EX37: 385.94
BA38: 46040 | BB38: M | BC38: 251.4 | BD38: 1733.4 | BE38: 420.7 | BF38: 2635.8 | BH38: 5041.3 | BK38: 15 | BN38: 10105.7 | BO38: 409.13 | BP38: 24.700462 | BR38: 46040 | BS38: M | BT38: 251.4 | BU38: 1733.4 | BV38: 420.7 | BW38: 2635.8 | BY38: 5041.3 | CB38: 15 | CE38: 10105.7 | CF38: 409.13 | CG38: 24.700462 | EI38: 46058 | EJ38: 9663.7 | EL38: 46058 | EM38: 5033.8 | EN38: 4629.9 | EP38: 46058 | EQ38: 409.16 | ES38: 46058 | ET38: 25 | EV38: 46058 | EW38: 10229 | EX38: 409.16
BA39: 46041 | BB39: E | BC39: 280.2 | BD39: 1781.6 | BE39: 514.5 | BF39: 2503.1 | BH39: 5079.4 | BR39: 46041 | BS39: E | BT39: 280.2 | BU39: 1781.6 | BV39: 514.5 | BW39: 2503.1 | BY39: 5079.4 | EI39: 46059 | EJ39: 10317.6 | EL39: 46059 | EM39: 5107.4 | EN39: 5210.2 | EP39: 46059 | EQ39: 339.5 | ES39: 46059 | ET39: 25.000589 | EV39: 46059 | EW39: 8487.7 | EX39: 339.5
BA40: 46041 | BB40: M | BC40: 252.8 | BD40: 1706.4 | BE40: 430.8 | BF40: 2669.2 | BH40: 5059.2 | BK40: 140 | BN40: 9980.2 | BO40: 405.69 | BP40: 24.600557 | BR40: 46041 | BS40: M | BT40: 252.8 | BU40: 1706.4 | BV40: 430.8 | BW40: 2669.2 | BY40: 5059.2 | CB40: 140 | CE40: 9980.2 | CF40: 405.69 | CG40: 24.600557 | EI40: 46060 | EJ40: 10307.4 | EL40: 46060 | EM40: 6912.1 | EN40: 3395.3 | EP40: 46060 | EQ40: 415.95 | ES40: 46060 | ET40: 24.900349 | EV40: 46060 | EW40: 10357.3 | EX40: 415.95
...

Sheet Nira-Bhima 
C1: 1 | D1: 2 | E1: 3 | F1: 4 | G1: 5 | H1: 6
A2: Date | B2: Time
C3: Vitthal | D3: Gangaram | E3: Vijay | F3: Vikram | G3: Ganesh | H3: Gopal | I3: Total ( M/E) | J3: Total Milk ( Liters)
C4: Qty | D4: Qty | E4: Qty | F4: Qty | G4: Qty | H4: Qty
A6: 46316 | B6: M | I6: =SUM(C6:H6) -> 0 | J6: =SUM(I6:I7) -> 0
B7: E | I7: =SUM(C7:H7) -> 0
A8: 46317 | B8: M | I8: =SUM(C8:H8) -> 0 | J8: =SUM(I8:I9) -> 0
B9: E | I9: =SUM(C9:H9) -> 0
A10: 46318 | B10: M | I10: =SUM(C10:H10) -> 0 | J10: =SUM(I10:I11) -> 0
B11: E | I11: =SUM(C11:H11) -> 0
A12: 46319 | B12: M | I12: =SUM(C12:H12) -> 0 | J12: =SUM(I12:I13) -> 0
B13: E | I13: =SUM(C13:H13) -> 0
A14: 46320 | B14: M | I14: =SUM(C14:H14) -> 0 | J14: =SUM(I14:I15) -> 0
B15: E | I15: =SUM(C15:H15) -> 0
A16: 46321 | B16: M | I16: =SUM(C16:H16) -> 0 | J16: =SUM(I16:I17) -> 0
B17: E | I17: =SUM(C17:H17) -> 0
A18: 46322 | B18: M | I18: =SUM(C18:H18) -> 0 | J18: =SUM(I18:I19) -> 0
B19: E | I19: =SUM(C19:H19) -> 0
A20: 46323 | B20: M | I20: =SUM(C20:H20) -> 0 | J20: =SUM(I20:I21) -> 0
B21: E | I21: =SUM(C21:H21) -> 0
A22: 46324 | B22: M | I22: =SUM(C22:H22) -> 0 | J22: =SUM(I22:I23) -> 0
B23: E | I23: =SUM(C23:H23) -> 0
A24: 46325 | B24: M | I24: =SUM(C24:H24) -> 0 | J24: =SUM(I24:I25) -> 0
B25: E | I25: =SUM(C25:H25) -> 0
A26: 46326 | B26: M | I26: =SUM(C26:H26) -> 0 | J26: =SUM(I26:I27) -> 0
B27: E | I27: =SUM(C27:H27) -> 0
A29: Total Qty Milk (Liters) | C29: =SUM(C6:C27) -> 0 | D29: =SUM(D6:D27) -> 0 | E29: =SUM(E6:E27) -> 0 | F29: =SUM(F6:F27) -> 0 | G29: =SUM(G6:G27) -> 0 | H29: =SUM(H6:H27) -> 0 | I29: =SUM(I6:I27) -> 0 | J29: =SUM(J6:J27) -> 0
A30: Total Rs Amount | C30: =C29*40 -> 0 | D30: =D29*40 -> 0 | E30: =E29*40 -> 0 | F30: =F29*40 -> 0 | G30: =G29*40 -> 0 | H30: =H29*40 -> 0 | I30: =I29*40 -> 0 | J30: =J29*40 -> 0
A32: CUT
A34: 46306 | B34: M | C34: 23.7 | D34: 27 | E34: 49.6 | F34: 30 | G34: 25.2 | H34: 24.5 | I34: =SUM(C34:H34) -> 180 | J34: =SUM(I34:I35) -> 350.3
B35: E | C35: 24.7 | D35: 27.8 | E35: 47.9 | F35: 25.5 | G35: 18.8 | H35: 25.6 | I35: =SUM(C35:H35) -> 170.3
A36: 46307 | B36: M | C36: 27 | D36: 28.4 | E36: 47.4 | F36: 31 | G36: 25.4 | H36: 24 | I36: =SUM(C36:H36) -> 183.2 | J36: =SUM(I36:I37) -> 343.1
B37: E | C37: 25.6 | D37: 27.9 | E37: 38.3 | F37: 29.5 | G37: 14.6 | H37: 24 | I37: =SUM(C37:H37) -> 159.9
A38: 46308 | B38: M | C38: 26 | D38: 26.5 | E38: 49.8 | F38: 29.9 | G38: 24.4 | H38: 25.1 | I38: =SUM(C38:H38) -> 181.7 | J38: =SUM(I38:I39) -> 342.9
B39: E | C39: 25.5 | D39: 25.7 | E39: 40.4 | F39: 26.5 | G39: 17.4 | H39: 25.7 | I39: =SUM(C39:H39) -> 161.2
A40: 46309 | B40: M | I40: =SUM(C40:H40) -> 0 | J40: =SUM(I40:I41) -> 0
B41: E | I41: =SUM(C41:H41) -> 0
A42: 46310 | B42: M | I42: =SUM(C42:H42) -> 0 | J42: =SUM(I42:I43) -> 0
B43: E | I43: =SUM(C43:H43) -> 0
A44: 46311 | B44: M | I44: =SUM(C44:H44) -> 0 | J44: =SUM(I44:I45) -> 0
...

Sheet Bhodani Jalgaon ALephata
A2: Date | B2: Time | E2: Alephata | F2: Alephata | G2: Jalgaon | H2: Shikrapur
C3: Raghu | D3: Bhaiyya | E3: Sanjay Mutke | F3: Raghu Mir | G3: Route | H3: Route | I3: Total (M/E) | J3: Total Milk ( Liters)
C5: Qty | D5: Qty | E5: Morning | F5: Evening
A6: 46316 | B6: M | C6: 0 | E6: 0 | F6: 0 | H6: 0 | I6: =SUM(C6:H6) -> 0 | J6: =SUM(I6:I7) -> 0
B7: E | C7: 0 | E7: 0 | F7: 0 | H7: 0 | I7: =SUM(C7:H7) -> 0
A8: 46317 | B8: M | C8: 0 | E8: 0 | F8: 0 | H8: 0 | I8: =SUM(C8:H8) -> 0 | J8: =SUM(I8:I9) -> 0
B9: E | C9: 0 | E9: 0 | F9: 0 | H9: 0 | I9: =SUM(C9:H9) -> 0
A10: 46318 | B10: M | C10: 0 | E10: 0 | F10: 0 | H10: 0 | I10: =SUM(C10:H10) -> 0 | J10: =SUM(I10:I11) -> 0
B11: E | C11: 0 | E11: 0 | F11: 0 | H11: 0 | I11: =SUM(C11:H11) -> 0
A12: 46319 | B12: M | C12: 0 | E12: 0 | F12: 0 | H12: 0 | I12: =SUM(C12:H12) -> 0 | J12: =SUM(I12:I13) -> 0
B13: E | C13: 0 | E13: 0 | F13: 0 | H13: 0 | I13: =SUM(C13:H13) -> 0
A14: 46320 | B14: M | C14: 0 | E14: 0 | F14: 0 | H14: 0 | I14: =SUM(C14:H14) -> 0 | J14: =SUM(I14:I15) -> 0
B15: E | C15: 0 | E15: 0 | F15: 0 | H15: 0 | I15: =SUM(C15:H15) -> 0
A16: 46321 | B16: M | C16: 0 | E16: 0 | F16: 0 | H16: 0 | I16: =SUM(C16:H16) -> 0 | J16: =SUM(I16:I17) -> 0
B17: E | C17: 0 | E17: 0 | F17: 0 | H17: 0 | I17: =SUM(C17:H17) -> 0
A18: 46322 | B18: M | C18: 0 | E18: 0 | F18: 0 | H18: 0 | I18: =SUM(C18:H18) -> 0 | J18: =SUM(I18:I19) -> 0
B19: E | C19: 0 | E19: 0 | F19: 0 | H19: 0 | I19: =SUM(C19:H19) -> 0
A20: 46323 | B20: M | C20: 0 | E20: 0 | F20: 0 | H20: 0 | I20: =SUM(C20:H20) -> 0 | J20: =SUM(I20:I21) -> 0
B21: E | C21: 0 | E21: 0 | F21: 0 | H21: 0 | I21: =SUM(C21:H21) -> 0
A22: 46324 | B22: M | C22: 0 | E22: 0 | F22: 0 | H22: 0 | I22: =SUM(C22:H22) -> 0 | J22: =SUM(I22:I23) -> 0
B23: E | C23: 0 | E23: 0 | F23: 0 | H23: 0 | I23: =SUM(C23:H23) -> 0
A24: 46325 | B24: M | C24: 0 | E24: 0 | F24: 0 | H24: 0 | I24: =SUM(C24:H24) -> 0 | J24: =SUM(I24:I25) -> 0
B25: E | C25: 0 | E25: 0 | F25: 0 | H25: 0 | I25: =SUM(C25:H25) -> 0
A26: 46326 | B26: M | I26: =SUM(C26:H26) -> 0 | J26: =SUM(I26:I27) -> 0
B27: E | I27: =SUM(C27:H27) -> 0
A29: Total Qty Milk (Liters) | C29: =SUM(C6:C27) -> 0 | D29: =SUM(D6:D27) -> 0 | E29: =SUM(E6:E27) -> 0 | F29: =SUM(F6:F27) -> 0 | G29: =SUM(G6:G27) -> 0 | H29: =SUM(H6:H27) -> 0 | I29: =SUM(I6:I27) -> 0 | J29: =SUM(J6:J27) -> 0
A30: Total Rs Amount | C30: =C29*40 -> 0 | D30: =D29*40 -> 0 | E30: =E29*40 -> 0 | F30: =F29*40 -> 0 | G30: =G29*40 -> 0 | H30: =H29*40 -> 0 | I30: =I29*40 -> 0 | J30: =J29*40 -> 0
A32: CUT
A33: PAY
A36: 46306 | B36: M | C36: 0 | D36: 19.2 | E36: 0 | F36: 0 | G36: 0 | H36: 0 | I36: =SUM(C36:H36) -> 19.2 | J36: =SUM(I36:I37) -> 36.7
B37: E | C37: 0 | D37: 17.5 | E37: 0 | F37: 0 | G37: 0 | H37: 0 | I37: =SUM(C37:H37) -> 17.5
A38: 46307 | B38: M | C38: 0 | D38: 14.5 | E38: 0 | F38: 0 | G38: 0 | H38: 0 | I38: =SUM(C38:H38) -> 14.5 | J38: =SUM(I38:I39) -> 10299.8
B39: E | C39: 0 | D39: 14.3 | E39: 0 | F39: 0 | G39: 10271 | H39: 0 | I39: =SUM(C39:H39) -> 10285.3
A40: 46308 | B40: M | C40: 0 | D40: 13.1 | E40: 0 | F40: 0 | G40: 0 | H40: 0 | I40: =SUM(C40:H40) -> 13.1 | J40: =SUM(I40:I41) -> 8076.4
B41: E | C41: 0 | D41: 15.3 | E41: 0 | F41: 0 | G41: 8048 | H41: 0 | I41: =SUM(C41:H41) -> 8063.3
A42: 46309 | B42: M | C42: 0 | E42: 0 | F42: 0 | H42: 0 | I42: =SUM(C42:H42) -> 0 | J42: =SUM(I42:I43) -> 0
B43: E | C43: 0 | E43: 0 | F43: 0 | H43: 0 | I43: =SUM(C43:H43) -> 0
A44: 46310 | B44: M | C44: 0 | E44: 0 | F44: 0 | H44: 0 | I44: =SUM(C44:H44) -> 0 | J44: =SUM(I44:I45) -> 0
B45: E | C45: 0 | E45: 0 | F45: 0 | H45: 0 | I45: =SUM(C45:H45) -> 0
A46: 46311 | B46: M | C46: 0 | E46: 0 | F46: 0 | H46: 0 | I46: =SUM(C46:H46) -> 0 | J46: =SUM(I46:I47) -> 0
...

Sheet Gagargaon 
A2: Date | B2: Time | C2: 1 | D2: 2 | E2: 3 | F2: 4 | G2: 5 | H2: 6 | I2: 7
C3: Arjun | D3: Nagaji | E3: Mapha | F3: Gopal | G3: Govind | H3: Munna Mir (1) | I3: Munna jograna (2) | J3: Total(M/E) | K3: Total Milk
C4: Qty | D4: Qty | E4: Qty | F4: Qty | G4: Qty | H4: Qty | I4: Qty
A5: 46316 | B5: M | J5: =SUM(D5:I5) -> 0 | K5: =SUM(J5:J6) -> 0
B6: E | J6: =SUM(D6:I6) -> 0
A7: 46317 | B7: M | J7: =SUM(D7:I7) -> 0 | K7: =SUM(J7:J8) -> 0
B8: E | J8: =SUM(D8:I8) -> 0
A9: 46318 | B9: M | J9: =SUM(D9:I9) -> 0 | K9: =SUM(J9:J10) -> 0
B10: E | J10: =SUM(D10:I10) -> 0
A11: 46319 | B11: M | J11: =SUM(D11:I11) -> 0 | K11: =SUM(J11:J12) -> 0
B12: E | J12: =SUM(D12:I12) -> 0
A13: 46320 | B13: M | J13: =SUM(D13:I13) -> 0 | K13: =SUM(J13:J14) -> 0
B14: E | J14: =SUM(D14:I14) -> 0
A15: 46321 | B15: M | J15: =SUM(D15:I15) -> 0 | K15: =SUM(J15:J16) -> 0
B16: E | J16: =SUM(D16:I16) -> 0
A17: 46322 | B17: M | J17: =SUM(D17:I17) -> 0 | K17: =SUM(J17:J18) -> 0
B18: E | J18: =SUM(D18:I18) -> 0
A19: 46323 | B19: M | J19: =SUM(D19:I19) -> 0 | K19: =SUM(J19:J20) -> 0
B20: E | J20: =SUM(D20:I20) -> 0
A21: 46324 | B21: M | J21: =SUM(D21:I21) -> 0 | K21: =SUM(J21:J22) -> 0
B22: E | J22: =SUM(D22:I22) -> 0
A23: 46325 | B23: M | J23: =SUM(D23:I23) -> 0 | K23: =SUM(J23:J24) -> 0
B24: E | J24: =SUM(D24:I24) -> 0
A25: 46326 | B25: M | J25: =SUM(D25:I25) -> 0 | K25: =SUM(J25:J26) -> 0
B26: E | J26: =SUM(D26:I26) -> 0
A28: Total Qty Milk (Liters) | C28: =SUM(C5:C26) -> 0 | D28: =SUM(D5:D26) -> 0 | E28: =SUM(E5:E26) -> 0 | F28: =SUM(F5:F26) -> 0 | G28: =SUM(G5:G26) -> 0 | H28: =SUM(H5:H26) -> 0 | I28: =SUM(I5:I26) -> 0 | J28: =SUM(J5:J26) -> 0 | K28: =SUM(K5:K26) -> 0
A29: Total Rs Amount | C29: =C28*40 -> 0 | D29: =D28*40 -> 0 | E29: =E28*40 -> 0 | F29: =F28*40 -> 0 | G29: =G28*40 -> 0 | H29: =H28*40 -> 0 | I29: =I28*40 -> 0 | J29: =J28*40 -> 0 | K29: =K28*40 -> 0
A31: CUT
A32: PAY
A34: 46306 | B34: M | C34: 0 | D34: 71.3 | E34: 42.8 | F34: 51.9 | G34: 41.8 | H34: 68.9 | I34: 99 | J34: =SUM(D34:I34) -> 375.7 | K34: =SUM(J34:J35) -> 686.4
B35: E | C35: 0 | D35: 54.3 | E35: 32.4 | F35: 50.4 | G35: 38.8 | H35: 63.6 | I35: 71.2 | J35: =SUM(D35:I35) -> 310.7
A36: 46307 | B36: M | C36: 0 | D36: 75.1 | E36: 38.6 | F36: 56.6 | G36: 39.3 | H36: 68.6 | I36: 87.5 | J36: =SUM(D36:I36) -> 365.7 | K36: =SUM(J36:J37) -> 526.3
B37: E | C37: 0 | D37: 59.7 | E37: 28.7 | F37: 0 | G37: 0 | H37: 72.2 | I37: 0 | J37: =SUM(D37:I37) -> 160.6
A38: 46308 | B38: M | C38: 0 | D38: 66.8 | E38: 34.5 | F38: 64.9 | G38: 41.5 | H38: 66.9 | I38: 102.2 | J38: =SUM(D38:I38) -> 376.8 | K38: =SUM(J38:J39) -> 709.5
B39: E | C39: 0 | D39: 60.8 | E39: 27.4 | F39: 51.2 | G39: 38.8 | H39: 76.3 | I39: 78.2 | J39: =SUM(D39:I39) -> 332.7
A40: 46309 | B40: M | J40: =SUM(D40:I40) -> 0 | K40: =SUM(J40:J41) -> 0
B41: E | J41: =SUM(D41:I41) -> 0
A42: 46310 | B42: M | J42: =SUM(D42:I42) -> 0 | K42: =SUM(J42:J43) -> 0
B43: E | J43: =SUM(D43:I43) -> 0
A44: 46311 | B44: M | J44: =SUM(D44:I44) -> 0 | K44: =SUM(J44:J45) -> 0
...

Sheet Indapur-Madha-Kandhar-Baramati
C1: INDAPUR
A2: Date | B2: Time | C2: 1 | D2: 2 | E2: 3 | F2: 4 | G2: 5 | H2: 6 | I2: 7 | J2: 8 | K2: 9 | L2: 10 | M2: 11 | N2: 12 | O2: 13 | P2: 14 | Q2: 15 | R2: 16 | S2: 17 | T2: 18 | U2: 19 | V2: 20 | W2: 21
C3: Ram | D3: navghan | E3: Sham | F3: Sidhu | G3: Hari | H3: Govind Mir | I3: Sukhabhai | J3: Amar | K3: Govind | L3: Bharat | M3: Lala | N3: Raju | O3: Vikram | P3: Hari | Q3: Devgan | R3: Kabu/Bhavani ngr | S3: Gopal/Kandr | T3: Nagji/Madha | U3: Krushna/Baramati | V3: Kanha/Baramati | W3: Vijay / Madha | X3: Total(M/E) | Y3: Total Milk ( Liters)
C4: Qty | D4: Qty | E4: Qty | F4: Qty | G4: Qty | H4: Qty | I4: Qty | J4: Qty | K4: Qty | L4: Qty | M4: Qty | N4: Qty | O4: Qty | P4: Qty | Q4: Qty | R4: Qty | S4: Qty | U4: Evening | V4: Morning
A5: 46316 | B5: M | X5: =SUM(C5:W5) -> 0 | Y5: =X5+X6 -> 0
B6: E | X6: =SUM(C6:W6) -> 0
A7: 46317 | B7: M | X7: =SUM(C7:W7) -> 0 | Y7: =X7+X8 -> 0
B8: E | X8: =SUM(C8:W8) -> 0
A9: 46318 | B9: M | X9: =SUM(C9:W9) -> 0 | Y9: =X9+X10 -> 0
B10: E | X10: =SUM(C10:W10) -> 0
A11: 46319 | B11: M | X11: =SUM(C11:W11) -> 0 | Y11: =X11+X12 -> 0
B12: E | X12: =SUM(C12:W12) -> 0
A13: 46320 | B13: M | X13: =SUM(C13:W13) -> 0 | Y13: =X13+X14 -> 0
B14: E | X14: =SUM(C14:W14) -> 0
A15: 46321 | B15: M | X15: =SUM(C15:W15) -> 0 | Y15: =X15+X16 -> 0
B16: E | X16: =SUM(C16:W16) -> 0
A17: 46322 | B17: M | X17: =SUM(C17:W17) -> 0 | Y17: =X17+X18 -> 0
B18: E | X18: =SUM(C18:W18) -> 0
A19: 46323 | B19: M | X19: =SUM(C19:W19) -> 0 | Y19: =X19+X20 -> 0
B20: E | X20: =SUM(C20:W20) -> 0
A21: 46324 | B21: M | X21: =SUM(C21:W21) -> 0 | Y21: =X21+X22 -> 0
B22: E | X22: =SUM(C22:W22) -> 0
A23: 46325 | B23: M | X23: =SUM(C23:W23) -> 0 | Y23: =X23+X24 -> 0
B24: E | X24: =SUM(C24:W24) -> 0
A25: 46326 | B25: M | X25: =SUM(C25:W25) -> 0 | Y25: =X25+X26 -> 0
B26: E | X26: =SUM(C26:W26) -> 0
A28: Total Qty Milk (Liters) | C28: =SUM(C5:C24) -> 0 | D28: =SUM(D5:D24) -> 0 | E28: =SUM(E5:E24) -> 0 | F28: =SUM(F5:F24) -> 0 | G28: =SUM(G5:G24) -> 0 | H28: =SUM(H5:H24) -> 0 | I28: =SUM(I5:I24) -> 0 | J28: =SUM(J5:J24) -> 0 | ... Y28: =SUM(Y5:Y24) -> 0
A29: Total Rs Amount | C29: =40*C28 -> 0 | D29: =40*D28 -> 0 | E29: =40*E28 -> 0 | F29: =40*F28 -> 0 | G29: =40*G28 -> 0 | H29: =40*H28 -> 0 | I29: =40*I28 -> 0 | J29: =40*J28 -> 0 | ... Q29: =40*Q28 -> 0 | S29: =40*S28 -> 0 | T29: =40*T28 -> 0 | X29: =40*X28 -> 0 | Y29: =40*Y28 -> 0
A31: CUT
A32: PAY
A33: 46306 | B33: M | C33: 42.6 | D33: 35.7 | E33: 27.4 | G33: 10.1 | H33: 0 | I33: 19.2 | J33: 21.4 | K33: 28 | L33: 16 | M33: 18.3 | N33: 6.4 | O33: 3.5 | P33: 18.5 | Q33: 29.5 | T33: 22.3 | W33: 13 | X33: =SUM(C33:W33) -> 311.9 | Y33: =X33+X34 -> 584.4
B34: E | C34: 25.1 | D34: 36.6 | E34: 22 | G34: 14 | H34: 0 | I34: 34.4 | J34: 14.5 | K34: 25.2 | L34: 17.7 | M34: 15.8 | N34: 0 | O34: 0 | P34: 19.5 | Q34: 23 | T34: 24.7 | W34: 0 | X34: =SUM(C34:W34) -> 272.5
A35: 46307 | B35: M | C35: 33.7 | D35: 30 | E35: 30.2 | G35: 11.1 | H35: 0 | I35: 20.8 | J35: 18.7 | K35: 24.2 | L35: 14.5 | M35: 19.1 | N35: 6 | O35: 1.8 | P35: 21.5 | Q35: 30.2 | T35: 32.8 | W35: 14 | X35: =SUM(C35:W35) -> 308.6 | Y35: =X35+X36 -> 438.6
B36: E | C36: 27.3 | D36: 36.2 | E36: 28.7 | G36: 18 | H36: 19.8 | I36: 0 | J36: 0 | K36: 0 | L36: 0 | M36: 0 | N36: 0 | O36: 0 | P36: 0 | Q36: 0 | T36: 0 | W36: 0 | X36: =SUM(C36:W36) -> 130
A37: 46308 | B37: M | C37: 38 | D37: 33.2 | E37: 27.7 | G37: 10.9 | H37: 0 | I37: 20.8 | J37: 18.7 | K37: 25.8 | L37: 17.4 | M37: 20.7 | N37: 7 | O37: 7.1 | P37: 28.6 | Q37: 33.5 | T37: 31.9 | W37: 14.7 | X37: =SUM(C37:W37) -> 336 | Y37: =X37+X38 -> 621.7
B38: E | C38: 30.5 | D38: 36 | E38: 27 | G38: 14.7 | H38: 23.2 | I38: 34.5 | J38: 14 | K38: 22.1 | L38: 15.3 | M38: 14.6 | N38: 0 | O38: 0 | P38: 18.1 | Q38: 19.5 | T38: 16.2 | W38: 0 | X38: =SUM(C38:W38) -> 285.7
A39: 46309 | B39: M | X39: =SUM(C39:W39) -> 0 | Y39: =X39+X40 -> 0
B40: E | X40: =SUM(C40:W40) -> 0
A41: 46310 | B41: M | X41: =SUM(C41:W41) -> 0 | Y41: =X41+X42 -> 0
B42: E | X42: =SUM(C42:W42) -> 0
...

Sheet Kalewadi
C1: 1 | D1: 2 | E1: 3 | F1: 4
A2: Date | B2: Time
C3: Jayram | D3: Babhabhai | E3: Munnabhai | F3: Lalabhai | G3: Total ( M/E) | H3: Total Milk ( Liters)
C4: Qty | D4: Qty | E4: Qty | F4: Qty
A6: 46316 | B6: M | G6: =SUM(C6:F6) -> 0 | H6: =SUM(G6:G7) -> 0
B7: E | G7: =SUM(C7:F7) -> 0
A8: 46317 | B8: M | G8: =SUM(C8:F8) -> 0 | H8: =SUM(G8:G9) -> 0
B9: E | G9: =SUM(C9:F9) -> 0
A10: 46318 | B10: M | G10: =SUM(C10:F10) -> 0 | H10: =SUM(G10:G11) -> 0
B11: E | G11: =SUM(C11:F11) -> 0
A12: 46319 | B12: M | G12: =SUM(C12:F12) -> 0 | H12: =SUM(G12:G13) -> 0
B13: E | G13: =SUM(C13:F13) -> 0
A14: 46320 | B14: M | G14: =SUM(C14:F14) -> 0 | H14: =SUM(G14:G15) -> 0
B15: E | G15: =SUM(C15:F15) -> 0
A16: 46321 | B16: M | G16: =SUM(C16:F16) -> 0 | H16: =SUM(G16:G17) -> 0
B17: E | G17: =SUM(C17:F17) -> 0
A18: 46322 | B18: M | G18: =SUM(C18:F18) -> 0 | H18: =SUM(G18:G19) -> 0
B19: E | G19: =SUM(C19:F19) -> 0
A20: 46323 | B20: M | G20: =SUM(C20:F20) -> 0 | H20: =SUM(G20:G21) -> 0
B21: E | G21: =SUM(C21:F21) -> 0
A22: 46324 | B22: M | G22: =SUM(C22:F22) -> 0 | H22: =SUM(G22:G23) -> 0
B23: E | G23: =SUM(C23:F23) -> 0
A24: 46325 | B24: M | G24: =SUM(C24:F24) -> 0 | H24: =SUM(G24:G25) -> 0
B25: E | G25: =SUM(C25:F25) -> 0
A26: 46326 | B26: M | G26: =SUM(C26:F26) -> 0 | H26: =SUM(G26:G27) -> 0
B27: E | G27: =SUM(C27:F27) -> 0
A29: Total Qty Milk (Liters) | C29: =SUM(C6:C27) -> 0 | D29: =SUM(D6:D27) -> 0 | E29: =SUM(E6:E27) -> 0 | F29: =SUM(F6:F27) -> 0 | G29: =SUM(G6:G27) -> 0 | H29: =SUM(H6:H27) -> 0
A30: Total Rs Amount | C30: =C29*40 -> 0 | D30: =D29*40 -> 0 | E30: =E29*40 -> 0 | F30: =F29*40 -> 0 | G30: =G29*40 -> 0 | H30: =H29*40 -> 0
A32: CUT
A34: 46306 | B34: M | C34: 20.3 | D34: 37 | E34: 19.2 | F34: 24.7 | G34: =SUM(C34:F34) -> 101.2 | H34: =SUM(G34:G35) -> 210.1
B35: E | C35: 21.4 | D35: 36.8 | E35: 20.5 | F35: 30.2 | G35: =SUM(C35:F35) -> 108.9
A36: 46307 | B36: M | C36: 20.8 | D36: 35.8 | E36: 19 | F36: 26.3 | G36: =SUM(C36:F36) -> 101.9 | H36: =SUM(G36:G37) -> 215.9
B37: E | C37: 21.3 | D37: 39.1 | E37: 21.2 | F37: 32.4 | G37: =SUM(C37:F37) -> 114
A38: 46308 | B38: M | C38: 26.5 | D38: 38.7 | E38: 21.4 | F38: 28.5 | G38: =SUM(C38:F38) -> 115.1 | H38: =SUM(G38:G39) -> 233.5
B39: E | C39: 26 | D39: 37.1 | E39: 21.3 | F39: 34 | G39: =SUM(C39:F39) -> 118.4
A40: 46309 | B40: M | G40: =SUM(C40:F40) -> 0 | H40: =SUM(G40:G41) -> 0
B41: E | G41: =SUM(C41:F41) -> 0
A42: 46310 | B42: M | G42: =SUM(C42:F42) -> 0 | H42: =SUM(G42:G43) -> 0
B43: E | G43: =SUM(C43:F43) -> 0
A44: 46311 | B44: M | G44: =SUM(C44:F44) -> 0 | H44: =SUM(G44:G45) -> 0
...

Sheet Ghee Avarage
A2: Date | B2: Shift | C2: Nira Bhima Total | D2: Bhodani + Alephata +Jalgaon | E2: Gagargaon | F2: Indapur /MadhaTotal | G2: Kalewadi | H2: Total Milk | I2: FAT | J2: SNF | L2: Consumed Milk wada and Gotha/midc/ Butter for mumbai order | M2: Waste | N2: Butter1kg-25ltr /Culture | O2: Milk for Ghee Process | P2: Ghee Produced | Q2: Ghee Average | R2: Ghee Outsource (liters) | S2: Rate/ liters | T2: Culture Addition | U2: Butter Produced | V2: Residue
A3: 46023 | B3: M | C3: ='Nira-Bhima '!I741 -> 232.6 | D3: ='Bhodani Jalgaon ALephata'!I753 -> 1446.1 | E3: ='Gagargaon '!J743 -> 424.2 | F3: ='Indapur-Madha-Kandhar-Baramati'!X743 -> 2307.3 | H3: =SUM(C3:F3) -> 4410.2 | L3: 15 | O3: =H3+H4+H5-L3 -> 14084.7 | P3: 573.56 | Q3: =O3/P3 -> 24.556629
B4: E | C4: ='Nira-Bhima '!I742 -> 196 | D4: ='Bhodani Jalgaon ALephata'!I754 -> 1915.6 | E4: ='Gagargaon '!J744 -> 361.6 | F4: ='Indapur-Madha-Kandhar-Baramati'!X744 -> 2542.8 | H4: =SUM(C4:F4) -> 5016
A5: 46024 | B5: M | C5: ='Nira-Bhima '!I743 -> 232.1 | D5: ='Bhodani Jalgaon ALephata'!I755 -> 1679.7 | E5: ='Gagargaon '!J745 -> 434.4 | F5: ='Indapur-Madha-Kandhar-Baramati'!X745 -> 2327.3 | H5: =SUM(C5:F5) -> 4673.5
B6: E | C6: ='Nira-Bhima '!I744 -> 204.4 | D6: ='Bhodani Jalgaon ALephata'!I756 -> 1516.6 | E6: ='Gagargaon '!J746 -> 342.8 | F6: ='Indapur-Madha-Kandhar-Baramati'!X746 -> 2480.3 | H6: =SUM(C6:F6) -> 4544.1 | L6: 15 | O6: =H6+H7-L6 -> 9237.7 | P6: 376.88 | Q6: =O6/P6 -> 24.510985
A7: 46025 | B7: M | C7: ='Nira-Bhima '!I745 -> 223 | D7: ='Bhodani Jalgaon ALephata'!I757 -> 1765.4 | E7: ='Gagargaon '!J747 -> 434.4 | F7: ='Indapur-Madha-Kandhar-Baramati'!X747 -> 2285.8 | H7: =SUM(C7:F7) -> 4708.6
B8: E | C8: ='Nira-Bhima '!I746 -> 203.6 | D8: ='Bhodani Jalgaon ALephata'!I758 -> 1641.7 | E8: ='Gagargaon '!J748 -> 361.5 | F8: ='Indapur-Madha-Kandhar-Baramati'!X748 -> 2626.9 | H8: =SUM(C8:F8) -> 4833.7 | L8: 15 | O8: =H8+H9-L8 -> 9372 | P8: 380.93 | Q8: =O8/P8 -> 24.602945
A9: 46026 | B9: M | C9: ='Nira-Bhima '!I747 -> 211 | D9: ='Bhodani Jalgaon ALephata'!I759 -> 1682.9 | E9: ='Gagargaon '!J749 -> 432.5 | F9: ='Indapur-Madha-Kandhar-Baramati'!X749 -> 2226.9 | H9: =SUM(C9:F9) -> 4553.3
B10: E | C10: ='Nira-Bhima '!I748 -> 208.1 | D10: ='Bhodani Jalgaon ALephata'!I760 -> 1644.3 | E10: ='Gagargaon '!J750 -> 349 | F10: ='Indapur-Madha-Kandhar-Baramati'!X750 -> 2562.2 | H10: =SUM(C10:F10) -> 4763.6 | L10: 15 | O10: =H10+H11-L10 -> 9615.9 | P10: 389.3 | Q10: =O10/P10 -> 24.700488
A11: 46027 | B11: M | C11: ='Nira-Bhima '!I749 -> 219.8 | D11: ='Bhodani Jalgaon ALephata'!I761 -> 1766 | E11: ='Gagargaon '!J751 -> 441.3 | F11: ='Indapur-Madha-Kandhar-Baramati'!X751 -> 2440.2 | H11: =SUM(C11:F11) -> 4867.3
B12: E | C12: ='Nira-Bhima '!I750 -> 228.3 | D12: ='Bhodani Jalgaon ALephata'!I762 -> 1518.5 | E12: ='Gagargaon '!J752 -> 373.3 | F12: ='Indapur-Madha-Kandhar-Baramati'!X752 -> 2557 | H12: =SUM(C12:F12) -> 4677.1 | L12: 15 | O12: =H12+H13-L12 -> 9553.6 | P12: 387.93 | Q12: =O12/P12 -> 24.627123
A13: 46028 | B13: M | C13: ='Nira-Bhima '!I751 -> 238.3 | D13: ='Bhodani Jalgaon ALephata'!I763 -> 1724.6 | E13: ='Gagargaon '!J753 -> 468 | F13: ='Indapur-Madha-Kandhar-Baramati'!X753 -> 2460.6 | H13: =SUM(C13:F13) -> 4891.5
B14: E | C14: ='Nira-Bhima '!I752 -> 215.1 | D14: ='Bhodani Jalgaon ALephata'!I764 -> 1629.9 | E14: ='Gagargaon '!J754 -> 359.2 | F14: ='Indapur-Madha-Kandhar-Baramati'!X754 -> 2528.2 | H14: =SUM(C14:F14) -> 4732.4 | L14: 15 | O14: =H14+H15-L14 -> 15113.5 | P14: 616.75 | Q14: =O14/P14 -> 24.505067
A15: 46029 | B15: M | C15: ='Nira-Bhima '!I753 -> 233.2 | D15: ='Bhodani Jalgaon ALephata'!I765 -> 7532.4 | E15: ='Gagargaon '!J755 -> 459.7 | F15: ='Indapur-Madha-Kandhar-Baramati'!X755 -> 2170.8 | H15: =SUM(C15:F15) -> 10396.1
B16: E | C16: ='Nira-Bhima '!I754 -> 222.2 | D16: ='Bhodani Jalgaon ALephata'!I766 -> 1746.2 | E16: ='Gagargaon '!J756 -> 377.3 | F16: ='Indapur-Madha-Kandhar-Baramati'!X756 -> 2457.5 | H16: =SUM(C16:F16) -> 4803.2 | L16: 15 | O16: =H16+H17-L16 -> 9704.9 | P16: 395.94 | Q16: =O16/P16 -> 24.511037
A17: 46030 | B17: M | C17: ='Nira-Bhima '!I755 -> 239.8 | D17: ='Bhodani Jalgaon ALephata'!I767 -> 1761.4 | E17: ='Gagargaon '!J757 -> 480.4 | F17: ='Indapur-Madha-Kandhar-Baramati'!X757 -> 2435.1 | H17: =SUM(C17:F17) -> 4916.7
B18: E | C18: ='Nira-Bhima '!I756 -> 230.1 | D18: ='Bhodani Jalgaon ALephata'!I768 -> 1491.8 | E18: ='Gagargaon '!J758 -> 391 | F18: ='Indapur-Madha-Kandhar-Baramati'!X758 -> 2551.6 | H18: =SUM(C18:F18) -> 4664.5 | L18: 15 | O18: =H18+H19-L18 -> 9661.7 | P18: 396.2 | Q18: =O18/P18 -> 24.385916
A19: 46031 | B19: M | C19: ='Nira-Bhima '!I757 -> 263 | D19: ='Bhodani Jalgaon ALephata'!I769 -> 1763.8 | E19: ='Gagargaon '!J759 -> 486.8 | F19: ='Indapur-Madha-Kandhar-Baramati'!X759 -> 2498.6 | H19: =SUM(C19:F19) -> 5012.2
B20: E | C20: ='Nira-Bhima '!I758 -> 215.7 | D20: ='Bhodani Jalgaon ALephata'!I770 -> 1653.1 | E20: ='Gagargaon '!J760 -> 389.7 | F20: ='Indapur-Madha-Kandhar-Baramati'!X760 -> 2624.5 | H20: =SUM(C20:F20) -> 4883 | L20: 15 | O20: =H20+H21-L20 -> 9701.4 | P20: 392.19 | Q20: =O20/P20 -> 24.73648
A21: 46032 | B21: M | C21: ='Nira-Bhima '!I759 -> 248.9 | D21: ='Bhodani Jalgaon ALephata'!I771 -> 1687.7 | E21: ='Gagargaon '!J761 -> 487.3 | F21: ='Indapur-Madha-Kandhar-Baramati'!X761 -> 2409.5 | H21: =SUM(C21:F21) -> 4833.4
B22: E | C22: ='Nira-Bhima '!I760 -> 213.4 | D22: ='Bhodani Jalgaon ALephata'!I772 -> 1646.6 | E22: ='Gagargaon '!J762 -> 393.7 | F22: ='Indapur-Madha-Kandhar-Baramati'!X762 -> 2528.2 | H22: =SUM(C22:F22) -> 4781.9 | L22: 15 | O22: =H22+H23-L22 -> 9834.5 | P22: 401.4 | Q22: =O22/P22 -> 24.500498
A23: 46033 | B23: M | C23: ='Nira-Bhima '!I768 -> 245.8 | D23: ='Bhodani Jalgaon ALephata'!I780 -> 1882 | E23: ='Gagargaon '!J770 -> 475.1 | F23: ='Indapur-Madha-Kandhar-Baramati'!X770 -> 2464.7 | H23: =SUM(C23:F23) -> 5067.6
B24: M | C24: ='Nira-Bhima '!I769 -> 248.4 | D24: ='Bhodani Jalgaon ALephata'!I781 -> 1599.4 | E24: ='Gagargaon '!J771 -> 398.7 | F24: ='Indapur-Madha-Kandhar-Baramati'!X771 -> 2648.3 | H24: =SUM(C24:F24) -> 4894.8 | L24: 15 | O24: =H24+H25-L24 -> 9955.1 | P24: 404.67 | Q24: =O24/P24 -> 24.600539
A25: 46034 | B25: E | C25: ='Nira-Bhima '!I770 -> 242.9 | D25: ='Bhodani Jalgaon ALephata'!I782 -> 1777.8 | E25: ='Gagargaon '!J772 -> 534.6 | F25: ='Indapur-Madha-Kandhar-Baramati'!X772 -> 2520 | H25: =SUM(C25:F25) -> 5075.3
B26: M | C26: ='Nira-Bhima '!I771 -> 231.8 | D26: ='Bhodani Jalgaon ALephata'!I783 -> 1700.2 | E26: ='Gagargaon '!J773 -> 401.7 | F26: ='Indapur-Madha-Kandhar-Baramati'!X773 -> 2506 | H26: =SUM(C26:F26) -> 4839.7 | L26: =15+125 -> 140 | O26: =H26+H27-L26 -> 9767.7 | P26: 397 | Q26: =O26/P26 -> 24.603778
A27: 46035 | B27: E | C27: ='Nira-Bhima '!I772 -> 261 | D27: ='Bhodani Jalgaon ALephata'!I784 -> 1795.2 | E27: ='Gagargaon '!J774 -> 523.9 | F27: ='Indapur-Madha-Kandhar-Baramati'!X774 -> 2487.9 | H27: =SUM(C27:F27) -> 5068
B28: M | C28: ='Nira-Bhima '!I773 -> 238.3 | D28: ='Bhodani Jalgaon ALephata'!I785 -> 1577.2 | E28: ='Gagargaon '!J775 -> 442.5 | F28: ='Indapur-Madha-Kandhar-Baramati'!X775 -> 2640.1 | H28: =SUM(C28:F28) -> 4898.1 | L28: 15 | O28: =H28+H29-L28 -> 9915.3 | P28: 401.4 | Q28: =O28/P28 -> 24.701794
A29: 46036 | B29: E | C29: ='Nira-Bhima '!I774 -> 255.4 | D29: ='Bhodani Jalgaon ALephata'!I786 -> 1788.9 | E29: ='Gagargaon '!J776 -> 553.3 | F29: ='Indapur-Madha-Kandhar-Baramati'!X776 -> 2434.6 | H29: =SUM(C29:F29) -> 5032.2
B30: M | C30: ='Nira-Bhima '!I775 -> 247.2 | D30: ='Bhodani Jalgaon ALephata'!I787 -> 1677.9 | E30: ='Gagargaon '!J777 -> 434.9 | F30: ='Indapur-Madha-Kandhar-Baramati'!X777 -> 2678.7 | H30: =SUM(C30:F30) -> 5038.7 | L30: 15 | O30: =H30+H31-L30 -> 9990.7 | P30: 404.48 | Q30: =O30/P30 -> 24.700109
A31: 46037 | B31: E | C31: ='Nira-Bhima '!I776 -> 277 | D31: ='Bhodani Jalgaon ALephata'!I788 -> 1799 | E31: ='Gagargaon '!J778 -> 544.7 | F31: ='Indapur-Madha-Kandhar-Baramati'!X778 -> 2346.3 | H31: =SUM(C31:F31) -> 4967
B32: M | C32: ='Nira-Bhima '!I777 -> 242.9 | D32: ='Bhodani Jalgaon ALephata'!I789 -> 1740.7 | E32: ='Gagargaon '!J779 -> 450.5 | F32: ='Indapur-Madha-Kandhar-Baramati'!X779 -> 2648.5 | H32: =SUM(C32:F32) -> 5082.6 | L32: 15 | O32: =H32+H33-L32 -> 9924.1 | P32: 403.41 | Q32: =O32/P32 -> 24.60053
A33: 46038 | B33: E | C33: ='Nira-Bhima '!I778 -> 255 | D33: ='Bhodani Jalgaon ALephata'!I790 -> 1790 | E33: ='Gagargaon '!J780 -> 491.2 | F33: ='Indapur-Madha-Kandhar-Baramati'!X780 -> 2320.3 | H33: =SUM(C33:F33) -> 4856.5
B34: M | C34: ='Nira-Bhima '!I779 -> 231.1 | D34: ='Bhodani Jalgaon ALephata'!I791 -> 1569.7 | E34: ='Gagargaon '!J781 -> 380.8 | F34: ='Indapur-Madha-Kandhar-Baramati'!X781 -> 2479 | H34: =SUM(C34:F34) -> 4660.6 | L34: 15 | O34: =H34+H35-L34 -> 9594.4 | P34: 388.43 | Q34: =O34/P34 -> 24.700461
A35: 46039 | B35: E | C35: ='Nira-Bhima '!I780 -> 259.7 | D35: ='Bhodani Jalgaon ALephata'!I792 -> 1759.8 | E35: ='Gagargaon '!J782 -> 505.4 | F35: ='Indapur-Madha-Kandhar-Baramati'!X782 -> 2423.9 | H35: =SUM(C35:F35) -> 4948.8
B36: M | C36: ='Nira-Bhima '!I781 -> 235.4 | D36: ='Bhodani Jalgaon ALephata'!I793 -> 1679.3 | E36: ='Gagargaon '!J783 -> 441.6 | F36: ='Indapur-Madha-Kandhar-Baramati'!X783 -> 2611.7 | H36: =SUM(C36:F36) -> 4968 | L36: 15 | O36: =H36+H37-L36 -> 9775.5 | P36: 397.37 | Q36: =O36/P36 -> 24.600498
A37: 46040 | B37: E | C37: ='Nira-Bhima '!I782 -> 277.1 | D37: ='Bhodani Jalgaon ALephata'!I794 -> 1682.8 | E37: ='Gagargaon '!J784 -> 500.2 | F37: ='Indapur-Madha-Kandhar-Baramati'!X784 -> 2362.4 | H37: =SUM(C37:F37) -> 4822.5
B38: M | C38: ='Nira-Bhima '!I783 -> 251.4 | D38: ='Bhodani Jalgaon ALephata'!I795 -> 1733.4 | E38: ='Gagargaon '!J785 -> 420.7 | F38: ='Indapur-Madha-Kandhar-Baramati'!X785 -> 2635.8 | H38: =SUM(C38:F38) -> 5041.3 | L38: 15 | O38: =H38+H39-L38 -> 10105.7 | P38: 409.13 | Q38: =O38/P38 -> 24.700462
A39: 46041 | B39: E | C39: ='Nira-Bhima '!I784 -> 280.2 | D39: ='Bhodani Jalgaon ALephata'!I796 -> 1781.6 | E39: ='Gagargaon '!J786 -> 514.5 | F39: ='Indapur-Madha-Kandhar-Baramati'!X786 -> 2503.1 | H39: =SUM(C39:F39) -> 5079.4
B40: M | C40: ='Nira-Bhima '!I785 -> 252.8 | D40: ='Bhodani Jalgaon ALephata'!I797 -> 1706.4 | E40: ='Gagargaon '!J787 -> 430.8 | F40: ='Indapur-Madha-Kandhar-Baramati'!X787 -> 2669.2 | H40: =SUM(C40:F40) -> 5059.2 | L40: =15+125 -> 140 | O40: =H40+H41-L40 -> 9980.2 | P40: 405.69 | Q40: =O40/P40 -> 24.600557
A41: 46042 | B41: E | C41: ='Nira-Bhima '!I786 -> 287.5 | D41: ='Bhodani Jalgaon ALephata'!I798 -> 1776 | E41: ='Gagargaon '!J788 -> 509.7 | F41: ='Indapur-Madha-Kandhar-Baramati'!X788 -> 2487.8 | H41: =SUM(C41:F41) -> 5061
...

Sheet Last3avg
A2: {=_xlfn.LET( _xlpm.src, 'Ghee Avarage'!A3:Q10000, _xlpm.colA, _xlfn.CHOOSECOLS(_xlpm.src, 1), _xlpm.colB, _xlfn.CHOOSECOLS(_xlpm.src, 2), _xlpm.colC, _xlfn.CHOOSECOLS(_xlpm.src, 3), _xlpm.colD, _xlfn.CHOOSECOLS(_xlpm.src, 4), _xlpm.colE, _xlfn.CHOOSECOLS(_xlpm.src, 5), _xlpm.colF, _xlfn.CHOOSECOLS(_xlpm.src, 6), _xlpm.colG, _xlfn.CHOOSECOLS(_xlpm.src, 7), _xlpm.colH, _xlfn.CHOOSECOLS(_xlpm.src, 8), _xlpm.colL, _xlfn.CHOOSECOLS(_xlpm.src, 12), _xlpm.colO, _xlfn.CHOOSECOLS(_xlpm.src, 15), _xlpm.colP, _xlfn.CHOOSECOLS(_xlpm.src, 16), _xlpm.colQ, _xlfn.CHOOSECOLS(_xlpm.src, 17), _xlpm.last_p, _xlfn.XMATCH(TRUE, IFERROR(_xlpm.colP > 0, FALSE), 0, -1), _xlpm.last, MIN(_xlpm.last_p + 1, ROWS(_xlpm.src)), _xlpm.r_A, _xlfn.TAKE(_xlpm.colA, _xlpm.last), _xlpm.r_B, _xlfn.TAKE(_xlpm.colB, _xlpm.last), _xlpm.r_C, _xlfn.TAKE(_xlpm.colC, _xlpm.last), _xlpm.r_D, _xlfn.TAKE(_xlpm.colD, _xlpm.last), _xlpm.r_E, _xlfn.TAKE(_xlpm.colE, _xlpm.last), _xlpm.r_F, _xlfn.TAKE(_xlpm.colF, _xlpm.last), _xlpm.r_G, _xlfn.TAKE(_xlpm.colG, _xlpm.last), _xlpm.r_H, _xlfn.TAKE(_xlpm.colH, _xlpm.last), _xlpm.r_L, _xlfn.TAKE(_xlpm.colL, _xlpm.last), _xlpm.r_O, _xlfn.TAKE(_xlpm.colO, _xlpm.last), _xlpm.r_P, _xlfn.TAKE(_xlpm.colP, _xlpm.last), _xlpm.r_Q, _xlfn.TAKE(_xlpm.colQ, _xlpm.last), _xlpm.d, _xlfn.SCAN(0, _xlpm.r_A, _xlfn.LAMBDA(_xlpm.a,_xlpm.b, IF(OR(_xlpm.b = 0, _xlpm.b = ""), _xlpm.a, _xlpm.b))), _xlpm.o, _xlfn.SCAN(0, _xlpm.r_O, _xlfn.LAMBDA(_xlpm.a,_xlpm.b, IF(OR(_xlpm.b = 0, _xlpm.b = ""), _xlpm.a, _xlpm.b))), _xlpm.pos, _xlfn._xlws.FILTER(_xlfn.SEQUENCE(_xlpm.last_p), IFERROR(_xlfn.TAKE(_xlpm.colO, _xlpm.last_p) <> 0, FALSE)), _xlpm.start, MIN(_xlfn.TAKE(_xlpm.pos, -3)), _xlfn.DROP( _xlfn.HSTACK( _xlpm.d, _xlpm.r_B, _xlpm.r_C, _xlpm.r_D, _xlpm.r_E, _xlpm.r_F, _xlpm.r_G, _xlpm.r_H, IF(_xlpm.r_B = "M", 0, _xlpm.r_L), IF(_xlpm.r_B = "M", 0, _xlpm.o), IF(_xlpm.r_B = "M", 0, _xlpm.r_P), IF(_xlpm.r_B = "M", 0, _xlpm.r_Q) ), _xlpm.start - 1 ) )} -> 46302 | B2: E | C2: 181.4 | D2: 9415.3 | E2: 334.9 | F2: 325.2 | G2: 109.4 | H2: 10366.2 | I2: 20 | J2: 11368.5 | K2: 487.58 | L2: 23.316174
A3: 46303 | B3: M | C3: 189.6 | D3: 9.3 | E3: 364.6 | F3: 356 | G3: 102.8 | H3: 1022.3 | I3: 0 | J3: 0 | K3: 0 | L3: 0
A4: 46303 | B4: E | C4: 179.2 | D4: 8030.6 | E4: 321.4 | F4: 323.8 | G4: 108.6 | H4: 8963.6 | I4: 20 | J4: 9973.8 | K4: 405.41 | L4: 24.601761
A5: 46304 | B5: M | C5: 180.4 | D5: 18 | E5: 370.8 | F5: 359.7 | G5: 101.3 | H5: 1030.2 | I5: 0 | J5: 0 | K5: 0 | L5: 0
A6: 46304 | B6: E | C6: 170.7 | D6: 9929 | E6: 319.1 | F6: 287.2 | G6: 112.2 | H6: 10818.2 | I6: 20 | J6: 11772.1 | K6: 510.82 | L6: 23.045495
A7: 46305 | B7: M | C7: 142.9 | D7: 19.2 | E7: 359.7 | F7: 347.9 | G7: 104.2 | H7: 973.9 | I7: 0 | J7: 0 | K7: 0 | L7: 0

Sheet ICE 
B1: TWO BROTHERS ORGANIC FARM
B2: Bhodani Vakilwasti Road, Bhodani, Taluka-Indapur, District-Pune, Maharashtra-413103
B3: ICE PURCHASE
B4: Overall
A5: Sr No | B5: Date | C5: Received ICE Qty | D5: Rate | E5: Amount | F5: Debited ICE Block (Quatity)
A6: 1 | B6: 46296 | C6: 30 | D6: 225 | E6: =+C6*D6 -> 6750
A7: 2 | B7: 46297 | C7: 30 | D7: 225 | E7: =+C7*D7 -> 6750
A8: 3 | B8: 46298 | C8: 15 | D8: 225 | E8: =+C8*D8 -> 3375
A9: 4 | B9: 46299 | C9: 33 | D9: 225 | E9: =+C9*D9 -> 7425 | G9: 18 Loose
A10: 5 | B10: 46300 | C10: 35 | D10: 225 | E10: =+C10*D10 -> 7875
A11: 6 | B11: 46301 | C11: 30 | D11: 225 | E11: =+C11*D11 -> 6750 | G11: 4 loose
A12: 7 | B12: 46302 | C12: 40 | D12: 225 | E12: =+C12*D12 -> 9000
A13: 8 | B13: 46303 | C13: 35 | D13: 225 | E13: =+C13*D13 -> 7875
A14: 9 | B14: 46304 | C14: 45 | D14: 225 | E14: =+C14*D14 -> 10125
A15: 10 | B15: 46305 | C15: 20 | D15: 225 | E15: =+C15*D15 -> 4500
A16: 11 | B16: 46306 | C16: 15 | D16: 225 | E16: =+C16*D16 -> 3375
A17: 12 | B17: 46307 | C17: 35 | D17: 225 | E17: =+C17*D17 -> 7875
A18: 13 | B18: 46308 | C18: 30 | D18: 225 | E18: =+C18*D18 -> 6750
A19: 14 | B19: 46309 | D19: 225 | E19: =+C19*D19 -> 0
A20: 15 | B20: 46310 | D20: 225 | E20: =+C20*D20 -> 0
A21: 16 | B21: 46311 | D21: 225 | E21: =+C21*D21 -> 0
A22: 17 | B22: 46312 | D22: 225 | E22: =+C22*D22 -> 0
A23: 18 | B23: 46313 | D23: 225 | E23: =+C23*D23 -> 0
A24: 19 | B24: 46314 | D24: 225 | E24: =+C24*D24 -> 0
A25: 20 | B25: 46315 | D25: 225 | E25: =+C25*D25 -> 0
A26: 21 | B26: 46316 | D26: 225 | E26: =+C26*D26 -> 0
A27: 22 | B27: 46317 | D27: 225 | E27: =+C27*D27 -> 0
A28: 23 | B28: 46318 | D28: 225 | E28: =+C28*D28 -> 0
A29: 24 | B29: 46319 | D29: 225 | E29: =+C29*D29 -> 0
A30: 25 | B30: 46320 | D30: 225 | E30: =+C30*D30 -> 0
... A35: 30 | B35: 46325 | D35: 225 | E35: =+C35*D35 -> 0
A36: 31 | B36: 46326
B37: Total | C37: =SUM(C6:C36) -> 393 | E37: =SUM(E6:E36) -> 88425
A38: 1 | B38: 46266 | C38: 35 | D38: 225 | E38: =+C38*D38 -> 7875
A39: 2 | B39: 46267 | C39: 30 | D39: 225 | E39: =+C39*D39 -> 6750
A40: 3 | B40: 46268 | C40: 40 | D40: 225 | E40: =+C40*D40 -> 9000
A41: 4 | B41: 46269 | C41: 35 | D41: 225 | E41: =+C41*D41 -> 7875
A42: 5 | B42: 46270 | C42: 40 | D42: 225 | E42: =+C42*D42 -> 9000
A43: 6 | B43: 46271 | C43: 35 | D43: 225 | E43: =+C43*D43 -> 7875
A44: 7 | B44: 46272 | C44: 40 | D44: 225 | E44: =+C44*D44 -> 9000
...
