Workbook

Sheet Dashboard
A1: ATTA PRODUCTION COMMAND CENTER
A3: ="Live production overview • "&TEXT(MIN(_xlfn.CHOOSECOLS(_xlfn.ANCHORARRAY(Automation!$B$2),2)),"dd-mmm-yy")&" to "&TEXT(MAX(_xlfn.CHOOSECOLS(_xlfn.ANCHORARRAY(Automation!$B$2),2)),"dd-mmm-yy")&" • "&COUNTA(Automation!$A$2:$A$50)&" registered source sheets" -> Live production overview • 02-Jan-26 to 12-Oct-26 • 18 registered source sheets
A5: TOTAL INPUT RM | D5: TOTAL OUTPUT | G5: WEIGHTED YIELD | J5: TOTAL WASTAGE | M5: VISIBLE RECORDS
A6: =SUBTOTAL(109,F42:F5000) -> 2126566.3 | D6: =SUBTOTAL(109,L42:L5000) -> 1975211.3 | G6: =IFERROR(D6/A6,0) -> 0.92882658 | J6: =SUBTOTAL(109,K42:K5000) -> 151632.7 | M6: =SUBTOTAL(103,A42:A5000) -> 586
A8: SORTING WASTE | D8: TOTAL BRAN | G8: FLOOR WASTE | J8: PROCESS LOSS | M8: WASTE RATE
A9: =SUBTOTAL(109,G42:G5000) -> 12158.8 | D9: =SUBTOTAL(109,H42:H5000) -> 55939.42 | G9: =SUBTOTAL(109,I42:I5000) -> 6014.68 | J9: =SUBTOTAL(109,J42:J5000) -> 77883.8 | M9: =IFERROR(J6/A6,0) -> 0.071304008
A10: MONTHLY PRODUCTION — 2026
A11: Month | B11: Input (kg) | C11: Output (kg) | D11: Wastage (kg) | E11: Yield
A12: 46023 | B12: {=SUM(_xlfn._xlws.FILTER(_xlfn.CHOOSECOLS(_xlfn.ANCHORARRAY(Automation!$B$2),6),(_xlfn.CHOOSECOLS(_xlfn.ANCHORARRAY(Automation!$B$2),2)>=A12)*(_xlfn.CHOOSECOLS(_xlfn.ANCHORARRAY(Automation!$B$2),2)<EDATE(A12,1)),0))} -> 222831.94 | C12: {=SUM(_xlfn._xlws.FILTER(_xlfn.CHOOSECOLS(_xlfn.ANCHORARRAY(Automation!$B$2),12),(_xlfn.CHOOSECOLS(_xlfn.ANCHORARRAY(Automation!$B$2),2)>=A12)*(_xlfn.CHOOSECOLS(_xlfn.ANCHORARRAY(Automation!$B$2),2)<EDATE(A12,1)),0))} -> 206866 | D12: {=SUM(_xlfn._xlws.FILTER(_xlfn.CHOOSECOLS(_xlfn.ANCHORARRAY(Automation!$B$2),11),(_xlfn.CHOOSECOLS(_xlfn.ANCHORARRAY(Automation!$B$2),2)>=A12)*(_xlfn.CHOOSECOLS(_xlfn.ANCHORARRAY(Automation!$B$2),2)<EDATE(A12,1)),0))} -> 16009.94 | E12: =IFERROR(C12/B12,0) -> 0.92834986
A13: 46054 | B13: {=SUM(_xlfn._xlws.FILTER(_xlfn.CHOOSECOLS(_xlfn.ANCHORARRAY(Automation!$B$2),6),(_xlfn.CHOOSECOLS(_xlfn.ANCHORARRAY(Automation!$B$2),2)>=A13)*(_xlfn.CHOOSECOLS(_xlfn.ANCHORARRAY(Automation!$B$2),2)<EDATE(A13,1)),0))} -> 203017.28 | C13: {=SUM(_xlfn._xlws.FILTER(_xlfn.CHOOSECOLS(_xlfn.ANCHORARRAY(Automation!$B$2),12),(_xlfn.CHOOSECOLS(_xlfn.ANCHORARRAY(Automation!$B$2),2)>=A13)*(_xlfn.CHOOSECOLS(_xlfn.ANCHORARRAY(Automation!$B$2),2)<EDATE(A13,1)),0))} -> 188374.3 | D13: {=SUM(_xlfn._xlws.FILTER(_xlfn.CHOOSECOLS(_xlfn.ANCHORARRAY(Automation!$B$2),11),(_xlfn.CHOOSECOLS(_xlfn.ANCHORARRAY(Automation!$B$2),2)>=A13)*(_xlfn.CHOOSECOLS(_xlfn.ANCHORARRAY(Automation!$B$2),2)<EDATE(A13,1)),0))} -> 14642.98 | E13: =IFERROR(C13/B13,0) -> 0.92787323
A14: 46082 | B14: {=SUM(_xlfn._xlws.FILTER(_xlfn.CHOOSECOLS(_xlfn.ANCHORARRAY(Automation!$B$2),6),(_xlfn.CHOOSECOLS(_xlfn.ANCHORARRAY(Automation!$B$2),2)>=A14)*(_xlfn.CHOOSECOLS(_xlfn.ANCHORARRAY(Automation!$B$2),2)<EDATE(A14,1)),0))} -> 127840 | C14: {=SUM(_xlfn._xlws.FILTER(_xlfn.CHOOSECOLS(_xlfn.ANCHORARRAY(Automation!$B$2),12),(_xlfn.CHOOSECOLS(_xlfn.ANCHORARRAY(Automation!$B$2),2)>=A14)*(_xlfn.CHOOSECOLS(_xlfn.ANCHORARRAY(Automation!$B$2),2)<EDATE(A14,1)),0))} -> 120427.6 | D14: {=SUM(_xlfn._xlws.FILTER(_xlfn.CHOOSECOLS(_xlfn.ANCHORARRAY(Automation!$B$2),11),(_xlfn.CHOOSECOLS(_xlfn.ANCHORARRAY(Automation!$B$2),2)>=A14)*(_xlfn.CHOOSECOLS(_xlfn.ANCHORARRAY(Automation!$B$2),2)<EDATE(A14,1)),0))} -> 7677.1 | E14: =IFERROR(C14/B14,0) -> 0.94201815
A15: 46113 | B15: {=SUM(_xlfn._xlws.FILTER(_xlfn.CHOOSECOLS(_xlfn.ANCHORARRAY(Automation!$B$2),6),(_xlfn.CHOOSECOLS(_xlfn.ANCHORARRAY(Automation!$B$2),2)>=A15)*(_xlfn.CHOOSECOLS(_xlfn.ANCHORARRAY(Automation!$B$2),2)<EDATE(A15,1)),0))} -> 212986 | C15: {=SUM(_xlfn._xlws.FILTER(_xlfn.CHOOSECOLS(_xlfn.ANCHORARRAY(Automation!$B$2),12),(_xlfn.CHOOSECOLS(_xlfn.ANCHORARRAY(Automation!$B$2),2)>=A15)*(_xlfn.CHOOSECOLS(_xlfn.ANCHORARRAY(Automation!$B$2),2)<EDATE(A15,1)),0))} -> 197138 | D15: {=SUM(_xlfn._xlws.FILTER(_xlfn.CHOOSECOLS(_xlfn.ANCHORARRAY(Automation!$B$2),11),(_xlfn.CHOOSECOLS(_xlfn.ANCHORARRAY(Automation!$B$2),2)>=A15)*(_xlfn.CHOOSECOLS(_xlfn.ANCHORARRAY(Automation!$B$2),2)<EDATE(A15,1)),0))} -> 15949 | E15: =IFERROR(C15/B15,0) -> 0.92559135
A16: 46143 | B16: {=SUM(_xlfn._xlws.FILTER(_xlfn.CHOOSECOLS(_xlfn.ANCHORARRAY(Automation!$B$2),6),(_xlfn.CHOOSECOLS(_xlfn.ANCHORARRAY(Automation!$B$2),2)>=A16)*(_xlfn.CHOOSECOLS(_xlfn.ANCHORARRAY(Automation!$B$2),2)<EDATE(A16,1)),0))} -> 194211 | C16: {=SUM(_xlfn._xlws.FILTER(_xlfn.CHOOSECOLS(_xlfn.ANCHORARRAY(Automation!$B$2),12),(_xlfn.CHOOSECOLS(_xlfn.ANCHORARRAY(Automation!$B$2),2)>=A16)*(_xlfn.CHOOSECOLS(_xlfn.ANCHORARRAY(Automation!$B$2),2)<EDATE(A16,1)),0))} -> 180921.4 | D16: {=SUM(_xlfn._xlws.FILTER(_xlfn.CHOOSECOLS(_xlfn.ANCHORARRAY(Automation!$B$2),11),(_xlfn.CHOOSECOLS(_xlfn.ANCHORARRAY(Automation!$B$2),2)>=A16)*(_xlfn.CHOOSECOLS(_xlfn.ANCHORARRAY(Automation!$B$2),2)<EDATE(A16,1)),0))} -> 13287.6 | E16: =IFERROR(C16/B16,0) -> 0.93157133
A17: 46174 | B17: {=SUM(_xlfn._xlws.FILTER(_xlfn.CHOOSECOLS(_xlfn.ANCHORARRAY(Automation!$B$2),6),(_xlfn.CHOOSECOLS(_xlfn.ANCHORARRAY(Automation!$B$2),2)>=A17)*(_xlfn.CHOOSECOLS(_xlfn.ANCHORARRAY(Automation!$B$2),2)<EDATE(A17,1)),0))} -> 170858.78 | C17: {=SUM(_xlfn._xlws.FILTER(_xlfn.CHOOSECOLS(_xlfn.ANCHORARRAY(Automation!$B$2),12),(_xlfn.CHOOSECOLS(_xlfn.ANCHORARRAY(Automation!$B$2),2)>=A17)*(_xlfn.CHOOSECOLS(_xlfn.ANCHORARRAY(Automation!$B$2),2)<EDATE(A17,1)),0))} -> 158518 | D17: {=SUM(_xlfn._xlws.FILTER(_xlfn.CHOOSECOLS(_xlfn.ANCHORARRAY(Automation!$B$2),11),(_xlfn.CHOOSECOLS(_xlfn.ANCHORARRAY(Automation!$B$2),2)>=A17)*(_xlfn.CHOOSECOLS(_xlfn.ANCHORARRAY(Automation!$B$2),2)<EDATE(A17,1)),0))} -> 12340.78 | E17: =IFERROR(C17/B17,0) -> 0.92777205
A18: 46204 | B18: {=SUM(_xlfn._xlws.FILTER(_xlfn.CHOOSECOLS(_xlfn.ANCHORARRAY(Automation!$B$2),6),(_xlfn.CHOOSECOLS(_xlfn.ANCHORARRAY(Automation!$B$2),2)>=A18)*(_xlfn.CHOOSECOLS(_xlfn.ANCHORARRAY(Automation!$B$2),2)<EDATE(A18,1)),0))} -> 224350.5 | C18: {=SUM(_xlfn._xlws.FILTER(_xlfn.CHOOSECOLS(_xlfn.ANCHORARRAY(Automation!$B$2),12),(_xlfn.CHOOSECOLS(_xlfn.ANCHORARRAY(Automation!$B$2),2)>=A18)*(_xlfn.CHOOSECOLS(_xlfn.ANCHORARRAY(Automation!$B$2),2)<EDATE(A18,1)),0))} -> 206773 | D18: {=SUM(_xlfn._xlws.FILTER(_xlfn.CHOOSECOLS(_xlfn.ANCHORARRAY(Automation!$B$2),11),(_xlfn.CHOOSECOLS(_xlfn.ANCHORARRAY(Automation!$B$2),2)>=A18)*(_xlfn.CHOOSECOLS(_xlfn.ANCHORARRAY(Automation!$B$2),2)<EDATE(A18,1)),0))} -> 17577.5 | E18: =IFERROR(C18/B18,0) -> 0.92165161
A19: 46235 | B19: {=SUM(_xlfn._xlws.FILTER(_xlfn.CHOOSECOLS(_xlfn.ANCHORARRAY(Automation!$B$2),6),(_xlfn.CHOOSECOLS(_xlfn.ANCHORARRAY(Automation!$B$2),2)>=A19)*(_xlfn.CHOOSECOLS(_xlfn.ANCHORARRAY(Automation!$B$2),2)<EDATE(A19,1)),0))} -> 299859 | C19: {=SUM(_xlfn._xlws.FILTER(_xlfn.CHOOSECOLS(_xlfn.ANCHORARRAY(Automation!$B$2),12),(_xlfn.CHOOSECOLS(_xlfn.ANCHORARRAY(Automation!$B$2),2)>=A19)*(_xlfn.CHOOSECOLS(_xlfn.ANCHORARRAY(Automation!$B$2),2)<EDATE(A19,1)),0))} -> 277493 | D19: {=SUM(_xlfn._xlws.FILTER(_xlfn.CHOOSECOLS(_xlfn.ANCHORARRAY(Automation!$B$2),11),(_xlfn.CHOOSECOLS(_xlfn.ANCHORARRAY(Automation!$B$2),2)>=A19)*(_xlfn.CHOOSECOLS(_xlfn.ANCHORARRAY(Automation!$B$2),2)<EDATE(A19,1)),0))} -> 22366 | E19: =IFERROR(C19/B19,0) -> 0.92541161
A20: 46266 | B20: {=SUM(_xlfn._xlws.FILTER(_xlfn.CHOOSECOLS(_xlfn.ANCHORARRAY(Automation!$B$2),6),(_xlfn.CHOOSECOLS(_xlfn.ANCHORARRAY(Automation!$B$2),2)>=A20)*(_xlfn.CHOOSECOLS(_xlfn.ANCHORARRAY(Automation!$B$2),2)<EDATE(A20,1)),0))} -> 342414.3 | C20: {=SUM(_xlfn._xlws.FILTER(_xlfn.CHOOSECOLS(_xlfn.ANCHORARRAY(Automation!$B$2),12),(_xlfn.CHOOSECOLS(_xlfn.ANCHORARRAY(Automation!$B$2),2)>=A20)*(_xlfn.CHOOSECOLS(_xlfn.ANCHORARRAY(Automation!$B$2),2)<EDATE(A20,1)),0))} -> 319559 | D20: {=SUM(_xlfn._xlws.FILTER(_xlfn.CHOOSECOLS(_xlfn.ANCHORARRAY(Automation!$B$2),11),(_xlfn.CHOOSECOLS(_xlfn.ANCHORARRAY(Automation!$B$2),2)>=A20)*(_xlfn.CHOOSECOLS(_xlfn.ANCHORARRAY(Automation!$B$2),2)<EDATE(A20,1)),0))} -> 22725.3 | E20: =IFERROR(C20/B20,0) -> 0.9332525
A21: 46296 | B21: {=SUM(_xlfn._xlws.FILTER(_xlfn.CHOOSECOLS(_xlfn.ANCHORARRAY(Automation!$B$2),6),(_xlfn.CHOOSECOLS(_xlfn.ANCHORARRAY(Automation!$B$2),2)>=A21)*(_xlfn.CHOOSECOLS(_xlfn.ANCHORARRAY(Automation!$B$2),2)<EDATE(A21,1)),0))} -> 128197.5 | C21: {=SUM(_xlfn._xlws.FILTER(_xlfn.CHOOSECOLS(_xlfn.ANCHORARRAY(Automation!$B$2),12),(_xlfn.CHOOSECOLS(_xlfn.ANCHORARRAY(Automation!$B$2),2)>=A21)*(_xlfn.CHOOSECOLS(_xlfn.ANCHORARRAY(Automation!$B$2),2)<EDATE(A21,1)),0))} -> 119141 | D21: {=SUM(_xlfn._xlws.FILTER(_xlfn.CHOOSECOLS(_xlfn.ANCHORARRAY(Automation!$B$2),11),(_xlfn.CHOOSECOLS(_xlfn.ANCHORARRAY(Automation!$B$2),2)>=A21)*(_xlfn.CHOOSECOLS(_xlfn.ANCHORARRAY(Automation!$B$2),2)<EDATE(A21,1)),0))} -> 9056.5 | E21: =IFERROR(C21/B21,0) -> 0.9293551
A22: 46327 | B22: {=SUM(_xlfn._xlws.FILTER(_xlfn.CHOOSECOLS(_xlfn.ANCHORARRAY(Automation!$B$2),6),(_xlfn.CHOOSECOLS(_xlfn.ANCHORARRAY(Automation!$B$2),2)>=A22)*(_xlfn.CHOOSECOLS(_xlfn.ANCHORARRAY(Automation!$B$2),2)<EDATE(A22,1)),0))} -> 0 | C22: {=SUM(_xlfn._xlws.FILTER(_xlfn.CHOOSECOLS(_xlfn.ANCHORARRAY(Automation!$B$2),12),(_xlfn.CHOOSECOLS(_xlfn.ANCHORARRAY(Automation!$B$2),2)>=A22)*(_xlfn.CHOOSECOLS(_xlfn.ANCHORARRAY(Automation!$B$2),2)<EDATE(A22,1)),0))} -> 0 | D22: {=SUM(_xlfn._xlws.FILTER(_xlfn.CHOOSECOLS(_xlfn.ANCHORARRAY(Automation!$B$2),11),(_xlfn.CHOOSECOLS(_xlfn.ANCHORARRAY(Automation!$B$2),2)>=A22)*(_xlfn.CHOOSECOLS(_xlfn.ANCHORARRAY(Automation!$B$2),2)<EDATE(A22,1)),0))} -> 0 | E22: =IFERROR(C22/B22,0) -> 0
A23: 46357 | B23: {=SUM(_xlfn._xlws.FILTER(_xlfn.CHOOSECOLS(_xlfn.ANCHORARRAY(Automation!$B$2),6),(_xlfn.CHOOSECOLS(_xlfn.ANCHORARRAY(Automation!$B$2),2)>=A23)*(_xlfn.CHOOSECOLS(_xlfn.ANCHORARRAY(Automation!$B$2),2)<EDATE(A23,1)),0))} -> 0 | C23: {=SUM(_xlfn._xlws.FILTER(_xlfn.CHOOSECOLS(_xlfn.ANCHORARRAY(Automation!$B$2),12),(_xlfn.CHOOSECOLS(_xlfn.ANCHORARRAY(Automation!$B$2),2)>=A23)*(_xlfn.CHOOSECOLS(_xlfn.ANCHORARRAY(Automation!$B$2),2)<EDATE(A23,1)),0))} -> 0 | D23: {=SUM(_xlfn._xlws.FILTER(_xlfn.CHOOSECOLS(_xlfn.ANCHORARRAY(Automation!$B$2),11),(_xlfn.CHOOSECOLS(_xlfn.ANCHORARRAY(Automation!$B$2),2)>=A23)*(_xlfn.CHOOSECOLS(_xlfn.ANCHORARRAY(Automation!$B$2),2)<EDATE(A23,1)),0))} -> 0 | E23: =IFERROR(C23/B23,0) -> 0
A25: PLANT GROUP PERFORMANCE
A26: Group | B26: Input (kg) | C26: Output (kg) | D26: Wastage (kg) | E26: Yield
A27: C6 | B27: {=SUM(_xlfn._xlws.FILTER(_xlfn.CHOOSECOLS(_xlfn.ANCHORARRAY(Automation!$B$2),6),ISNUMBER(SEARCH($A27,_xlfn.CHOOSECOLS(_xlfn.ANCHORARRAY(Automation!$B$2),1))),0))} -> 726377.58 | C27: {=SUM(_xlfn._xlws.FILTER(_xlfn.CHOOSECOLS(_xlfn.ANCHORARRAY(Automation!$B$2),12),ISNUMBER(SEARCH($A27,_xlfn.CHOOSECOLS(_xlfn.ANCHORARRAY(Automation!$B$2),1))),0))} -> 674041.3 | D27: {=SUM(_xlfn._xlws.FILTER(_xlfn.CHOOSECOLS(_xlfn.ANCHORARRAY(Automation!$B$2),11),ISNUMBER(SEARCH($A27,_xlfn.CHOOSECOLS(_xlfn.ANCHORARRAY(Automation!$B$2),1))),0))} -> 52472.28 | E27: =IFERROR(C27/B27,0) -> 0.92794893
A28: C39 | B28: {=SUM(_xlfn._xlws.FILTER(_xlfn.CHOOSECOLS(_xlfn.ANCHORARRAY(Automation!$B$2),6),ISNUMBER(SEARCH($A28,_xlfn.CHOOSECOLS(_xlfn.ANCHORARRAY(Automation!$B$2),1))),0))} -> 1400188.7 | C28: {=SUM(_xlfn._xlws.FILTER(_xlfn.CHOOSECOLS(_xlfn.ANCHORARRAY(Automation!$B$2),12),ISNUMBER(SEARCH($A28,_xlfn.CHOOSECOLS(_xlfn.ANCHORARRAY(Automation!$B$2),1))),0))} -> 1301170 | D28: {=SUM(_xlfn._xlws.FILTER(_xlfn.CHOOSECOLS(_xlfn.ANCHORARRAY(Automation!$B$2),11),ISNUMBER(SEARCH($A28,_xlfn.CHOOSECOLS(_xlfn.ANCHORARRAY(Automation!$B$2),1))),0))} -> 99160.42 | E28: =IFERROR(C28/B28,0) -> 0.92928188
A30: TOP PRODUCTS BY OUTPUT
A31: Product | B31: Output (kg)
A32: {=_xlfn.LET(_xlpm.raw,UPPER(TRIM(_xlfn.CHOOSECOLS(_xlfn.ANCHORARRAY(Automation!$B$2),5))),_xlpm.p,IF(_xlpm.raw="MULTGRAIN","MULTIGRAIN",_xlpm.raw),_xlpm.o,_xlfn.CHOOSECOLS(_xlfn.ANCHORARRAY(Automation!$B$2),12),_xlpm.u,_xlfn.UNIQUE(_xlfn._xlws.FILTER(_xlpm.p,_xlpm.p<>"")),_xlpm.z,_xlfn.MAP(_xlpm.u,_xlfn.LAMBDA(_xlpm.x,SUM(_xlfn._xlws.FILTER(_xlpm.o,_xlpm.p=_xlpm.x,0)))),_xlfn.TAKE(_xlfn.SORTBY(_xlfn.HSTACK(_xlpm.u,_xlpm.z),_xlpm.z,-1),7))} -> MULTIGRAIN | B32: 1029675.3
A33: KHAPLI | B33: 433252
A34: KHAPLI PROTEIN GRAINS | B34: 152813.5
A35: HIGH PROTEIN ATTA | B35: 88375.5
A36: KHAPLI GRAINS | B36: 50607
A37: KHAPLI WHEAT GRAINS | B37: 32338
A38: JOWAR GRAINS | B38: 30867.5
A40: ALL PRODUCTION RECORDS — USE HEADER DROPDOWNS TO FILTER DATE, PLANT, PRODUCT, SHIFT & MORE
A41: Source Sheet | B41: Date | C41: Machine | D41: Plant | E41: Product | F41: IN in Kg | G41: Sorting | H41: Bran | I41: Floor Atta | J41: Process Loss | K41: Total Wastage | L41: OUT in Kg | M41: Manpower | N41: Shift | O41: Yield % | P41: Mass Balance | Q41: Variance
A42: {=_xlfn.ANCHORARRAY(Automation!B2)} -> C6 JAN-FEB | B42: 46024 | C42: Chakki1,2&3 | D42: C6 | E42: Jowar | F42: 1900 | G42: 0 | H42: 18 | I42: 2 | J42: 132 | K42: 152 | L42: 1748 | M42: 0 | N42: 0 | O42: 0.92 | P42: 1900 | Q42: 0
A43: C6 JAN-FEB | B43: 46024 | C43: Chakki1,2&3 | D43: C6 | E43: Jowar | F43: 2450 | G43: 0 | H43: 104 | I43: 3 | J43: 163 | K43: 270 | L43: 2180 | M43: 0 | N43: 0 | O43: 0.88979592 | P43: 2450 | Q43: 0
A44: C6 JAN-FEB | B44: 46025 | C44: Chakki1,2&3 | D44: C6 | E44: Bajra | F44: 2850 | G44: 0 | H44: 67 | I44: 2 | J44: 183 | K44: 252 | L44: 2598 | M44: 0 | N44: 0 | O44: 0.91157895 | P44: 2850 | Q44: 0
A45: C6 JAN-FEB | B45: 46026 | C45: Chakki1,2&3 | D45: C6 | E45: Multigrain | F45: 1450 | G45: 0 | H45: 18 | I45: 1 | J45: 121 | K45: 140 | L45: 1310 | M45: 3 | N45: Day | O45: 0.90344828 | P45: 1450 | Q45: 0
A46: C6 JAN-FEB | B46: 46026 | C46: Chakki1,2&3 | D46: C6 | E46: Multigrain | F46: 2250 | G46: 0 | H46: 21 | I46: 2 | J46: 162 | K46: 185 | L46: 2065 | M46: 3 | N46: Night | O46: 0.91777778 | P46: 2250 | Q46: 0
...

Sheet C6 JAN-FEB
A2: Atta Production Report
A3: Date | B3: Machine | C3: Plant | D3: Product | E3: IN in Kg | F3: Sorting | G3: Bran | H3: Floor Atta | I3: Process Loss | J3: Total Wastage | K3: OUT in Kg | L3: Manpower | M3: SHIFT | N3: Yield %
F4: Grader | G4: Sieve | H4: Floor | I4: Process Loss
A5: 46024 | B5: Chakki1,2&3 | C5: C6 | D5: Jowar | E5: 1900 | F5: 0 | G5: 18 | H5: 2 | I5: 132 | J5: =F5+G5+H5+I5 -> 152 | K5: 1748 | N5: =K5/E5*100 -> 92 | O5: =K5+J5 -> 1900 | P5: =E5-O5 -> 0
A6: 46024 | B6: Chakki1,2&3 | C6: C6 | D6: Jowar | E6: 2450 | F6: 0 | G6: 104 | H6: 3 | I6: 163 | J6: =F6+G6+H6+I6 -> 270 | K6: 2180 | N6: =K6/E6*100 -> 88.979592 | O6: =K6+J6 -> 2450 | P6: 0
A7: 46025 | B7: Chakki1,2&3 | C7: C6 | D7: Bajra | E7: 2850 | F7: 0 | G7: 67 | H7: 2 | I7: 183 | J7: =F7+G7+H7+I7 -> 252 | K7: =2585+13 -> 2598 | N7: =K7/E7*100 -> 91.157895 | O7: =K7+J7 -> 2850 | P7: =E7-O7 -> 0
B8: Chakki1,2&3 | C8: C6 | D8: Jowar | E8: =173.92+1138.7 -> 1312.62 | I8: 13.92 | J8: =F8+G8+H8+I8 -> 13.92 | K8: =160+1047.6 -> 1207.6 | N8: =K8/E8*100 -> 91.999208 | O8: =K8+J8 -> 1221.52 | P8: =E8-O8 -> 91.1
A9: 46026 | B9: Chakki1,2&3 | C9: C6 | D9: Multigrain | E9: 1450 | F9: 0 | G9: 18 | H9: 1 | I9: 121 | J9: =F9+G9+H9+I9 -> 140 | K9: 1310 | L9: 3 | M9: Day | N9: =K9/E9*100 -> 90.344828 | O9: =K9+J9 -> 1450 | P9: =E9-O9 -> 0
A10: 46026 | B10: Chakki1,2&3 | C10: C6 | D10: Multigrain | E10: 2250 | F10: 0 | G10: 21 | H10: 2 | I10: 162 | J10: =F10+G10+H10+I10 -> 185 | K10: 2065 | L10: 3 | M10: Night | N10: =K10/E10*100 -> 91.777778 | O10: =K10+J10 -> 2250 | P10: =E10-O10 -> 0
A11: 46027 | B11: Chakki1,2&3 | C11: C6 | D11: Multigrain | E11: 1350 | F11: 0 | G11: 10 | H11: 3 | I11: 118 | J11: =F11+G11+H11+I11 -> 131 | K11: 1219 | L11: 3 | M11: Day | N11: =K11/E11*100 -> 90.296296 | O11: =K11+J11 -> 1350 | P11: =E11-O11 -> 0
A12: 46027 | B12: Chakki1,2&3 | C12: C6 | D12: Khapli | E12: 3019.5 | F12: 1 | G12: 120 | H12: 1 | I12: 179.5 | J12: =F12+G12+H12+I12 -> 301.5 | K12: 2718 | L12: 3 | M12: Night | N12: =K12/E12*100 -> 90.014903 | O12: =K12+J12 -> 3019.5 | P12: =E12-O12 -> 0
A13: 46028 | B13: Chakki1,2&3 | C13: C6 | D13: Khapli | E13: 2178 | F13: 0 | G13: 85 | H13: 2 | I13: 35 | J13: =F13+G13+H13+I13 -> 122 | K13: 2056 | L13: 3 | M13: Day | N13: =K13/E13*100 -> 94.398531 | O13: =K13+J13 -> 2178 | P13: =E13-O13 -> 0
A14: 46028 | B14: Chakki1,2&3 | C14: C6 | D14: Multigrain | E14: 3700 | F14: 0 | G14: 90 | H14: 2 | I14: 246 | J14: =F14+G14+H14+I14 -> 338 | K14: 3362 | L14: 3 | M14: Night | N14: =K14/E14*100 -> 90.864865 | O14: =K14+J14 -> 3700 | P14: =E14-O14 -> 0
A15: 46029 | B15: Chakki1,2&3 | C15: C6 | D15: Multigrain | E15: 2400 | F15: 0 | G15: 19 | H15: 3 | I15: 195 | J15: =F15+G15+H15+I15 -> 217 | K15: 2183 | L15: 3 | M15: Day | N15: =K15/E15*100 -> 90.958333 | O15: =K15+J15 -> 2400 | P15: =E15-O15 -> 0
A16: 46029 | B16: Chakki1,2&3 | C16: C6 | D16: Multigrain | E16: 3750 | F16: 0 | G16: 110 | H16: 4 | I16: 214 | J16: =F16+G16+H16+I16 -> 328 | K16: 3422 | L16: 3 | M16: Night | N16: =K16/E16*100 -> 91.253333 | O16: =K16+J16 -> 3750 | P16: =E16-O16 -> 0
A17: 46030 | B17: Chakki1,2 | C17: C6 | D17: Multigrain | E17: 600 | F17: 0 | G17: 2 | H17: 1 | I17: 16 | J17: =F17+G17+H17+I17 -> 19 | K17: 581 | L17: 2 | M17: Day | N17: =K17/E17*100 -> 96.833333 | O17: =K17+J17 -> 600 | P17: =E17-O17 -> 0
A18: 46030 | B18: Chakki1,2&3 | C18: C6 | D18: Multigrain | E18: 1150 | F18: 0 | G18: 23 | H18: 2 | I18: 87 | J18: =F18+G18+H18+I18 -> 112 | K18: 1038 | L18: 4 | M18: Night | N18: =K18/E18*100 -> 90.26087 | O18: =K18+J18 -> 1150 | P18: =E18-O18 -> 0
A19: 46031 | B19: Chakki1,2 | C19: C6 | D19: Multigrain | E19: 70 | I19: 6 | J19: =F19+G19+H19+I19 -> 6 | K19: 64 | M19: Day | N19: =K19/E19*100 -> 91.428571 | O19: =K19+J19 -> 70 | P19: =E19-O19 -> 0
A20: 46032 | B20: Chakki1,2&3 | C20: C6 | D20: Multigrain | E20: 1000 | F20: 0 | G20: 8 | H20: 0 | I20: 31 | J20: =F20+G20+H20+I20 -> 39 | K20: 961 | L20: 2 | M20: Day | N20: =K20/E20*100 -> 96.1 | O20: =K20+J20 -> 1000 | P20: =E20-O20 -> 0
A21: 46033 | B21: Chakki1,2&3 | C21: C6 | D21: Multigrain | E21: 1600 | F21: 0 | G21: 12 | H21: 2 | I21: 46 | J21: =F21+G21+H21+I21 -> 60 | K21: 1540 | L21: 3 | M21: Day | N21: =K21/E21*100 -> 96.25 | O21: =K21+J21 -> 1600 | P21: =E21-O21 -> 0
A22: 46034 | B22: Chakki1,2&3 | C22: C6 | D22: Multigrain | E22: 1650 | F22: 0 | G22: 16 | H22: 2 | I22: 71 | J22: =F22+G22+H22+I22 -> 89 | K22: 1561 | L22: 3 | M22: Day | N22: =K22/E22*100 -> 94.606061 | O22: =K22+J22 -> 1650 | P22: =E22-O22 -> 0
A23: 46034 | B23: Chakki1,2&3 | C23: C6 | D23: Multigrain | E23: 1500 | F23: 0 | G23: 13 | H23: 3 | I23: 149 | J23: =F23+G23+H23+I23 -> 165 | K23: =1335-2 -> 1333 | L23: 4 | M23: Night | N23: =K23/E23*100 -> 88.866667 | O23: =K23+J23 -> 1498 | P23: =E23-O23 -> 2
A24: 46035 | B24: Chakki1,2&3 | C24: C6 | D24: Multigrain | E24: 2650 | F24: 0 | G24: 31 | H24: 4 | I24: 170 | J24: =F24+G24+H24+I24 -> 205 | K24: 2445 | L24: 3 | M24: Day | N24: =K24/E24*100 -> 92.264151 | O24: =K24+J24 -> 2650 | P24: =E24-O24 -> 0
A25: 46035 | B25: Chakki1,2&3 | C25: C6 | D25: Multigrain | E25: 2200 | F25: 0 | G25: 18 | H25: 1 | I25: 181 | J25: =F25+G25+H25+I25 -> 200 | K25: 2000 | L25: 4 | M25: Night | N25: =K25/E25*100 -> 90.909091 | O25: =K25+J25 -> 2200 | P25: =E25-O25 -> 0
A26: 46036 | B26: Chakki1,2&3 | C26: C6 | D26: Multigrain | E26: 3000 | F26: 0 | G26: 51 | H26: 4 | I26: 255 | J26: =F26+G26+H26+I26 -> 310 | K26: 2690 | L26: 4 | M26: Night | N26: =K26/E26*100 -> 89.666667 | O26: =K26+J26 -> 3000 | P26: =E26-O26 -> 0
A27: 46037 | B27: Chakki1,2&3 | C27: C6 | D27: Multigrain | E27: 2000 | F27: 0 | G27: 85 | H27: 2 | I27: 93 | J27: =F27+G27+H27+I27 -> 180 | K27: 1820 | L27: 4 | M27: Night | N27: =K27/E27*100 -> 91 | O27: =K27+J27 -> 2000 | P27: =E27-O27 -> 0
A28: 46038 | B28: Chakki1,2&3 | C28: C6 | D28: Multigrain | E28: 2100 | F28: 0 | G28: 18 | H28: 1 | I28: 80 | J28: =F28+G28+H28+I28 -> 99 | K28: 2001 | L28: 3 | M28: Day | N28: =K28/E28*100 -> 95.285714 | O28: =K28+J28 -> 2100 | P28: =E28-O28 -> 0
A29: 46038 | B29: Chakki1,2&3 | C29: C6 | D29: Multigrain | E29: 700 | F29: 0 | G29: 8 | H29: 2 | I29: 49 | J29: =F29+G29+H29+I29 -> 59 | K29: 641 | L29: 4 | M29: Night | N29: =K29/E29*100 -> 91.571429 | O29: =K29+J29 -> 700 | P29: =E29-O29 -> 0
A30: 46039 | B30: Chakki1,2&3 | C30: C6 | D30: Multigrain | E30: 2050 | F30: 0 | G30: 9 | H30: 2 | I30: 110 | J30: =F30+G30+H30+I30 -> 121 | K30: 1929 | L30: 3 | M30: Day | N30: =K30/E30*100 -> 94.097561 | O30: =K30+J30 -> 2050 | P30: =E30-O30 -> 0
A31: 46040 | B31: Chakki1,2&3 | C31: C6 | D31: Multigrain | E31: 1950 | F31: 0 | G31: 24 | H31: 2 | I31: 134 | J31: =F31+G31+H31+I31 -> 160 | K31: 1790 | L31: 4 | M31: Night | N31: =K31/E31*100 -> 91.794872 | O31: =K31+J31 -> 1950 | P31: =E31-O31 -> 0
A32: 46040 | B32: Chakki1,2&3 | C32: C6 | D32: Multigrain | E32: 2400 | F32: 0 | G32: 23 | H32: 3 | I32: 74 | J32: =F32+G32+H32+I32 -> 100 | K32: 2300 | L32: 4 | M32: Day | N32: =K32/E32*100 -> 95.833333 | O32: =K32+J32 -> 2400 | P32: =E32-O32 -> 0
A33: 46041 | B33: Chakki1,2&3 | C33: C6 | D33: Multigrain | E33: 2400 | F33: 0 | G33: 18 | H33: 5 | I33: 127 | J33: =F33+G33+H33+I33 -> 150 | K33: 2250 | L33: 3 | M33: DAY | N33: =K33/E33*100 -> 93.75 | O33: =K33+J33 -> 2400 | P33: =E33-O33 -> 0
A34: 46041 | B34: Chakki1,2&3 | C34: C6 | D34: Multigrain | E34: 2300 | F34: 0 | G34: 28 | H34: 1 | I34: 114 | J34: =F34+G34+H34+I34 -> 143 | K34: 2157 | L34: 4 | M34: NIGHT | N34: =K34/E34*100 -> 93.782609 | O34: =K34+J34 -> 2300 | P34: =E34-O34 -> 0
A35: 46042 | B35: Chakki1,2&3 | C35: C6 | D35: Multigrain | E35: 2250 | F35: 0 | G35: 20 | H35: 5 | I35: 137 | J35: =F35+G35+H35+I35 -> 162 | K35: 2088 | L35: 3 | M35: DAY | N35: =K35/E35*100 -> 92.8 | O35: =K35+J35 -> 2250 | P35: =E35-O35 -> 0
... A42: 46045 | B42: Chakki1,2 | C42: C6 | D42: Multigrain | E42: 3050 | F42: 0 | G42: 31 | H42: 5 | I42: 146 | J42: =F42+G42+H42+I42 -> 182 | K42: 2868 | L42: 4 | M42: NIGHT | N42: =K42/E42*100 -> 94.032787 | O42: =K42+J42 -> 3050 | P42: =E42-O42 -> 0
A43: 46046 | B43: Chakki1,2 | C43: C6 | D43: Multigrain | E43: 1450 | F43: 0 | G43: 14 | H43: 4 | J43: 115 | K43: 1335 | L43: 4 | M43: DAY | N43: =K43/E43*100 -> 92.068966 | O43: =K43+J43 -> 1450 | P43: =E43-O43 -> 0
A44: 46046 | B44: Chakki1,2 | C44: C6 | D44: Multigrain | E44: 3250 | F44: 0 | G44: 80 | H44: 2 | I44: 117 | J44: =F44+G44+H44+I44 -> 199 | K44: 3051 | L44: 4 | M44: NIGHT | N44: =K44/E44*100 -> 93.876923 | O44: =K44+J44 -> 3250 | P44: =E44-O44 -> 0
A45: 46047 | B45: Chakki1,2 | C45: C6 | D45: Multigrain | E45: 1850 | F45: 0 | G45: 37 | H45: 3 | I45: 105 | J45: =F45+G45+H45+I45 -> 145 | K45: 1722 | L45: 3 | M45: DAY | N45: =K45/E45*100 -> 93.081081 | O45: =K45+J45 -> 1867 | P45: =E45-O45 -> -17
A46: 46049 | B46: Chakki1,2 | C46: C6 | D46: Multigrain | E46: 2050 | F46: 0 | G46: 45 | H46: 4 | I46: 122 | J46: =F46+G46+H46+I46 -> 171 | K46: 1910 | L46: 3 | M46: DAY | N46: =K46/E46*100 -> 93.170732 | O46: =K46+J46 -> 2081 | P46: =E46-O46 -> -31
A47: 46049 | B47: Chakki1,2 | C47: C6 | D47: Jowar | E47: 550 | F47: 0 | G47: 42 | H47: 3 | I47: 42 | J47: =F47+G47+H47+I47 -> 87 | K47: =401+42+20 -> 463 | L47: 4 | M47: NIGHT | N47: =K47/E47*100 -> 84.181818 | O47: =K47+J47 -> 550 | P47: =E47-O47 -> 0
...

Sheet  C39 JAN-FEB
A2: Atta Production Report
A3: Date | B3: Machine | C3: Plant | D3: Product | E3: IN in Kg | F3: Sorting | G3: Bran | H3: Floor Atta | I3: Process Loss | J3: Total Wastage | K3: OUT in Kg | L3: Manpower | M3: Shift | N3: Yield %
F4: Grader | G4: Sieve | H4: Floor | I4: Process Loss | Q4: Remark
A5: 46026 | B5: 3&4 | C5: C39 | D5: Khapli | E5: 5000 | F5: 130 | G5: 92 | H5: 6 | I5: 240 | J5: =F5+G5+H5+I5 -> 468 | K5: 4532 | L5: 9 | M5: Day | N5: =K5/E5*100 -> 90.64 | O5: =K5+J5 -> 5000 | P5: =E5-O5 -> 0
A6: 46027 | B6: 3&4 | C6: C39 | D6: Khapli | E6: 4450 | F6: 85 | G6: 72 | H6: 5.4 | I6: 156.6 | J6: =F6+G6+H6+I6 -> 319 | K6: 4131 | L6: 9 | M6: Day | N6: =K6/E6*100 -> 92.831461 | O6: =K6+J6 -> 4450 | P6: =E6-O6 -> 0
A7: 46028 | B7: 3&4 | C7: C39 | D7: Khapli | E7: 5550 | F7: 184 | G7: 152 | H7: 6 | I7: 202 | J7: =F7+G7+H7+I7 -> 544 | K7: 5006 | L7: 9 | M7: Day | N7: =K7/E7*100 -> 90.198198 | O7: =K7+J7 -> 5550 | P7: =E7-O7 -> 0
A8: 46029 | B8: 3&4 | C8: C39 | D8: Khapli | E8: 5700 | F8: 127 | G8: 85 | H8: 7 | I8: 156 | J8: =F8+G8+H8+I8 -> 375 | K8: 5325 | L8: 9 | M8: Day | N8: =K8/E8*100 -> 93.421053 | O8: =K8+J8 -> 5700 | P8: =E8-O8 -> 0
A9: 46030 | B9: 3&4 | C9: C39 | D9: Khapli | E9: 5000 | F9: 127 | G9: 78 | H9: 6 | I9: 169 | J9: =F9+G9+H9+I9 -> 380 | K9: 4620 | L9: 9 | M9: Day | N9: =K9/E9*100 -> 92.4 | O9: =K9+J9 -> 5000 | P9: =E9-O9 -> 0
A10: 46031 | B10: 3&4 | C10: C39 | D10: Khapli | E10: 5000 | F10: 133 | G10: 81 | H10: 6.6 | I10: 140.4 | J10: =F10+G10+H10+I10 -> 361 | K10: 4639 | L10: 9 | M10: Day | N10: =K10/E10*100 -> 92.78 | O10: =K10+J10 -> 5000 | P10: =E10-O10 -> 0
A11: 46032 | B11: 3&4 | C11: C39 | D11: Khapli | E11: 4500 | F11: 112 | G11: 65 | H11: 4 | I11: 129 | J11: =F11+G11+H11+I11 -> 310 | K11: 4190 | L11: 9 | M11: Day | N11: =K11/E11*100 -> 93.111111 | O11: =K11+J11 -> 4500 | P11: =E11-O11 -> 0
A12: 46033 | B12: 3&4 | C12: C39 | D12: Khapli | E12: 3150 | F12: 90 | G12: 46 | H12: 4 | I12: 100 | J12: =F12+G12+H12+I12 -> 240 | K12: 2910 | L12: 9 | M12: Day | N12: =K12/E12*100 -> 92.380952 | O12: =K12+J12 -> 3150 | P12: =E12-O12 -> 0
A13: 46034 | B13: 3&4 | C13: C39 | D13: Khapli | E13: 4500 | F13: 106 | G13: 50 | H13: 4.6 | I13: 118.4 | J13: =F13+G13+H13+I13 -> 279 | K13: 4221 | L13: 9 | M13: Day | N13: =K13/E13*100 -> 93.8 | O13: =K13+J13 -> 4500 | P13: =E13-O13 -> 0
A14: 46035 | B14: 3&4 | C14: C39 | D14: Khapli | E14: 5000 | F14: 111 | G14: 84 | H14: 6 | I14: 132 | J14: =F14+G14+H14+I14 -> 333 | K14: 4667 | L14: 9 | M14: Day | N14: =K14/E14*100 -> 93.34 | O14: =K14+J14 -> 5000 | P14: =E14-O14 -> 0
A15: 46038 | B15: 3&4 | C15: C39 | D15: Khapli | E15: 5000 | F15: 94 | G15: 62 | H15: 0 | I15: 129 | J15: =F15+G15+H15+I15 -> 285 | K15: 4715 | L15: 9 | M15: DAY | N15: =K15/E15*100 -> 94.3 | O15: =K15+J15 -> 5000 | P15: =E15-O15 -> 0
A16: 46039 | B16: 3&4 | C16: C39 | D16: Khapli | E16: 5000 | F16: 111 | G16: 71 | H16: 7 | I16: 140 | J16: =F16+G16+H16+I16 -> 329 | K16: 4671 | L16: 9 | M16: day | N16: =K16/E16*100 -> 93.42 | O16: =K16+J16 -> 5000 | P16: =E16-O16 -> 0
... A53: 46056 | B53: 3&4 | C53: C39 | D53: Multigrain | E53: 3050 | F53: 4.6 | G53: 59 | H53: 6 | I53: 60.4 | J53: =F53+G53+H53+I53 -> 130 | K53: 2920 | L53: 5 | M53: Day | N53: =K53/E53*100 -> 95.737705 | O53: =K53+J53 -> 3050 | P53: =E53-O53 -> 0
N56: =AVERAGE(#REF!) -> #REF!
I57: Total | N57: Avarage
I58: Total Cost
I59: Cost Per kg

Sheet C6 MARCH
A1: Atta Production Report
A2: Date | B2: Machine | C2: Plant | D2: Product | E2: IN in Kg | F2: Sorting | G2: Bran | H2: Floor Atta | I2: Process Loss | J2: Total Wastage | K2: OUT in Kg | L2: Manpower | M2: SHIFT | N2: Yield %
F3: Grader | G3: Sieve | H3: Floor | I3: Process Loss
A4: 46078 | B4: Pulvriser | C4: C39 | D4: Besan | E4: 650 | F4: 0 | G4: 0 | H4: 0 | I4: 40 | J4: 40 | K4: 610 | L4: 4 | N4: =K4/E4*100 -> 93.846154 | O4: =K4+J4 -> 650 | P4: =E4-O4 -> 0
A5: 46082 | B5: Chakki1,2,3 | C5: C6 | D5: Multigrain | E5: 2100 | F5: 30 | G5: 25 | H5: 2 | I5: 133 | J5: =I5+H5+G5+F5 -> 190 | K5: 1910 | L5: 4 | M5: DAY | N5: =K5/E5*100 -> 90.952381 | O5: =K5+J5 -> 2100 | P5: =E5-O5 -> 0
A6: 46082 | B6: Chakki1,2,3 | C6: C6 | D6: Pearl Millet | E6: 1750 | F6: 28 | G6: 42 | H6: 2 | I6: 82.4 | J6: =I6+H6+G6+F6 -> 154.4 | K6: =1580+15.6 -> 1595.6 | L6: 4 | M6: NIGHT | N6: =K6/E6*100 -> 91.177143 | O6: =K6+J6 -> 1750 | P6: =E6-O6 -> 0
A7: 46083 | B7: Chakki1,2,3 | C7: C6 | D7: Jowar | E7: 2400 | F7: 30 | G7: 56 | H7: 3 | I7: 132 | J7: =I7+H7+G7+F7 -> 221 | K7: 2240 | L7: 4 | M7: DAY | N7: =K7/E7*100 -> 93.333333 | O7: =K7+J7 -> 2461 | P7: =E7-O7 -> -61
A8: 46085 | B8: Chakki1,2,3 | C8: C6 | D8: Multigrain | E8: 2100 | F8: 31 | G8: 30 | H8: 2 | I8: 110 | J8: =I8+H8+G8+F8 -> 173 | K8: 1927 | L8: 4 | M8: DAY | N8: =K8/E8*100 -> 91.761905 | O8: =K8+J8 -> 2100 | P8: =E8-O8 -> 0
A9: 46085 | B9: Chakki1,2,3 | C9: C6 | D9: Multigrain | E9: 2900 | F9: 29 | G9: 40 | H9: 1 | I9: 120 | J9: =I9+H9+G9+F9 -> 190 | K9: 2660 | L9: 4 | M9: NIGHT | N9: =K9/E9*100 -> 91.724138 | O9: =K9+J9 -> 2850 | P9: =E9-O9 -> 50
A10: 46086 | B10: Chakki1,2,3 | C10: C6 | D10: Multigrain | E10: 1750 | F10: 30 | G10: 14 | H10: 1 | I10: 105 | J10: =I10+H10+G10+F10 -> 150 | K10: 1605 | L10: 4 | M10: DAY | N10: =K10/E10*100 -> 91.714286 | O10: =K10+J10 -> 1755 | P10: =E10-O10 -> -5
A11: 46086 | B11: Chakki1,2,3 | C11: C6 | D11: Multigrain | E11: 3250 | F11: 45 | G11: 68 | H11: 2 | I11: 130 | J11: =I11+H11+G11+F11 -> 245 | K11: 3005 | L11: 4 | M11: NIGHT | N11: =K11/E11*100 -> 92.461538 | O11: =K11+J11 -> 3250 | P11: =E11-O11 -> 0
A12: 46087 | B12: Chakki1,2,3 | C12: C6 | D12: Khapli wheat | E12: 175 | F12: 10 | G12: 0.4 | H12: 0.2 | I12: 3.4 | J12: =I12+H12+G12+F12 -> 14 | K12: 161 | L12: 4 | M12: DAY | N12: =K12/E12*100 -> 92 | O12: =K12+J12 -> 175 | P12: =E12-O12 -> 0
A13: 46087 | B13: Chakki1,2,3 | C13: C6 | D13: Khapli wheat | E13: 3350 | F13: 42 | G13: 35 | H13: 4 | I13: 233 | J13: =I13+H13+G13+F13 -> 314 | K13: 3111 | L13: 4 | M13: NIGHT | N13: =K13/E13*100 -> 92.865672 | O13: =K13+J13 -> 3425 | P13: =E13-O13 -> -75
A14: 46088 | B14: Chakki 1,2,3 | C14: C6 | D14: Khapli wheat | E14: 2200 | F14: 20 | G14: 4 | H14: 1 | I14: 134 | J14: =I14+H14+G14+F14 -> 159 | K14: 2041 | L14: 4 | M14: DAY | N14: =K14/E14*100 -> 92.772727 | O14: =K14+J14 -> 2200 | P14: =E14-O14 -> 0
A15: 07.03.26 | B15: Chakki 1,2,3 | C15: C6 | D15: Khapli wheat | E15: =2200+300 -> 2500 | F15: 25 | G15: 23 | H15: 5 | I15: 130 | J15: =I15+H15+G15+F15 -> 183 | K15: =2010+300 -> 2310 | L15: 4 | M15: NIGHT | N15: =K15/E15*100 -> 92.4 | O15: =K15+J15 -> 2493 | P15: =E15-O15 -> 7
A16: 08.02.26 | B16: Chakki1,2,3 | C16: C6 | D16: Khapli wheat | E16: 2000 | F16: 30 | G16: 15 | H16: 1 | I16: 105 | J16: =I16+H16+G16+F16 -> 151 | K16: 1849 | L16: 3 | M16: DAY | N16: =K16/E16*100 -> 92.45 | O16: =K16+J16 -> 2000 | P16: =E16-O16 -> 0
A17: 09.03.26 | B17: Chakki1,2,3 | C17: C6 | D17: Khapli wheat | E17: 2550 | F17: 35 | G17: 11 | H17: 2 | I17: 122 | J17: =I17+H17+G17+F17 -> 170 | K17: 2380 | L17: 4 | M17: DAY | N17: =K17/E17*100 -> 93.333333 | O17: =K17+J17 -> 2550 | P17: =E17-O17 -> 0
A18: 09.03.26 | B18: Chakki1,2,3 | C18: C6 | D18: Khapli wheat | E18: 3400 | F18: 49 | G18: 17 | H18: 2 | I18: 122 | J18: =I18+H18+G18+F18 -> 190 | K18: 3210 | L18: 4 | M18: NIGHT | N18: =K18/E18*100 -> 94.411765 | O18: =K18+J18 -> 3400 | P18: =E18-O18 -> 0
A19: 10.03.26 | B19: Chakki1,2,3 | C19: C6 | D19: Khapli wheat | E19: 2600 | F19: 30 | G19: 5 | H19: 1 | I19: 114 | J19: =I19+H19+G19+F19 -> 150 | K19: 2450 | L19: 4 | M19: DAY | N19: =K19/E19*100 -> 94.230769 | O19: =K19+J19 -> 2600 | P19: =E19-O19 -> 0
A20: 11.03.26 | B20: Chakki1,2,3 | C20: C6 | D20: Khapli wheat | E20: 2750 | F20: 10 | G20: 10 | H20: 1 | I20: 129 | J20: =I20+H20+G20+F20 -> 150 | K20: 2600 | L20: 4 | M20: DAY | N20: =K20/E20*100 -> 94.545455 | O20: =K20+J20 -> 2750 | P20: =E20-O20 -> 0
A21: 11.03.26 | B21: Chakki1,2,3 | C21: C6 | D21: jowar | E21: 1139 | F21: 30 | G21: 25 | H21: 1.5 | I21: 67.5 | J21: =I21+H21+G21+F21 -> 124 | K21: 1015 | L21: 4 | M21: NIGHT | N21: =K21/E21*100 -> 89.113257 | O21: =K21+J21 -> 1139 | P21: =E21-O21 -> 0
A22: 12.03.26 | B22: Chakki1,2,3 | C22: C6 | D22: jowar | E22: 1861 | F22: 21 | G22: 28 | H22: 1 | I22: 106 | J22: 201 | K22: 1660 | L22: 4 | M22: DAY | N22: =K22/E22*100 -> 89.199355 | O22: =K22+J22 -> 1861 | P22: =E22-O22 -> 0
A23: 12.03.26 | B23: Chakki1,2,3 | D23: Khapli wheat | E23: 2250 | F23: 27 | G23: 6 | H23: 2 | I23: 144 | J23: =I23+H23+G23+F23 -> 179 | K23: 2071 | L23: 3 | M23: NIGHT | N23: =K23/E23*100 -> 92.044444 | O23: =K23+J23 -> 2250 | P23: =E23-O23 -> 0
A24: 13.03.26 | B24: Chakki1,2,3 | C24: C6 | D24: Khapli wheat | E24: 2250 | F24: 17 | G24: 10 | H24: 2 | I24: 99 | J24: =I24+H24+G24+F24 -> 128 | K24: 2122 | L24: 3 | M24: DAY | N24: =K24/E24*100 -> 94.311111 | O24: =K24+J24 -> 2250 | P24: =E24-O24 -> 0
A25: 13.03.26 | B25: Chakki1,2,3 | C25: C6 | D25: Multigrain | E25: 2700 | F25: 25 | G25: 31 | H25: 2 | I25: 135 | J25: =I25+H25+G25+F25 -> 193 | K25: 2507 | L25: 4 | M25: Night | N25: =K25/E25*100 -> 92.851852 | O25: =K25+J25 -> 2700 | P25: =E25-O25 -> 0
A26: 13.03.26 | B26: Chakki1,2,3 | C26: C6 | D26: Khapli wheat | E26: 425 | F26: 4 | G26: 2 | H26: 1 | I26: 23 | J26: =I26+H26+G26+F26 -> 30 | K26: 395 | L26: 4 | M26: Night | N26: =K26/E26*100 -> 92.941176 | O26: =K26+J26 -> 425 | P26: =E26-O26 -> 0
A27: 14.03.26 | B27: Chakki1,2,3 | C27: C6 | D27: Multigrain | E27: 2700 | F27: 28 | G27: 45 | H27: 2 | I27: 65 | J27: =I27+H27+G27+F27 -> 140 | K27: 2560 | L27: 4 | M27: DAY | N27: =K27/E27*100 -> 94.814815 | O27: =K27+J27 -> 2700 | P27: =E27-O27 -> 0
A28: 14.03.26 | B28: Chakki1,2,3 | C28: C6 | D28: Multigrain | E28: 2300 | F28: 12 | G28: 30 | H28: 6 | I28: 99 | J28: =I28+H28+G28+F28 -> 147 | K28: 2153 | L28: 4 | M28: Night | N28: =K28/E28*100 -> 93.608696 | O28: =K28+J28 -> 2300 | P28: =E28-O28 -> 0
A29: 17.03.26 | B29: Chakki 1 | C29: C6 | D29: Multigrain | E29: 900 | F29: 22 | G29: 5 | H29: 1 | I29: 27 | J29: =I29+H29+G29+F29 -> 55 | K29: 845 | L29: 3 | M29: DAY | N29: =K29/E29*100 -> 93.888889 | O29: =K29+J29 -> 900 | P29: =E29-O29 -> 0
A30: 17.03.26 | B30: Chakki1,2,3 | C30: C6 | D30: Multigrain | E30: =2300+550 -> 2850 | F30: 30 | G30: 20 | H30: 3 | I30: 122 | J30: =I30+H30+G30+F30 -> 175 | K30: =2150+525 -> 2675 | L30: 4 | M30: Night | N30: =K30/E30*100 -> 93.859649 | O30: =K30+J30 -> 2850 | P30: =E30-O30 -> 0
A31: 18.03.26 | B31: Chakki1,2,3 | C31: C6 | D31: Jowar | E31: 1429 | F31: 26 | G31: 23 | H31: 1 | I31: 65 | J31: =I31+H31+G31+F31 -> 115 | K31: 1310 | L31: 3 | M31: DAY | N31: =K31/E31*100 -> 91.672498 | O31: =K31+J31 -> 1425 | P31: =E31-O31 -> 4
A32: 18.03.26 | B32: Chakki1,2,3 | C32: C6 | D32: Jowar | E32: 1500 | F32: 30 | G32: 25 | H32: 1 | I32: 74 | J32: =I32+H32+G32+F32 -> 130 | K32: 1370 | L32: 4 | M32: Night | N32: =K32/E32*100 -> 91.333333 | O32: =K32+J32 -> 1500 | P32: =E32-O32 -> 0
A33: 20.03.26 | B33: Chakki1,2,3 | C33: C6 | D33: Bajra | E33: 980 | F33: 15 | G33: 9 | H33: 1 | I33: 50 | J33: =I33+H33+G33+F33 -> 75 | K33: 905 | L33: 3 | M33: DAY | N33: =K33/E33*100 -> 92.346939 | O33: =K33+J33 -> 980 | P33: =E33-O33 -> 0
A34: 21.03.26 | B34: Chakki1,2,3 | C34: C6 | D34: Bajra | E34: 310 | F34: 5 | G34: 6 | H34: 3 | I34: 16 | J34: =I34+H34+G34+F34 -> 30 | K34: 280 | L34: 2 | M34: DAY | N34: =K34/E34*100 -> 90.322581 | O34: =K34+J34 -> 310 | P34: =E34-O34 -> 0
A35: 28.03.26 | B35: Chakki1,2,3 | C35: C6 | D35: Jowar | E35: 491 | F35: 0 | G35: 7 | H35: 2 | I35: 30 | J35: =I35+H35+G35+F35 -> 39 | K35: 447 | L35: 3 | M35: DAY | N35: =K35/E35*100 -> 91.038697 | O35: =K35+J35 -> 486 | P35: =E35-O35 -> 5
A36: 28.03.26 | B36: Pulveriser | C36: C39 | D36: Besan | E36: 55 | F36: 0 | G36: 0 | H36: 0 | I36: 5 | J36: =I36+H36+G36+F36 -> 5 | K36: 50 | N36: =K36/E36*100 -> 90.909091 | O36: =K36+J36 -> 55 | P36: =E36-O36 -> 0
A37: 28.03.26 | B37: Pulveriser | C37: C39 | D37: Besan | E37: 145 | F37: 0 | G37: 0 | H37: 0 | I37: 10 | J37: =I37+H37+G37+F37 -> 10 | K37: 135 | N37: =K37/E37*100 -> 93.103448 | O37: =K37+J37 -> 145 | P37: =E37-O37 -> 0
A38: 30.03.26 | B38: Chakki1,2,3 | C38: C6 | D38: Jowar | E38: 2750 | F38: 35 | G38: 39 | H38: 2 | I38: 46 | J38: =I38+H38+G38+F38 -> 122 | K38: 2628 | L38: 4 | M38: Night | N38: =K38/E38*100 -> 95.563636 | O38: =K38+J38 -> 2750 | P38: =E38-O38 -> 0
A39: 31.03.26 | B39: Chakki1,2,3 | C39: C6 | D39: Jowar | E39: 1550 | F39: 22 | G39: 22 | H39: 2 | I39: 64 | J39: =I39+H39+G39+F39 -> 110 | K39: 1440 | L39: 3 | M39: Night | N39: =K39/E39*100 -> 92.903226 | O39: =K39+J39 -> 1550 | P39: =E39-O39 -> 0
N42: =AVERAGE(#REF!) -> #REF!
...

Sheet C39 MARCH
A1: Atta Production Report
A2: Date | B2: Machine | C2: Plant | D2: Product | E2: IN in Kg | F2: Sorting | G2: Bran | H2: Floor Atta | I2: Process Loss | J2: Total Wastage | K2: OUT in Kg | L2: Manpower | M2: Shift | N2: Yield %
F3: Grader | G3: Sieve | H3: Floor | I3: Process Loss
A4: 46082 | B4: 3&4 | C4: C39 | D4: Multigrain | E4: 5100 | F4: 3.8 | G4: 72 | H4: 15 | I4: 149.2 | J4: =F4+G4+H4+I4 -> 240 | K4: 4860 | L4: 9 | M4: Day | N4: =K4/E4*100 -> 95.294118 | O4: =K4+J4 -> 5100 | P4: =E4-O4 -> 0
A5: 46082 | B5: 3&4 | C5: C39 | D5: Multigrain | E5: 720 | F5: 1.5 | G5: 12 | H5: 5 | I5: 21.5 | J5: =F5+G5+H5+I5 -> 40 | K5: 680 | L5: 6 | M5: Night | N5: =K5/E5*100 -> 94.444444 | O5: =K5+J5 -> 720 | P5: =E5-O5 -> 0
A6: 46083 | B6: 3&4 | C6: C39 | D6: Multigrain | E6: 3050 | F6: 4.6 | G6: 59 | H6: 6 | I6: 60.4 | J6: =F6+G6+H6+I6 -> 130 | K6: 2920 | L6: 5 | M6: Day | N6: =K6/E6*100 -> 95.737705 | O6: =K6+J6 -> 3050 | P6: =E6-O6 -> 0
A7: 46087 | B7: 3&4 | C7: C39 | D7: Multigrain | E7: 4800 | F7: 2 | G7: 97 | H7: 6 | I7: 105 | J7: =F7+G7+H7+I7 -> 210 | K7: 4590 | L7: 5 | M7: Day | N7: =K7/E7*100 -> 95.625 | O7: =K7+J7 -> 4800 | P7: =E7-O7 -> 0
A8: 46089 | B8: 3&4 | C8: C39 | D8: Multigrain | E8: 5200 | F8: 10 | G8: 95 | H8: 15 | I8: 130 | J8: =F8+G8+H8+I8 -> 250 | K8: 4950 | L8: 6 | M8: DAY | N8: =K8/E8*100 -> 95.192308 | O8: =K8+J8 -> 5200 | P8: =E8-O8 -> 0
A9: 46091 | B9: 3&4 | C9: C39 | D9: Multigrain | E9: 2680 | F9: 20 | G9: 20 | H9: 15.8 | I9: 64.2 | J9: =F9+G9+H9+I9 -> 120 | K9: 2560 | L9: 7 | M9: DAY | N9: =K9/E9*100 -> 95.522388 | O9: =K9+J9 -> 2680 | P9: =E9-O9 -> 0
A10: 46091 | B10: 3&4 | C10: C39 | D10: Multigrain | E10: 1920 | F10: 15 | G10: 15 | H10: 3 | I10: 47 | J10: =F10+G10+H10+I10 -> 80 | K10: 1840 | L10: 4 | M10: Night | N10: =K10/E10*100 -> 95.833333 | O10: =K10+J10 -> 1920 | P10: =E10-O10 -> 0
A11: 46092 | B11: 3&4 | C11: C39 | D11: Multigrain | E11: 2830 | F11: 12 | G11: 55 | H11: 7 | I11: 56 | J11: =F11+G11+H11+I11 -> 130 | K11: 2700 | L11: 4 | M11: Day | N11: 95.4 | O11: =K11+J11 -> 2830 | P11: =E11-O11 -> 0
A12: 46094 | B12: Pulveriser | C12: C39 | D12: Besan atta | E12: 255 | F12: 0 | G12: 0 | H12: 1.2 | I12: 4 | J12: =F12+G12+H12+I12 -> 5.2 | K12: 250 | L12: 1 | M12: DAY | N12: =K12/E12*100 -> 98.039216 | O12: =K12+J12 -> 255.2 | P12: =E12-O12 -> -0.2
A13: 46094 | B13: Pulveriser | C13: C39 | D13: Besan | E13: =500+200 -> 700 | F13: 0 | G13: 0 | H13: 3.5 | I13: 0 | J13: =F13+G13+H13+I13 -> 3.5 | K13: =460+186 -> 646 | L13: 1 | M13: DAY | N13: 92 | O13: =K13+J13 -> 649.5 | P13: =E13-O13 -> 50.5
A14: 46094 | B14: 1,3&4 | C14: C39 | D14: khapli | E14: 4150 | F14: 42 | G14: 56 | H14: 12 | I14: 120 | J14: =F14+G14+H14+I14 -> 230 | K14: 3920 | L14: 5 | M14: Day | N14: =K14/E14*100 -> 94.457831 | O14: =K14+J14 -> 4150 | P14: =E14-O14 -> 0
A15: 46095 | B15: 1,3&4 | C15: C39 | D15: khapli | E15: 6600 | F15: 43 | G15: 89 | H15: 16 | I15: 196 | J15: =F15+G15+H15+I15 -> 344 | K15: 6256 | L15: 4 | M15: Day | N15: =K15/E15*100 -> 94.787879 | O15: =K15+J15 -> 6600 | P15: =E15-O15 -> 0
A16: 46096 | B16: 1&3&4 | C16: C39 | D16: Khapli | E16: 6300 | F16: 46 | G16: 84 | H16: 140 | I16: 160 | J16: =F16+G16+H16+I16 -> 430 | K16: 6000 | L16: 4 | M16: DAY | N16: =K16/E16*100 -> 95.238095 | O16: =K16+J16 -> 6430 | P16: =E16-O16 -> -130
A17: 46097 | B17: 1&3&4 | C17: C39 | D17: khapli | E17: 4300 | F17: 30 | G17: 54 | H17: 94 | I17: 86 | J17: =F17+G17+H17+I17 -> 264 | K17: 4120 | L17: 4 | M17: DAY | N17: =K17/E17*100 -> 95.813953 | O17: =K17+J17 -> 4384 | P17: =E17-O17 -> -84
A18: 46099 | B18: 1,2,3&4 | C18: C39 | D18: khapli | E18: 6400 | F18: 32 | G18: 58 | H18: 16 | I18: 94 | J18: =F18+G18+H18+I18 -> 200 | K18: 6200 | L18: 5 | M18: Day | N18: =K18/E18*100 -> 96.875 | O18: =K18+J18 -> 6400 | P18: =E18-O18 -> 0
A19: 46101 | B19: 1,2,3&4 | C19: C39 | D19: multigrain | E19: 5500 | F19: 4 | G19: 110 | H19: 15 | I19: 179 | J19: =F19+G19+H19+I19 -> 308 | K19: 5200 | L19: 5 | M19: Day | N19: =K19/E19*100 -> 94.545455 | O19: =K19+J19 -> 5508 | P19: =E19-O19 -> -8
A20: 46102 | B20: 1,2,3&4 | C20: C39 | D20: multigrain | E20: 6500 | F20: 6 | G20: 127 | H20: 15 | I20: 192 | J20: =F20+G20+H20+I20 -> 340 | K20: 6160 | L20: 5 | M20: Day | N20: =K20/E20*100 -> 94.769231 | O20: =K20+J20 -> 6500 | P20: =E20-O20 -> 0
A21: 46103 | B21: 1,2,3&4 | C21: C39 | D21: multigrain | E21: 3600 | F21: 4.5 | G21: 67 | H21: 9 | I21: 159.5 | J21: =F21+G21+H21+I21 -> 240 | K21: 3360 | L21: 4 | M21: day | N21: 93.33 | O21: =K21+J21 -> 3600 | P21: =E21-O21 -> 0
A22: 46105 | B22: 1,2,3&4 | C22: C39 | D22: multigrain | E22: 5900 | F22: 6 | G22: 135 | H22: 15 | I22: 144 | J22: =F22+G22+H22+I22 -> 300 | K22: 5600 | L22: 4 | M22: day | N22: =K22/E22*100 -> 94.915254 | O22: =K22+J22 -> 5900 | P22: =E22-O22 -> 0
A23: 46106 | B23: 1,2,3&4 | C23: C39 | D23: multigrain | E23: 5700 | F23: 7 | G23: 156 | H23: 15 | I23: 162 | J23: =F23+G23+H23+I23 -> 340 | K23: 5360 | L23: 4 | M23: day | N23: =K23/E23*100 -> 94.035088 | O23: =K23+J23 -> 5700 | P23: =E23-O23 -> 0
A24: 46108 | B24: 1,2,3&4 | C24: C39 | D24: multigrain | E24: 4850 | F24: 6 | G24: 104 | H24: 12 | I24: 128 | J24: =F24+G24+H24+I24 -> 250 | K24: 4600 | L24: 4 | M24: day | N24: =K24/E24*100 -> 94.845361 | O24: =K24+J24 -> 4850 | P24: =E24-O24 -> 0
A25: 46109 | B25: 1,2,3&4 | C25: C39 | D25: multigrain | E25: 4500 | F25: 4 | G25: 112 | H25: 16 | I25: 168 | J25: =F25+G25+H25+I25 -> 300 | K25: 4200 | L25: 4 | N25: =K25/E25*100 -> 93.333333 | O25: =K25+J25 -> 4500 | P25: =E25-O25 -> 0
A26: 46110 | B26: 1,2,3&4 | C26: c39 | D26: multigrain | E26: 2050 | F26: 4 | G26: 45 | H26: 11 | I26: 72 | J26: =4+45+11+72 -> 132 | K26: 1920 | L26: 4 | M26: Day | N26: =K26/E26*100 -> 93.658537 | O26: =K26+J26 -> 2052 | P26: =E26-O26 -> -2
A27: 46111 | B27: 1,2,3&4 | C27: c39 | D27: multigrain | E27: 4260 | F27: 7 | G27: 90 | H27: 10 | I27: 153 | J27: 260 | K27: 4000 | L27: 4 | M27: DAY | N27: =K27/E27*100 -> 93.896714 | O27: =K27+J27 -> 4260 | P27: =E27-O27 -> 0
A28: 46112 | B28: 1,2,3&4 | C28: c39 | D28: multigrain | E28: 8000 | F28: 8 | G28: 470 | H28: 16 | I28: 226 | J28: =F28+G28+H28+I28 -> 720 | K28: 7280 | L28: 5 | M28: DAY | N28: =K28/E28*100 -> 91 | O28: =K28+J28 -> 8000 | P28: =E28-O28 -> 0

Sheet C6 APRIL
A1: Atta Production Report
A2: Date | B2: Machine | C2: Plant | D2: Product | E2: IN in Kg | F2: Sorting | G2: Bran | H2: Floor Atta | I2: Process Loss | J2: Total Wastage | K2: OUT in Kg | L2: Manpower | M2: SHIFT | N2: Yield % | O2: Cross Verification
F3: Grader | G3: Sieve | H3: Floor | I3: Process Loss
A4: 46113 | B4: Chakki1,2,3 | C4: C6 | D4: Khapli wheat | E4: 1000 | F4: 6 | G4: 1 | H4: 1 | I4: 42 | J4: =I4+H4+G4+F4 -> 50 | K4: 950 | L4: 3 | M4: Night | N4: =K4/E4*100 -> 95 | O4: =K4+J4 -> 1000 | P4: =E4-O4 -> 0
A5: 46114 | B5: Chakki1,2,3 | C5: C6 | D5: Khapli wheat | E5: 1050 | F5: 0 | G5: 6 | H5: 1 | I5: 66 | J5: =I5+H5+G5+F5 -> 73 | K5: 977 | L5: 3 | M5: Night | N5: =K5/E5*100 -> 93.047619 | O5: =K5+J5 -> 1050 | P5: =E5-O5 -> 0
A6: 46118 | B6: Chakki1,2,3 | C6: C6 | D6: Khapli wheat | E6: 1150 | F6: 7 | G6: 26 | H6: 1.5 | I6: 80.5 | J6: =I6+H6+G6+F6 -> 115 | K6: 1035 | L6: 4 | M6: Night | N6: =K6/E6*100 -> 90 | O6: =K6+J6 -> 1150 | P6: =E6-O6 -> 0
A7: 46116 | B7: Chakki 1 | C7: C6 | D7: Khapli wheat | E7: 720 | F7: 3 | G7: 10 | H7: 1 | I7: 45 | J7: =I7+H7+G7+F7 -> 59 | K7: 661 | L7: 3 | M7: Day | N7: =K7/E7*100 -> 91.805556 | O7: =K7+J7 -> 720 | P7: =E7-O7 -> 0
A8: 46119 | B8: Chakki1,2,3 | C8: C6 | D8: Khapli wheat | E8: 720 | F8: 1 | G8: 10 | H8: 1 | I8: 28 | J8: =I8+H8+G8+F8 -> 40 | K8: 680 | L8: 2 | M8: Day | N8: =K8/E8*100 -> 94.444444 | O8: =K8+J8 -> 720 | P8: =E8-O8 -> 0
A9: 46120 | B9: Chakki1,2,3 | C9: C6 | D9: Khapli wheat | E9: 850 | F9: 2.5 | G9: 15 | H9: 2 | I9: 40.5 | J9: =I9+H9+G9+F9 -> 60 | K9: 790 | L9: 3 | M9: Night | N9: =K9/E9*100 -> 92.941176 | O9: =K9+J9 -> 850 | P9: =E9-O9 -> 0
A10: 46120 | B10: Chakki1,2,3 | C10: C6 | D10: Khapli wheat | E10: 1200 | F10: 3 | G10: 30 | H10: 2 | I10: 65 | J10: =I10+H10+G10+F10 -> 100 | K10: 1100 | L10: 3 | M10: Day | N10: =K10/E10*100 -> 91.666667 | O10: =K10+J10 -> 1200 | P10: =E10-O10 -> 0
A11: 46121 | B11: Chakki1,2,3 | C11: C6 | D11: Khapli wheat | E11: 900 | F11: 2.5 | G11: 16 | H11: 2 | I11: 56.5 | J11: =I11+H11+G11+F11 -> 77 | K11: 823 | L11: 3 | M11: Day | N11: =K11/E11*100 -> 91.444444 | O11: =K11+J11 -> 900 | P11: =E11-O11 -> 0
A12: 46121 | B12: Chakki1,2,3 | C12: C6 | D12: Bajra | E12: 720 | F12: 2 | G12: 5 | H12: 1 | I12: 62 | J12: =I12+H12+G12+F12 -> 70 | K12: 650 | L12: 3 | M12: Night | N12: =K12/E12*100 -> 90.277778 | O12: =K12+J12 -> 720 | P12: =E12-O12 -> 0
A13: 46122 | B13: Chakki1,2,3 | C13: C6 | D13: Bajra | E13: 1500 | F13: 4.5 | G13: 15 | H13: 2 | I13: 108.5 | J13: =I13+H13+G13+F13 -> 130 | K13: 1370 | L13: 3 | M13: Night | N13: =K13/E13*100 -> 91.333333 | O13: =K13+J13 -> 1500 | P13: =E13-O13 -> 0
A14: 46123 | B14: Chakki1,2,3 | C14: C6 | D14: Bajra | E14: 1200 | F14: 4 | G14: 29 | H14: 2 | I14: 69 | J14: =G14+H14+I14 -> 100 | K14: 1100 | L14: 2 | M14: Day | N14: =K14/E14*100 -> 91.666667 | O14: =K14+J14 -> 1200 | P14: =E14-O14 -> 0
A15: 46123 | B15: Chakki1,2,3 | C15: C6 | D15: Bajra | E15: 420 | F15: 3 | G15: 8 | H15: 1 | I15: 31 | J15: =I15+H15+G15 -> 40 | K15: 380 | L15: 2 | M15: Night | N15: =K15/E15*100 -> 90.47619 | O15: =K15+J15 -> 420 | P15: =E15-O15 -> 0
A16: 46123 | B16: Chakki1,2,3 | C16: C6 | D16: jowar | E16: 944 | F16: 0 | G16: 20 | H16: 1 | I16: 56 | J16: =I16+H16+G16 -> 77 | K16: 867 | L16: 2 | M16: Night | N16: =K16/E16*100 -> 91.84322 | O16: =K16+J16 -> 944 | P16: =E16-O16 -> 0
A17: 46125 | B17: Chakki1,2,3 | C17: C6 | D17: Jowar | E17: 1800 | F17: 7 | G17: 36 | H17: 1 | I17: 113 | J17: =I17+H17+G17 -> 150 | K17: 1650 | L17: 2 | M17: Day | N17: =K17/E17*100 -> 91.666667 | O17: =K17+J17 -> 1800 | P17: =E17-O17 -> 0
A18: 46125 | B18: Chakki1,2,3 | C18: C6 | D18: Jowar | E18: 1420 | F18: 5 | G18: 15 | H18: 1 | I18: 84 | J18: =I18+H18+G18 -> 100 | K18: 1320 | L18: 2 | M18: Night | N18: =K18/E18*100 -> 92.957746 | O18: =K18+J18 -> 1420 | P18: =E18-O18 -> 0
A19: 46126 | B19: Chakki1,2,3 | C19: C6 | D19: Jowar | E19: 1450 | F19: 6 | G19: 60 | H19: 3 | I19: 38 | J19: =I19+H19+G19 -> 101 | K19: 1349 | L19: 2 | M19: Day | N19: =K19/E19*100 -> 93.034483 | O19: =K19+J19 -> 1450 | P19: =E19-O19 -> 0
A20: 46127 | B20: Chakki1,2,3 | C20: C6 | D20: Jowar | E20: 195 | F20: 1 | G20: 3 | H20: 1 | I20: 16 | J20: =I20+H20+G20 -> 20 | K20: 175 | L20: 2 | M20: Day | N20: =K20/E20*100 -> 89.74359 | O20: =K20+J20 -> 195 | P20: =E20-O20 -> 0
A21: 46128 | B21: Chakki1,2,3 | C21: C6 | D21: Khapli wheat | E21: 1450 | F21: 5 | G21: 32 | H21: 2 | I21: 86 | J21: =I21+H21+G21 -> 120 | K21: 1330 | L21: 2 | M21: Night | N21: =K21/E21*100 -> 91.724138 | O21: =K21+J21 -> 1450 | P21: =E21-O21 -> 0
A22: 46129 | B22: Chakki1,2,3 | C22: C6 | D22: Khapli wheat | E22: 2000 | F22: 9 | G22: 21 | H22: 2 | I22: 81 | J22: =I22+H22+G22 -> 104 | K22: 1896 | L22: 2 | M22: Day | N22: =K22/E22*100 -> 94.8 | O22: =K22+J22 -> 2000 | P22: =E22-O22 -> 0
A23: 46129 | B23: Chakki1,2,3 | C23: C6 | D23: Khapli wheat | E23: 1570 | F23: 0 | G23: 10 | H23: 2 | I23: 123 | J23: =I23+H23+G23 -> 135 | K23: 1435 | L23: 3 | M23: Night | N23: =K23/E23*100 -> 91.401274 | O23: =K23+J23 -> 1570 | P23: =E23-O23 -> 0
A24: 46130 | B24: Chakki1,2,3 | C24: C6 | D24: Khapli wheat | E24: 2550 | F24: 15 | G24: 12 | H24: 4 | I24: 207 | J24: =I24+H24+G24 -> 223 | K24: 2327 | L24: 2 | M24: Day | N24: =K24/E24*100 -> 91.254902 | O24: =K24+J24 -> 2550 | P24: =E24-O24 -> 0
A25: 46130 | B25: Chakki1,2,3 | C25: C6 | D25: Khapli wheat | E25: 2300 | F25: 0 | G25: 10 | H25: 2 | I25: 177 | J25: =I25+H25+G25 -> 189 | K25: 2111 | L25: 3 | M25: Night | N25: =K25/E25*100 -> 91.782609 | O25: =K25+J25 -> 2300 | P25: =E25-O25 -> 0
A26: 46128 | B26: Chakki 1&2 | C26: C6 | D26: Protein Atta | E26: 2425 | F26: 15 | G26: 18 | H26: 3 | I26: 124 | J26: =I26+H26+G26 -> 145 | K26: 2280 | L26: 3 | M26: Day | N26: =K26/E26*100 -> 94.020619 | O26: =K26+J26 -> 2425 | P26: =E26-O26 -> 0
... A28: 46133 | B28: Chakki1,2,3 | C28: C6 | D28: Multigrains | E28: 2550 | F28: 24 | G28: 18 | H28: 2 | I28: 180 | J28: =I28+H28+G28 -> 200 | K28: 2350 | L28: 3 | M28: Night | N28: =K28/E28*100 -> 92.156863 | O28: =K28+J28 -> 2550 | P28: =E28-O28 -> 0
A29: 46133 | B29: Chakki1,2,3 | C29: C6 | D29: Multigrains | E29: 2100 | F29: 17 | G29: 18 | H29: 3 | I29: 149 | J29: =I29+H29+G29 -> 170 | K29: 1930 | N29: =K29/E29*100 -> 91.904762 | O29: =K29+J29 -> 2100 | P29: =E29-O29 -> 0
A30: 46134 | B30: Chakki1,2,3 | C30: C6 | D30: Multigrains | E30: 3200 | F30: 27 | G30: 51 | H30: 3 | I30: 196 | J30: =I30+H30+G30 -> 250 | K30: 2950 | L30: 3 | M30: Day | N30: =K30/E30*100 -> 92.1875 | O30: =K30+J30 -> 3200 | P30: =E30-O30 -> 0
A31: 46134 | B31: Chakki1,2,3 | C31: C6 | D31: Multigrains | E31: 2250 | F31: 13 | G31: 12 | H31: 2 | I31: 156 | J31: =I31+H31+G31 -> 170 | K31: 2080 | L31: 3 | M31: Night | N31: =K31/E31*100 -> 92.444444 | O31: =K31+J31 -> 2250 | P31: =E31-O31 -> 0
A32: 46135 | B32: Chakki1,2,3 | C32: C6 | D32: Multigrains | E32: 2000 | F32: 11 | G32: 10 | H32: 2 | I32: 160 | J32: =I32+H32+G32 -> 172 | K32: 1828 | L32: 3 | M32: Day | N32: =K32/E32*100 -> 91.4 | O32: =K32+J32 -> 2000 | P32: =E32-O32 -> 0
A33: 46135 | B33: Chakki1,2,3 | C33: C6 | D33: Multigrains | E33: 2000 | F33: 10 | G33: 17 | H33: 2 | I33: 131 | J33: =I33+H33+G33 -> 150 | K33: 1850 | L33: 3 | M33: Night | N33: =K33/E33*100 -> 92.5 | O33: =K33+J33 -> 2000 | P33: =E33-O33 -> 0
A34: 46135 | B34: Chakki1,2,3 | C34: C6 | D34: Protein Atta | E34: 1261 | F34: 0 | G34: 8 | H34: 8 | I34: 62 | J34: =I34+H34+G34 -> 78 | K34: 1183 | L34: 3 | M34: Night | N34: =K34/E34*100 -> 93.814433 | O34: =K34+J34 -> 1261 | P34: =E34-O34 -> 0
A35: 46136 | B35: Chakki1,2,3 | C35: C6 | D35: Multigrains | E35: 3100 | F35: 15 | G35: 55 | H35: 2 | I35: 173 | J35: =I35+H35+G35 -> 230 | K35: 2870 | L35: 3 | M35: Day | N35: =K35/E35*100 -> 92.580645 | O35: =K35+J35 -> 3100 | P35: =E35-O35 -> 0
A36: 46136 | B36: Chakki1,2,3 | C36: C6 | D36: Multigrains | E36: 2850 | F36: 17 | G36: 48 | H36: 2 | I36: 170 | J36: =I36+H36+G36 -> 220 | K36: 2630 | L36: 3 | M36: Night | N36: =K36/E36*100 -> 92.280702 | O36: =K36+J36 -> 2850 | P36: =E36-O36 -> 0
A37: 46139 | B37: Chakki1,2,3 | C37: C6 | D37: Multigrains | E37: 2100 | F37: 14 | G37: 24 | H37: 2 | I37: 134 | J37: =I37+H37+G37 -> 160 | K37: 1940 | L37: 3 | M37: Day | N37: =K37/E37*100 -> 92.380952 | O37: =K37+J37 -> 2100 | P37: =E37-O37 -> 0
A38: 46140 | B38: Chakki1,2,3 | C38: C6 | D38: Bajra | E38: 535 | F38: 1 | G38: 3 | H38: 10 | I38: 37 | J38: =I38+H38+G38 -> 50 | K38: 485 | L38: 3 | M38: Day | N38: =K38/E38*100 -> 90.654206 | O38: =K38+J38 -> 535 | P38: =E38-O38 -> 0
A39: 46141 | B39: Chakki1,2,3 | C39: C6 | D39: Jowar | E39: 2870 | F39: 14 | G39: 39 | H39: 2 | I39: 193 | J39: =I39+H39+G39 -> 234 | K39: 2636 | L39: 3 | M39: Night | N39: =K39/E39*100 -> 91.84669 | O39: =K39+J39 -> 2870 | P39: =E39-O39 -> 0
A40: 46142 | B40: Chakki1,2,3 | C40: C6 | D40: Bajra | E40: 225 | F40: 1 | G40: 8 | H40: 2 | I40: 11 | J40: =I40+H40+G40 -> 21 | K40: 204 | L40: 3 | M40: Day | N40: =K40/E40*100 -> 90.666667 | O40: =K40+J40 -> 225 | P40: =E40-O40 -> 0
A41: 46142 | B41: Chakki1,2,3 | C41: C6 | D41: Jowar | E41: 340 | F41: 1 | G41: 15 | H41: 2 | I41: 18 | J41: =SUM(F41:I41) -> 36 | K41: 305 | L41: 3 | M41: Day | N41: =K41/E41*100 -> 89.705882 | O41: =K41+J41 -> 341 | P41: =E41-O41 -> -1
...

Sheet C39 APRIL
A1: Atta Production Report
A2: Date | B2: Machine | C2: Plant | D2: Product | E2: IN in Kg | F2: Sorting | G2: Bran | H2: Floor Atta | I2: Process Loss | J2: Total Wastage | K2: OUT in Kg | L2: Manpower | M2: Shift | N2: Yield % | O2: Cross Verification
F3: Grader | G3: Sieve | H3: Floor | I3: Process Loss
A4: 46113 | B4: 1,2,3&4 | C4: C39 | D4: multigrain | E4: 7600 | F4: 7 | G4: 463 | H4: 12 | I4: 272 | J4: 754 | K4: 6846 | L4: 5 | M4: Day | N4: =K4/E4*100 -> 90.078947 | O4: =K4+J4 -> 7600 | P4: =E4-O4 -> 0
A5: 46114 | B5: 1,2,3&4 | C5: C39 | D5: multigrain | E5: 6500 | F5: 8 | G5: 420 | H5: 16 | I5: 189 | J5: =I5+H5+G5+F5 -> 633 | K5: 5867 | L5: 5 | M5: Day | N5: =K5/E5*100 -> 90.261538 | O5: =K5+J5 -> 6500 | P5: =E5-O5 -> 0
A6: 46115 | B6: 123&4 | C6: C39 | D6: multigrain | E6: 6800 | F6: 9 | G6: 310 | H6: 22 | I6: 119 | J6: 560 | K6: 6340 | L6: 5 | M6: Day | N6: =K6/E6*100 -> 93.235294 | O6: 6800 | P6: =E6-O6 -> 0
A7: 46116 | B7: 123&4 | C7: C39 | D7: multigrain | E7: 4750 | F7: 6 | G7: 300 | H7: 18 | I7: 91 | J7: =6+300+18+91 -> 415 | K7: 4335 | L7: 5 | M7: Day | N7: =K7/E7*100 -> 91.263158 | O7: =K7+J7 -> 4750 | P7: =E7-O7 -> 0
A8: 46117 | B8: 123&4 | C8: C39 | D8: multigrain | E8: 5500 | F8: 6 | G8: 280 | H8: 18 | I8: 96 | J8: =SUM(F8:I8) -> 400 | K8: 5100 | L8: 5 | M8: Day | N8: =K8/E8*100 -> 92.727273 | O8: =K8+J8 -> 5500 | P8: =E8-O8 -> 0
A9: 46118 | B9: 123&4 | C9: C39 | D9: multigrain | E9: 5000 | F9: 6 | G9: 240 | H9: 22 | I9: 82 | J9: =SUM(F9:I9) -> 350 | K9: 4650 | L9: 6 | M9: Day | N9: =K9/E9*100 -> 93 | O9: =K9+J9 -> 5000 | P9: =E9-O9 -> 0
A10: 46119 | B10: 123&4 | C10: C39 | D10: multigrain | E10: 4650 | F10: 9 | G10: 160 | H10: 10 | I10: 141 | J10: =SUM(F10:I10) -> 320 | K10: 4330 | L10: 7 | M10: Day | N10: =K10/E10*100 -> 93.11828 | O10: =K10+J10 -> 4650 | P10: =E10-O10 -> 0
A11: 46120 | B11: 123&4 | C11: C39 | D11: multigrain | E11: 5400 | F11: 8 | G11: 240 | H11: 12 | I11: 165 | J11: =SUM(F11:I11) -> 425 | K11: 4975 | L11: 6 | M11: Day | N11: =K11/E11*100 -> 92.12963 | O11: =K11+J11 -> 5400 | P11: =E11-O11 -> 0
A12: 46121 | B12: 123&4 | C12: C39 | D12: multigrain | E12: 7600 | F12: 12 | G12: 230 | H12: 18 | I12: 290 | J12: =SUM(F12:I12) -> 550 | K12: 7050 | L12: 6 | M12: Day | N12: =K12/E12*100 -> 92.763158 | O12: =K12+J12 -> 7600 | P12: =E12-O12 -> 0
A13: 46122 | B13: 123&4 | C13: C39 | D13: multigrain | E13: 7000 | F13: 9 | G13: 210 | H13: 12 | I13: 254 | J13: =SUM(F13:I13) -> 485 | K13: 6515 | L13: 6 | M13: Day | N13: =K13/E13*100 -> 93.071429 | O13: =K13+J13 -> 7000 | P13: =E13-O13 -> 0
A14: 46123 | B14: 123&4 | C14: C39 | D14: multigrain | E14: 7400 | F14: 12 | G14: 175 | H14: 18 | I14: 175 | J14: =SUM(F14:I14) -> 380 | K14: 7020 | L14: 6 | M14: Day | N14: =K14/E14*100 -> 94.864865 | O14: =K14+J14 -> 7400 | P14: =E14-O14 -> 0
A15: 46124 | B15: 123&4 | C15: C39 | D15: multigrain | E15: 5900 | F15: 10 | G15: 160 | H15: 19 | I15: 181 | J15: =SUM(F15:I15) -> 370 | K15: 5530 | L15: 6 | M15: Day | N15: =K15/E15*100 -> 93.728814 | O15: =K15+J15 -> 5900 | P15: =E15-O15 -> 0
A16: 46125 | B16: 123&4 | C16: C39 | D16: multigrain | E16: 3000 | F16: 8 | G16: 98 | H16: 28 | I16: 66 | J16: =SUM(F16:I16) -> 200 | K16: 2800 | L16: 6 | M16: day | N16: =K16/E16*100 -> 93.333333 | O16: =K16+J16 -> 3000 | P16: =E16-O16 -> 0
A17: 46126 | B17: 123&4 | C17: C39 | D17: multigrain | E17: 7000 | F17: 10 | G17: 198 | H17: 16 | I17: 236 | J17: =SUM(F17:I17) -> 460 | K17: 6540 | L17: 6 | M17: day | N17: =K17/E17*100 -> 93.428571 | O17: =K17+J17 -> 7000 | P17: =E17-O17 -> 0
A18: 46127 | B18: 123&4 | C18: C39 | D18: multigrain | E18: 2150 | F18: 16 | G18: 55 | H18: 15 | I18: 64 | J18: =SUM(F18:I18) -> 150 | K18: 2000 | L18: 6 | M18: Day | N18: =K18/E18*100 -> 93.023256 | O18: =K18+J18 -> 2150 | P18: =E18-O18 -> 0
A19: 46129 | B19: 123&4 | C19: C39 | D19: multigrain | E19: 5000 | F19: 5 | G19: 137 | H19: 18 | I19: 140 | J19: =SUM(F19:I19) -> 300 | K19: 4700 | L19: 5 | M19: day | N19: =K19/E19*100 -> 94 | O19: =K19+J19 -> 5000 | P19: =E19-O19 -> 0
A20: 46132 | B20: 123&4 | C20: C39 | D20: khapli Grains | E20: 950 | F20: 12 | G20: 40 | H20: 15 | I20: 33 | J20: 100 | K20: 850 | L20: 4 | M20: Day | N20: =K20/E20*100 -> 89.473684 | O20: =K20+J20 -> 950 | P20: =E20-O20 -> 0
A21: 46133 | B21: 123&4 | C21: C39 | D21: khapli Grains | E21: 8600 | F21: 90 | G21: 142 | H21: 38 | I21: 330 | J21: 600 | K21: 8000 | L21: 4 | M21: Day | N21: =K21/E21*100 -> 93.023256 | O21: =K21+J21 -> 8600 | P21: =E21-O21 -> 0
A22: 46134 | B22: 123&4 | C22: C39 | D22: khapli Grains | E22: 6512 | F22: 84 | G22: 106 | H22: 25 | I22: 297 | J22: 512 | K22: 6000 | L22: 4 | M22: Day | N22: =K22/E22*100 -> 92.137592 | O22: =K22+J22 -> 6512 | P22: =E22-O22 -> 0
A23: 46135 | B23: 123&4 | C23: C39 | D23: khapli Grains | E23: 7000 | F23: 70 | G23: 128 | H23: 22 | I23: 280 | J23: 500 | K23: 6500 | L23: 4 | M23: Day | N23: =K23/E23*100 -> 92.857143 | O23: =K23+J23 -> 7000 | P23: =E23-O23 -> 0
A24: 46136 | B24: 123&4 | C24: C39 | D24: khapli Grains | E24: 8600 | F24: 95 | G24: 160 | H24: 28 | I24: 355 | J24: 638 | K24: 7962 | L24: 4 | M24: Day | N24: =K24/E24*100 -> 92.581395 | O24: =K24+J24 -> 8600 | P24: =E24-O24 -> 0
A25: 46137 | B25: 123&4 | C25: C39 | D25: khapli Grains | E25: 4900 | F25: 51 | G25: 98 | H25: 25 | I25: 190 | J25: 364 | K25: 4536 | L25: 4 | M25: Day | N25: =K25/E25*100 -> 92.571429 | O25: =K25+J25 -> 4900 | P25: =E25-O25 -> 0
A26: 46139 | B26: 123&4 | C26: C39 | D26: MULTIGRAIN | E26: 7000 | F26: 45 | G26: 265 | H26: 30 | I26: 195 | J26: 530 | K26: 6470 | L26: 4 | M26: Day | N26: =K26/E26*100 -> 92.428571 | O26: =K26+J26 -> 7000 | P26: =E26-O26 -> 0
A27: 46140 | B27: 123&4 | C27: C39 | D27: MULTIGRAIN | E27: 7449 | F27: 52 | G27: 270 | H27: 20 | I27: 215 | J27: 557 | K27: 6892 | L27: 4 | M27: day | N27: 92.4 | O27: =K27+J27 -> 7449 | P27: =E27-O27 -> 0
A28: 46141 | B28: 123&4 | C28: C39 | D28: MULTIGRAIN | E28: 7900 | F28: 85 | G28: 235 | H28: 25 | I28: 222 | J28: =85+235+25+222 -> 567 | K28: 7333 | L28: 4 | M28: DAY | N28: 92.82 | O28: 7900 | P28: =E28-O28 -> 0
A29: 46142 | B29: 123&4 | C29: C39 | D29: MULTIGRAIN | E29: 2000 | F29: 15 | G29: 75 | H29: 15 | I29: 83 | J29: 125 | K29: 1875 | L29: 4 | M29: DAY | N29: 93.75 | O29: 2000 | P29: =E29-O29 -> 0
N32: =AVERAGE(#REF!) -> #REF!
I33: Total | N33: Avarage
I34: Total Cost
I35: Cost Per kg

Sheet C6-MAY
A1: Atta Production Report
A2: Date | B2: Machine | C2: Plant | D2: Product | E2: IN in Kg | F2: Sorting | G2: Bran | H2: Floor Atta | I2: Process Loss | J2: Total Wastage | K2: OUT in Kg | L2: Manpower | M2: Shift | N2: Yield %
F3: Grader | G3: Sieve | H3: Floor | I3: Process Loss | Q3: Remark
A4: 46144 | B4: chakki1,2,3 | C4: C6 | D4: jowar | E4: 1850 | F4: 0 | G4: 41 | H4: 4 | I4: 82.1 | J4: =I4+H4+G4 -> 127.1 | K4: 1722.9 | L4: 3 | M4: DAY | N4: =K4/E4*100 -> 93.12973 | O4: =K4+J4 -> 1850 | P4: =O4-E4 -> 0
A5: 46144 | B5: chakki1,2,3 | C5: C6 | D5: khapli | E5: 1200 | F5: 0 | G5: 48 | H5: 5 | I5: 59 | J5: =I5+H5+G5 -> 112 | K5: 1088 | L5: 3 | M5: DAY | N5: =K5/E5*100 -> 90.666667 | O5: =K5+J5 -> 1200 | P5: =O5-E5 -> 0
A6: 46146 | B6: chakki1,2,3 | C6: C6 | D6: khapli | E6: 3100 | F6: 25 | G6: 70 | H6: 5 | I6: 100 | J6: =I6+H6+G6+F6 -> 200 | K6: 2900 | L6: 4 | M6: DAY | N6: =K6/E6*100 -> 93.548387 | O6: =K6+J6 -> 3100 | P6: =O6-E6 -> 0
A7: 46147 | B7: chakki1,2,3 | C7: C6 | D7: khapli | E7: 2450 | F7: 10 | G7: 105 | H7: 16 | I7: 99 | J7: =I7+H7+G7+F7 -> 230 | K7: 2220 | L7: 3 | M7: DAY | N7: =K7/E7*100 -> 90.612245 | O7: =K7+J7 -> 2450 | P7: =O7-E7 -> 0
A8: 46148 | B8: chakki1,2,3 | C8: C6 | D8: khapli | E8: 2650 | F8: 12 | G8: 35 | H8: 6 | I8: 89 | J8: =F8+G8+H8+I8 -> 142 | K8: 2508 | L8: 3 | M8: DAY | N8: =K8/E8*100 -> 94.641509 | O8: =K8+J8 -> 2650 | P8: =O8-E8 -> 0
A9: 46149 | B9: chakki1,2,3 | C9: C6 | D9: khapli | E9: 750 | F9: 7 | G9: 10 | H9: 3 | I9: 30 | J9: =F9+G9+H9+I9 -> 50 | K9: 700 | L9: 4 | M9: DAY | N9: =K9/E9*100 -> 93.333333 | O9: =K9+J9 -> 750 | P9: =O9-E9 -> 0
A10: 46150 | B10: chakki1,2,3 | C10: C6 | D10: khapli Multigrain | E10: 2700 | F10: 20 | G10: 35 | H10: 5 | I10: 110 | J10: =F10+G10+H10+I10 -> 170 | K10: 2530 | L10: 3 | M10: DAY | N10: =K10/E10*100 -> 93.703704 | O10: =K10+J10 -> 2700 | P10: =O10-E10 -> 0
A11: 46151 | B11: chakki1,2,3 | C11: C6 | D11: khapli Multigrain | E11: 300 | F11: 5 | G11: 4 | H11: 1 | I11: 10 | J11: =F11+G11+H11+I11 -> 20 | K11: 280 | L11: 4 | M11: DAY | N11: =K11/E11*100 -> 93.333333 | O11: =K11+J11 -> 300 | P11: =O11-E11 -> 0
A12: 46151 | B12: chakki1,2,3 | C12: NEW PLANT | D12: HIGH PROTEIN ATTA | E12: 1455 | F12: 2 | G12: 30 | H12: 7 | I12: 70 | J12: =F12+G12+H12+I12 -> 109 | K12: 1346 | L12: 4 | M12: DAY | N12: =K12/E12*100 -> 92.508591 | O12: =K12+J12 -> 1455 | P12: =O12-E12 -> 0
A13: 46153 | B13: chakki1,2,3 | C13: NEW PLANT | D13: HIGH PROTEIN ATTA | E13: 1649 | F13: 0 | G13: 43 | H13: 3 | I13: 75 | J13: =G13+H13+I13 -> 121 | K13: 1528 | L13: 3 | M13: DAY | N13: =K13/E13*100 -> 92.66222 | O13: =K13+J13 -> 1649 | P13: =O13-E13 -> 0
