Workbook

Sheet Dashboard
A1: WORKFORCE COMMAND CENTER
P2: Section | Q2: Gap | R2: Date | S2: Plan | T2: Present | U2: OT Hours | AA2: ='Daily Tracker'!E$2 -> 46174 | AB2: ='Daily Tracker'!F$2 -> 46175 | AC2: ='Daily Tracker'!G$2 -> 46176 | AD2: ='Daily Tracker'!H$2 -> 46177 | AE2: ='Daily Tracker'!I$2 -> 46178 | AF2: ='Daily Tracker'!J$2 -> 46179 | AG2: ='Daily Tracker'!K$2 -> 46180 | AH2: ='Daily Tracker'!L$2 -> 46181 | ... GS2: ='Daily Tracker'!FW$2 -> 0
A3: Daily manpower intelligence • KPI KEY: GREEN ≥95% | AMBER 85–94.9% | RED <85% | P3: {=_xlfn.LET(_xlpm.msk,(($E$4="All")+($A$17:$A$43=$E$4)>0)*(($H$4="All")+($B$17:$B$43=$H$4)>0)*(($K$4="All")+($C$17:$C$43=$K$4)>0),_xlpm.x,_xlfn._xlws.FILTER(CHOOSE({1,2},$C$17:$C$43,IF($F$17:$F$43<0,0,$F$17:$F$43)),_xlpm.msk),IFERROR(_xlfn.TAKE(_xlfn.SORTBY(_xlpm.x,_xlfn.CHOOSECOLS(_xlpm.x,2),-1),MIN(10,ROWS(_xlpm.x))),""))} -> C39 - Atta | Q3: 13 | R3: {=IFERROR(INDEX('Daily Tracker'!$E$2:$FA$2,1,MAX(1,MATCH($B$4,'Daily Tracker'!$E$2:$FA$2,0)-13)),"")} -> 46295 | S3: =IF(R3="","",$A$7) -> 266 | T3: =IF(R3="","",SUMIFS(W$17:W$43,$A$17:$A$43,IF($E$4="All","*",$E$4),$B$17:$B$43,IF($H$4="All","*",$H$4),$C$17:$C$43,IF($K$4="All","*",$K$4))) -> 222 | U3: =IF(R3="","",INDEX('Daily Tracker'!$E$37:$FA$37,1,MATCH(R3,'Daily Tracker'!$E$2:$FA$2,0))) -> 0 | FX3: All | FY3: All | FZ3: All
A4: DATE | B4: 46308 | D4: CATEGORY | E4: All | G4: PLANT | H4: All | J4: SECTION | K4: All | P4: Supervisors + Executive+AM +HR | Q4: 8 | R4: {=IFERROR(INDEX('Daily Tracker'!$E$2:$FA$2,1,MAX(1,MATCH($B$4,'Daily Tracker'!$E$2:$FA$2,0)-12)),"")} -> 46296 | S4: =IF(R4="","",$A$7) -> 266 | T4: =IF(R4="","",SUMIFS(X$17:X$43,$A$17:$A$43,IF($E$4="All","*",$E$4),$B$17:$B$43,IF($H$4="All","*",$H$4),$C$17:$C$43,IF($K$4="All","*",$K$4))) -> 222 | U4: =IF(R4="","",INDEX('Daily Tracker'!$E$37:$FA$37,1,MATCH(R4,'Daily Tracker'!$E$2:$FA$2,0))) -> 103 | FX4: Production | FY4: C6 | FZ4: C6 - Oil
A5: ="ACTIVE VIEW • "&TEXT($B$4,"dd-mmm-yyyy")&" | Category: "&$E$4&" | Plant: "&$H$4&" | Section: "&$K$4 -> ACTIVE VIEW • 13-Oct-2026 | Category: All | Plant: All | Section: All | P5: C6 Atta - 2 | Q5: 6 | R5: {=IFERROR(INDEX('Daily Tracker'!$E$2:$FA$2,1,MAX(1,MATCH($B$4,'Daily Tracker'!$E$2:$FA$2,0)-11)),"")} -> 46297 | S5: =IF(R5="","",$A$7) -> 266 | T5: =IF(R5="","",SUMIFS(Y$17:Y$43,$A$17:$A$43,IF($E$4="All","*",$E$4),$B$17:$B$43,IF($H$4="All","*",$H$4),$C$17:$C$43,IF($K$4="All","*",$K$4))) -> 0 | U5: =IF(R5="","",INDEX('Daily Tracker'!$E$37:$FA$37,1,MATCH(R5,'Daily Tracker'!$E$2:$FA$2,0))) -> 0 | FX5: Support | FY5: C39 | FZ5: C6 - Ghee
A6: PLANNED MP | D6: TOTAL PRESENT | G6: ABSENT MP | J6: ATTENDANCE RATE | M6: APPROVED LEAVE (ALL) | P6: Supply/ Dispatch (Common) | Q6: 5 | R6: {=IFERROR(INDEX('Daily Tracker'!$E$2:$FA$2,1,MAX(1,MATCH($B$4,'Daily Tracker'!$E$2:$FA$2,0)-10)),"")} -> 46298 | S6: =IF(R6="","",$A$7) -> 266 | T6: =IF(R6="","",SUMIFS(Z$17:Z$43,$A$17:$A$43,IF($E$4="All","*",$E$4),$B$17:$B$43,IF($H$4="All","*",$H$4),$C$17:$C$43,IF($K$4="All","*",$K$4))) -> 194 | U6: =IF(R6="","",INDEX('Daily Tracker'!$E$37:$FA$37,1,MATCH(R6,'Daily Tracker'!$E$2:$FA$2,0))) -> 8 | FY6: Printer | FZ6: C39 - MG batch Making
A7: =SUMIFS($D$17:$D$43,$A$17:$A$43,IF($E$4="All","*",$E$4),$B$17:$B$43,IF($H$4="All","*",$H$4),$C$17:$C$43,IF($K$4="All","*",$K$4)) -> 266 | D7: =SUMIFS($E$17:$E$43,$A$17:$A$43,IF($E$4="All","*",$E$4),$B$17:$B$43,IF($H$4="All","*",$H$4),$C$17:$C$43,IF($K$4="All","*",$K$4)) -> 234 | G7: =MAX(0,A7-D7) -> 32 | J7: =IFERROR(D7/A7,0) -> 0.87969925 | M7: =IFERROR(INDEX('Daily Tracker'!$E$36:$FA$36,1,MATCH($B$4,'Daily Tracker'!$E$2:$FA$2,0)),0) -> 0 | P7: Night MP Total Ghee | Q7: 5 | R7: {=IFERROR(INDEX('Daily Tracker'!$E$2:$FA$2,1,MAX(1,MATCH($B$4,'Daily Tracker'!$E$2:$FA$2,0)-9)),"")} -> 46299 | S7: =IF(R7="","",$A$7) -> 266 | T7: =IF(R7="","",SUMIFS(AA$17:AA$43,$A$17:$A$43,IF($E$4="All","*",$E$4),$B$17:$B$43,IF($H$4="All","*",$H$4),$C$17:$C$43,IF($K$4="All","*",$K$4))) -> 103 | U7: =IF(R7="","",INDEX('Daily Tracker'!$E$37:$FA$37,1,MATCH(R7,'Daily Tracker'!$E$2:$FA$2,0))) -> 140 | FY7: FRM | FZ7: Supply/ Dispatch (Common)
P8: C39 - Honey / all Spices | Q8: 4 | R8: {=IFERROR(INDEX('Daily Tracker'!$E$2:$FA$2,1,MAX(1,MATCH($B$4,'Daily Tracker'!$E$2:$FA$2,0)-8)),"")} -> 46300 | S8: =IF(R8="","",$A$7) -> 266 | T8: =IF(R8="","",SUMIFS(AB$17:AB$43,$A$17:$A$43,IF($E$4="All","*",$E$4),$B$17:$B$43,IF($H$4="All","*",$H$4),$C$17:$C$43,IF($K$4="All","*",$K$4))) -> 196 | U8: =IF(R8="","",INDEX('Daily Tracker'!$E$37:$FA$37,1,MATCH(R8,'Daily Tracker'!$E$2:$FA$2,0))) -> 0 | FY8: Support | FZ8: Printer (Common)
P9: C6 - Oil | Q9: 3 | R9: {=IFERROR(INDEX('Daily Tracker'!$E$2:$FA$2,1,MAX(1,MATCH($B$4,'Daily Tracker'!$E$2:$FA$2,0)-7)),"")} -> 46301 | S9: =IF(R9="","",$A$7) -> 266 | T9: =IF(R9="","",SUMIFS(AC$17:AC$43,$A$17:$A$43,IF($E$4="All","*",$E$4),$B$17:$B$43,IF($H$4="All","*",$H$4),$C$17:$C$43,IF($K$4="All","*",$K$4))) -> 227 | U9: =IF(R9="","",INDEX('Daily Tracker'!$E$37:$FA$37,1,MATCH(R9,'Daily Tracker'!$E$2:$FA$2,0))) -> 112 | FY9: Ghee | FZ9: C6 - Raw Agri (Millets)
P10: C6 - Ghee | Q10: 3 | R10: {=IFERROR(INDEX('Daily Tracker'!$E$2:$FA$2,1,MAX(1,MATCH($B$4,'Daily Tracker'!$E$2:$FA$2,0)-6)),"")} -> 46302 | S10: =IF(R10="","",$A$7) -> 266 | T10: =IF(R10="","",SUMIFS(AD$17:AD$43,$A$17:$A$43,IF($E$4="All","*",$E$4),$B$17:$B$43,IF($H$4="All","*",$H$4),$C$17:$C$43,IF($K$4="All","*",$K$4))) -> 222 | U10: =IF(R10="","",INDEX('Daily Tracker'!$E$37:$FA$37,1,MATCH(R10,'Daily Tracker'!$E$2:$FA$2,0))) -> 85 | FY10: Supply | FZ10: C39 - Honey / all Spices
A11: PRODUCTION PRESENT | D11: SUPPORT PRESENT | G11: OT HOURS (ALL) | J11: PRODUCTION SHARE | M11: GAP VS PLAN | P11: Total C6 Night MP | Q11: 2 | R11: {=IFERROR(INDEX('Daily Tracker'!$E$2:$FA$2,1,MAX(1,MATCH($B$4,'Daily Tracker'!$E$2:$FA$2,0)-5)),"")} -> 46303 | S11: =IF(R11="","",$A$7) -> 266 | T11: =IF(R11="","",SUMIFS(AE$17:AE$43,$A$17:$A$43,IF($E$4="All","*",$E$4),$B$17:$B$43,IF($H$4="All","*",$H$4),$C$17:$C$43,IF($K$4="All","*",$K$4))) -> 155 | U11: =IF(R11="","",INDEX('Daily Tracker'!$E$37:$FA$37,1,MATCH(R11,'Daily Tracker'!$E$2:$FA$2,0))) -> 92 | FZ11: C39 - Jaggery
A12: =IF(OR($E$4="All",$E$4="Production"),SUMIFS($E$17:$E$43,$A$17:$A$43,"Production",$B$17:$B$43,IF($H$4="All","*",$H$4),$C$17:$C$43,IF($K$4="All","*",$K$4)),0) -> 187 | D12: =IF(OR($E$4="All",$E$4="Support"),SUMIFS($E$17:$E$43,$A$17:$A$43,"Support",$B$17:$B$43,IF($H$4="All","*",$H$4),$C$17:$C$43,IF($K$4="All","*",$K$4)),0) -> 47 | G12: =IFERROR(INDEX('Daily Tracker'!$E$37:$FA$37,1,MATCH($B$4,'Daily Tracker'!$E$2:$FA$2,0)),0) -> 92 | J12: =IFERROR(A12/D7,0) -> 0.7991453 | M12: =A7-D7 -> 32 | P12: QA | Q12: 2 | R12: {=IFERROR(INDEX('Daily Tracker'!$E$2:$FA$2,1,MAX(1,MATCH($B$4,'Daily Tracker'!$E$2:$FA$2,0)-4)),"")} -> 46304 | S12: =IF(R12="","",$A$7) -> 266 | T12: =IF(R12="","",SUMIFS(AF$17:AF$43,$A$17:$A$43,IF($E$4="All","*",$E$4),$B$17:$B$43,IF($H$4="All","*",$H$4),$C$17:$C$43,IF($K$4="All","*",$K$4))) -> 231 | U12: =IF(R12="","",INDEX('Daily Tracker'!$E$37:$FA$37,1,MATCH(R12,'Daily Tracker'!$E$2:$FA$2,0))) -> 101 | FZ12: C39 - Atta
R13: {=IFERROR(INDEX('Daily Tracker'!$E$2:$FA$2,1,MAX(1,MATCH($B$4,'Daily Tracker'!$E$2:$FA$2,0)-3)),"")} -> 46305 | S13: =IF(R13="","",$A$7) -> 266 | T13: =IF(R13="","",SUMIFS(AG$17:AG$43,$A$17:$A$43,IF($E$4="All","*",$E$4),$B$17:$B$43,IF($H$4="All","*",$H$4),$C$17:$C$43,IF($K$4="All","*",$K$4))) -> 211 | U13: =IF(R13="","",INDEX('Daily Tracker'!$E$37:$FA$37,1,MATCH(R13,'Daily Tracker'!$E$2:$FA$2,0))) -> 90 | FZ13: C6 - Atta - 1
R14: {=IFERROR(INDEX('Daily Tracker'!$E$2:$FA$2,1,MAX(1,MATCH($B$4,'Daily Tracker'!$E$2:$FA$2,0)-2)),"")} -> 46306 | S14: =IF(R14="","",$A$7) -> 266 | T14: =IF(R14="","",SUMIFS(AH$17:AH$43,$A$17:$A$43,IF($E$4="All","*",$E$4),$B$17:$B$43,IF($H$4="All","*",$H$4),$C$17:$C$43,IF($K$4="All","*",$K$4))) -> 91 | U14: =IF(R14="","",INDEX('Daily Tracker'!$E$37:$FA$37,1,MATCH(R14,'Daily Tracker'!$E$2:$FA$2,0))) -> 96 | FZ14: C6 Atta - 2
A15: SECTION DETAIL — SELECTED DATE | R15: {=IFERROR(INDEX('Daily Tracker'!$E$2:$FA$2,1,MAX(1,MATCH($B$4,'Daily Tracker'!$E$2:$FA$2,0)-1)),"")} -> 46307 | S15: =IF(R15="","",$A$7) -> 266 | T15: =IF(R15="","",SUMIFS(AI$17:AI$43,$A$17:$A$43,IF($E$4="All","*",$E$4),$B$17:$B$43,IF($H$4="All","*",$H$4),$C$17:$C$43,IF($K$4="All","*",$K$4))) -> 195 | U15: =IF(R15="","",INDEX('Daily Tracker'!$E$37:$FA$37,1,MATCH(R15,'Daily Tracker'!$E$2:$FA$2,0))) -> 0 | FZ15: FRM - Khapal-Khapli
A16: Category | B16: Plant | C16: Section | D16: Plan MP | E16: Present MP | F16: Gap vs Plan | G16: Attendance % | R16: {=IFERROR(INDEX('Daily Tracker'!$E$2:$FA$2,1,MAX(1,MATCH($B$4,'Daily Tracker'!$E$2:$FA$2,0)-0)),"")} -> 46308 | S16: =IF(R16="","",$A$7) -> 266 | T16: =IF(R16="","",SUMIFS(AJ$17:AJ$43,$A$17:$A$43,IF($E$4="All","*",$E$4),$B$17:$B$43,IF($H$4="All","*",$H$4),$C$17:$C$43,IF($K$4="All","*",$K$4))) -> 234 | U16: =IF(R16="","",INDEX('Daily Tracker'!$E$37:$FA$37,1,MATCH(R16,'Daily Tracker'!$E$2:$FA$2,0))) -> 92 | W16: =R3 -> 46295 | X16: =R4 -> 46296 | Y16: =R5 -> 46297 | Z16: =R6 -> 46298 | AA16: =R7 -> 46299 | AB16: =R8 -> 46300 | AC16: =R9 -> 46301 | AD16: =R10 -> 46302 | AE16: =R11 -> 46303 | AF16: =R12 -> 46304 | AG16: =R13 -> 46305 | AH16: =R14 -> 46306 | AI16: =R15 -> 46307 | AJ16: =R16 -> 46308 | FZ16: Total Ghee B Shift MP
A17: Production | B17: =IF('Daily Tracker'!B3="",A17,'Daily Tracker'!B3) -> C6 | C17: ='Daily Tracker'!C3 -> C6 - Oil | D17: ='Daily Tracker'!D3 -> 14 | E17: =IFERROR(INDEX('Daily Tracker'!$E3:$FA3,1,MATCH($B$4,'Daily Tracker'!$E$2:$FA$2,0)),0) -> 11 | F17: =D17-E17 -> 3 | G17: =IFERROR(E17/D17,0) -> 0.78571429 | V17: 3 | W17: =IF(W$16="","",IFERROR(INDEX('Daily Tracker'!$E3:$FA3,1,MATCH(W$16,'Daily Tracker'!$E$2:$FA$2,0)),0)) -> 11 | X17: =IF(X$16="","",IFERROR(INDEX('Daily Tracker'!$E3:$FA3,1,MATCH(X$16,'Daily Tracker'!$E$2:$FA$2,0)),0)) -> 11 | Y17: =IF(Y$16="","",IFERROR(INDEX('Daily Tracker'!$E3:$FA3,1,MATCH(Y$16,'Daily Tracker'!$E$2:$FA$2,0)),0)) -> 0 | Z17: =IF(Z$16="","",IFERROR(INDEX('Daily Tracker'!$E3:$FA3,1,MATCH(Z$16,'Daily Tracker'!$E$2:$FA$2,0)),0)) -> 12 | AA17: =IF(AA$16="","",IFERROR(INDEX('Daily Tracker'!$E3:$FA3,1,MATCH(AA$16,'Daily Tracker'!$E$2:$FA$2,0)),0)) -> 0 | AB17: =IF(AB$16="","",IFERROR(INDEX('Daily Tracker'!$E3:$FA3,1,MATCH(AB$16,'Daily Tracker'!$E$2:$FA$2,0)),0)) -> 12 | AC17: =IF(AC$16="","",IFERROR(INDEX('Daily Tracker'!$E3:$FA3,1,MATCH(AC$16,'Daily Tracker'!$E$2:$FA$2,0)),0)) -> 13 | AD17: =IF(AD$16="","",IFERROR(INDEX('Daily Tracker'!$E3:$FA3,1,MATCH(AD$16,'Daily Tracker'!$E$2:$FA$2,0)),0)) -> 14 | ... AJ17: =IF(AJ$16="","",IFERROR(INDEX('Daily Tracker'!$E3:$FA3,1,MATCH(AJ$16,'Daily Tracker'!$E$2:$FA$2,0)),0)) -> 11 | FZ17: Total Ghee Night MP
A18: Production | B18: =IF('Daily Tracker'!B4="",A18,'Daily Tracker'!B4) -> Ghee | C18: ='Daily Tracker'!C4 -> C6 - Ghee | D18: ='Daily Tracker'!D4 -> 24 | E18: =IFERROR(INDEX('Daily Tracker'!$E4:$FA4,1,MATCH($B$4,'Daily Tracker'!$E$2:$FA$2,0)),0) -> 21 | F18: =D18-E18 -> 3 | G18: =IFERROR(E18/D18,0) -> 0.875 | V18: 4 | W18: =IF(W$16="","",IFERROR(INDEX('Daily Tracker'!$E4:$FA4,1,MATCH(W$16,'Daily Tracker'!$E$2:$FA$2,0)),0)) -> 18 | X18: =IF(X$16="","",IFERROR(INDEX('Daily Tracker'!$E4:$FA4,1,MATCH(X$16,'Daily Tracker'!$E$2:$FA$2,0)),0)) -> 20 | Y18: =IF(Y$16="","",IFERROR(INDEX('Daily Tracker'!$E4:$FA4,1,MATCH(Y$16,'Daily Tracker'!$E$2:$FA$2,0)),0)) -> 0 | Z18: =IF(Z$16="","",IFERROR(INDEX('Daily Tracker'!$E4:$FA4,1,MATCH(Z$16,'Daily Tracker'!$E$2:$FA$2,0)),0)) -> 19 | AA18: =IF(AA$16="","",IFERROR(INDEX('Daily Tracker'!$E4:$FA4,1,MATCH(AA$16,'Daily Tracker'!$E$2:$FA$2,0)),0)) -> 9 | AB18: =IF(AB$16="","",IFERROR(INDEX('Daily Tracker'!$E4:$FA4,1,MATCH(AB$16,'Daily Tracker'!$E$2:$FA$2,0)),0)) -> 19 | AC18: =IF(AC$16="","",IFERROR(INDEX('Daily Tracker'!$E4:$FA4,1,MATCH(AC$16,'Daily Tracker'!$E$2:$FA$2,0)),0)) -> 17 | AD18: =IF(AD$16="","",IFERROR(INDEX('Daily Tracker'!$E4:$FA4,1,MATCH(AD$16,'Daily Tracker'!$E$2:$FA$2,0)),0)) -> 16 | ... AJ18: =IF(AJ$16="","",IFERROR(INDEX('Daily Tracker'!$E4:$FA4,1,MATCH(AJ$16,'Daily Tracker'!$E$2:$FA$2,0)),0)) -> 21 | FZ18: Total C6 Night MP
A19: Production | B19: =IF('Daily Tracker'!B5="",A19,'Daily Tracker'!B5) -> C39 | C19: ='Daily Tracker'!C5 -> C39 - MG batch Making | D19: ='Daily Tracker'!D5 -> 7 | E19: =IFERROR(INDEX('Daily Tracker'!$E5:$FA5,1,MATCH($B$4,'Daily Tracker'!$E$2:$FA$2,0)),0) -> 8 | F19: =D19-E19 -> -1 | G19: =IFERROR(E19/D19,0) -> 1.1428571 | V19: 5 | W19: =IF(W$16="","",IFERROR(INDEX('Daily Tracker'!$E5:$FA5,1,MATCH(W$16,'Daily Tracker'!$E$2:$FA$2,0)),0)) -> 9 | X19: =IF(X$16="","",IFERROR(INDEX('Daily Tracker'!$E5:$FA5,1,MATCH(X$16,'Daily Tracker'!$E$2:$FA$2,0)),0)) -> 9 | Y19: =IF(Y$16="","",IFERROR(INDEX('Daily Tracker'!$E5:$FA5,1,MATCH(Y$16,'Daily Tracker'!$E$2:$FA$2,0)),0)) -> 0 | Z19: =IF(Z$16="","",IFERROR(INDEX('Daily Tracker'!$E5:$FA5,1,MATCH(Z$16,'Daily Tracker'!$E$2:$FA$2,0)),0)) -> 9 | AA19: =IF(AA$16="","",IFERROR(INDEX('Daily Tracker'!$E5:$FA5,1,MATCH(AA$16,'Daily Tracker'!$E$2:$FA$2,0)),0)) -> 2 | AB19: =IF(AB$16="","",IFERROR(INDEX('Daily Tracker'!$E5:$FA5,1,MATCH(AB$16,'Daily Tracker'!$E$2:$FA$2,0)),0)) -> 10 | AC19: =IF(AC$16="","",IFERROR(INDEX('Daily Tracker'!$E5:$FA5,1,MATCH(AC$16,'Daily Tracker'!$E$2:$FA$2,0)),0)) -> 6 | AD19: =IF(AD$16="","",IFERROR(INDEX('Daily Tracker'!$E5:$FA5,1,MATCH(AD$16,'Daily Tracker'!$E$2:$FA$2,0)),0)) -> 9 | ... AJ19: =IF(AJ$16="","",IFERROR(INDEX('Daily Tracker'!$E5:$FA5,1,MATCH(AJ$16,'Daily Tracker'!$E$2:$FA$2,0)),0)) -> 8 | FZ19: Total C39 Night MP
A20: Production | B20: =IF('Daily Tracker'!B6="",A20,'Daily Tracker'!B6) -> Supply | C20: ='Daily Tracker'!C6 -> Supply/ Dispatch (Common) | D20: ='Daily Tracker'!D6 -> 11 | E20: =IFERROR(INDEX('Daily Tracker'!$E6:$FA6,1,MATCH($B$4,'Daily Tracker'!$E$2:$FA$2,0)),0) -> 6 | F20: =D20-E20 -> 5 | G20: =IFERROR(E20/D20,0) -> 0.54545455 | V20: 6 | W20: =IF(W$16="","",IFERROR(INDEX('Daily Tracker'!$E6:$FA6,1,MATCH(W$16,'Daily Tracker'!$E$2:$FA$2,0)),0)) -> 12 | X20: =IF(X$16="","",IFERROR(INDEX('Daily Tracker'!$E6:$FA6,1,MATCH(X$16,'Daily Tracker'!$E$2:$FA$2,0)),0)) -> 11 | Y20: =IF(Y$16="","",IFERROR(INDEX('Daily Tracker'!$E6:$FA6,1,MATCH(Y$16,'Daily Tracker'!$E$2:$FA$2,0)),0)) -> 0 | Z20: =IF(Z$16="","",IFERROR(INDEX('Daily Tracker'!$E6:$FA6,1,MATCH(Z$16,'Daily Tracker'!$E$2:$FA$2,0)),0)) -> 6 | AA20: =IF(AA$16="","",IFERROR(INDEX('Daily Tracker'!$E6:$FA6,1,MATCH(AA$16,'Daily Tracker'!$E$2:$FA$2,0)),0)) -> 6 | AB20: =IF(AB$16="","",IFERROR(INDEX('Daily Tracker'!$E6:$FA6,1,MATCH(AB$16,'Daily Tracker'!$E$2:$FA$2,0)),0)) -> 15 | AC20: =IF(AC$16="","",IFERROR(INDEX('Daily Tracker'!$E6:$FA6,1,MATCH(AC$16,'Daily Tracker'!$E$2:$FA$2,0)),0)) -> 15 | AD20: =IF(AD$16="","",IFERROR(INDEX('Daily Tracker'!$E6:$FA6,1,MATCH(AD$16,'Daily Tracker'!$E$2:$FA$2,0)),0)) -> 15 | ... AJ20: =IF(AJ$16="","",IFERROR(INDEX('Daily Tracker'!$E6:$FA6,1,MATCH(AJ$16,'Daily Tracker'!$E$2:$FA$2,0)),0)) -> 6 | FZ20: Supervisors + Executive+AM +HR
A21: Production | B21: =IF('Daily Tracker'!B7="",A21,'Daily Tracker'!B7) -> Printer | C21: ='Daily Tracker'!C7 -> Printer (Common) | D21: ='Daily Tracker'!D7 -> 6 | E21: =IFERROR(INDEX('Daily Tracker'!$E7:$FA7,1,MATCH($B$4,'Daily Tracker'!$E$2:$FA$2,0)),0) -> 8 | F21: =D21-E21 -> -2 | G21: =IFERROR(E21/D21,0) -> 1.3333333 | V21: 7 | W21: =IF(W$16="","",IFERROR(INDEX('Daily Tracker'!$E7:$FA7,1,MATCH(W$16,'Daily Tracker'!$E$2:$FA$2,0)),0)) -> 7 | X21: =IF(X$16="","",IFERROR(INDEX('Daily Tracker'!$E7:$FA7,1,MATCH(X$16,'Daily Tracker'!$E$2:$FA$2,0)),0)) -> 8 | Y21: =IF(Y$16="","",IFERROR(INDEX('Daily Tracker'!$E7:$FA7,1,MATCH(Y$16,'Daily Tracker'!$E$2:$FA$2,0)),0)) -> 0 | Z21: =IF(Z$16="","",IFERROR(INDEX('Daily Tracker'!$E7:$FA7,1,MATCH(Z$16,'Daily Tracker'!$E$2:$FA$2,0)),0)) -> 7 | AA21: =IF(AA$16="","",IFERROR(INDEX('Daily Tracker'!$E7:$FA7,1,MATCH(AA$16,'Daily Tracker'!$E$2:$FA$2,0)),0)) -> 3 | AB21: =IF(AB$16="","",IFERROR(INDEX('Daily Tracker'!$E7:$FA7,1,MATCH(AB$16,'Daily Tracker'!$E$2:$FA$2,0)),0)) -> 6 | AC21: =IF(AC$16="","",IFERROR(INDEX('Daily Tracker'!$E7:$FA7,1,MATCH(AC$16,'Daily Tracker'!$E$2:$FA$2,0)),0)) -> 6 | AD21: =IF(AD$16="","",IFERROR(INDEX('Daily Tracker'!$E7:$FA7,1,MATCH(AD$16,'Daily Tracker'!$E$2:$FA$2,0)),0)) -> 5 | ... AJ21: =IF(AJ$16="","",IFERROR(INDEX('Daily Tracker'!$E7:$FA7,1,MATCH(AJ$16,'Daily Tracker'!$E$2:$FA$2,0)),0)) -> 8 | FZ21: C39-HK
A22: Production | B22: =IF('Daily Tracker'!B8="",A22,'Daily Tracker'!B8) -> C6 | C22: ='Daily Tracker'!C8 -> C6 - Raw Agri (Millets) | D22: ='Daily Tracker'!D8 -> 16 | E22: =IFERROR(INDEX('Daily Tracker'!$E8:$FA8,1,MATCH($B$4,'Daily Tracker'!$E$2:$FA$2,0)),0) -> 22 | F22: =D22-E22 -> -6 | G22: =IFERROR(E22/D22,0) -> 1.375 | V22: 8 | W22: =IF(W$16="","",IFERROR(INDEX('Daily Tracker'!$E8:$FA8,1,MATCH(W$16,'Daily Tracker'!$E$2:$FA$2,0)),0)) -> 18 | X22: =IF(X$16="","",IFERROR(INDEX('Daily Tracker'!$E8:$FA8,1,MATCH(X$16,'Daily Tracker'!$E$2:$FA$2,0)),0)) -> 19 | Y22: =IF(Y$16="","",IFERROR(INDEX('Daily Tracker'!$E8:$FA8,1,MATCH(Y$16,'Daily Tracker'!$E$2:$FA$2,0)),0)) -> 0 | Z22: =IF(Z$16="","",IFERROR(INDEX('Daily Tracker'!$E8:$FA8,1,MATCH(Z$16,'Daily Tracker'!$E$2:$FA$2,0)),0)) -> 23 | AA22: =IF(AA$16="","",IFERROR(INDEX('Daily Tracker'!$E8:$FA8,1,MATCH(AA$16,'Daily Tracker'!$E$2:$FA$2,0)),0)) -> 0 | AB22: =IF(AB$16="","",IFERROR(INDEX('Daily Tracker'!$E8:$FA8,1,MATCH(AB$16,'Daily Tracker'!$E$2:$FA$2,0)),0)) -> 18 | AC22: =IF(AC$16="","",IFERROR(INDEX('Daily Tracker'!$E8:$FA8,1,MATCH(AC$16,'Daily Tracker'!$E$2:$FA$2,0)),0)) -> 18 | AD22: =IF(AD$16="","",IFERROR(INDEX('Daily Tracker'!$E8:$FA8,1,MATCH(AD$16,'Daily Tracker'!$E$2:$FA$2,0)),0)) -> 15 | ... AJ22: =IF(AJ$16="","",IFERROR(INDEX('Daily Tracker'!$E8:$FA8,1,MATCH(AJ$16,'Daily Tracker'!$E$2:$FA$2,0)),0)) -> 22 | FZ22: C6-HK
A23: Production | B23: =IF('Daily Tracker'!B9="",A23,'Daily Tracker'!B9) -> C39 | C23: ='Daily Tracker'!C9 -> C39 - Honey / all Spices | D23: ='Daily Tracker'!D9 -> 22 | E23: =IFERROR(INDEX('Daily Tracker'!$E9:$FA9,1,MATCH($B$4,'Daily Tracker'!$E$2:$FA$2,0)),0) -> 18 | F23: =D23-E23 -> 4 | G23: =IFERROR(E23/D23,0) -> 0.81818182 | V23: 9 | W23: =IF(W$16="","",IFERROR(INDEX('Daily Tracker'!$E9:$FA9,1,MATCH(W$16,'Daily Tracker'!$E$2:$FA$2,0)),0)) -> 15 | X23: =IF(X$16="","",IFERROR(INDEX('Daily Tracker'!$E9:$FA9,1,MATCH(X$16,'Daily Tracker'!$E$2:$FA$2,0)),0)) -> 19 | Y23: =IF(Y$16="","",IFERROR(INDEX('Daily Tracker'!$E9:$FA9,1,MATCH(Y$16,'Daily Tracker'!$E$2:$FA$2,0)),0)) -> 0 | Z23: =IF(Z$16="","",IFERROR(INDEX('Daily Tracker'!$E9:$FA9,1,MATCH(Z$16,'Daily Tracker'!$E$2:$FA$2,0)),0)) -> 18 | AA23: =IF(AA$16="","",IFERROR(INDEX('Daily Tracker'!$E9:$FA9,1,MATCH(AA$16,'Daily Tracker'!$E$2:$FA$2,0)),0)) -> 0 | AB23: =IF(AB$16="","",IFERROR(INDEX('Daily Tracker'!$E9:$FA9,1,MATCH(AB$16,'Daily Tracker'!$E$2:$FA$2,0)),0)) -> 15 | AC23: =IF(AC$16="","",IFERROR(INDEX('Daily Tracker'!$E9:$FA9,1,MATCH(AC$16,'Daily Tracker'!$E$2:$FA$2,0)),0)) -> 11 | AD23: =IF(AD$16="","",IFERROR(INDEX('Daily Tracker'!$E9:$FA9,1,MATCH(AD$16,'Daily Tracker'!$E$2:$FA$2,0)),0)) -> 16 | ... AJ23: =IF(AJ$16="","",IFERROR(INDEX('Daily Tracker'!$E9:$FA9,1,MATCH(AJ$16,'Daily Tracker'!$E$2:$FA$2,0)),0)) -> 18 | FZ23: Maintenance-C6&C39
A24: Production | B24: =IF('Daily Tracker'!B10="",A24,'Daily Tracker'!B10) -> C39 | C24: ='Daily Tracker'!C10 -> C39 - Jaggery | D24: ='Daily Tracker'!D10 -> 9 | E24: =IFERROR(INDEX('Daily Tracker'!$E10:$FA10,1,MATCH($B$4,'Daily Tracker'!$E$2:$FA$2,0)),0) -> 19 | F24: =D24-E24 -> -10 | G24: =IFERROR(E24/D24,0) -> 2.1111111 | V24: 10 | W24: =IF(W$16="","",IFERROR(INDEX('Daily Tracker'!$E10:$FA10,1,MATCH(W$16,'Daily Tracker'!$E$2:$FA$2,0)),0)) -> 20 | X24: =IF(X$16="","",IFERROR(INDEX('Daily Tracker'!$E10:$FA10,1,MATCH(X$16,'Daily Tracker'!$E$2:$FA$2,0)),0)) -> 14 | Y24: =IF(Y$16="","",IFERROR(INDEX('Daily Tracker'!$E10:$FA10,1,MATCH(Y$16,'Daily Tracker'!$E$2:$FA$2,0)),0)) -> 0 | Z24: =IF(Z$16="","",IFERROR(INDEX('Daily Tracker'!$E10:$FA10,1,MATCH(Z$16,'Daily Tracker'!$E$2:$FA$2,0)),0)) -> 15 | AA24: =IF(AA$16="","",IFERROR(INDEX('Daily Tracker'!$E10:$FA10,1,MATCH(AA$16,'Daily Tracker'!$E$2:$FA$2,0)),0)) -> 15 | AB24: =IF(AB$16="","",IFERROR(INDEX('Daily Tracker'!$E10:$FA10,1,MATCH(AB$16,'Daily Tracker'!$E$2:$FA$2,0)),0)) -> 17 | AC24: =IF(AC$16="","",IFERROR(INDEX('Daily Tracker'!$E10:$FA10,1,MATCH(AC$16,'Daily Tracker'!$E$2:$FA$2,0)),0)) -> 16 | AD24: =IF(AD$16="","",IFERROR(INDEX('Daily Tracker'!$E10:$FA10,1,MATCH(AD$16,'Daily Tracker'!$E$2:$FA$2,0)),0)) -> 15 | ... AJ24: =IF(AJ$16="","",IFERROR(INDEX('Daily Tracker'!$E10:$FA10,1,MATCH(AJ$16,'Daily Tracker'!$E$2:$FA$2,0)),0)) -> 19 | FZ24: Admin
A25: Production | B25: =IF('Daily Tracker'!B11="",A25,'Daily Tracker'!B11) -> C39 | C25: ='Daily Tracker'!C11 -> C39 - Atta | D25: ='Daily Tracker'!D11 -> 22 | E25: =IFERROR(INDEX('Daily Tracker'!$E11:$FA11,1,MATCH($B$4,'Daily Tracker'!$E$2:$FA$2,0)),0) -> 9 | F25: =D25-E25 -> 13 | G25: =IFERROR(E25/D25,0) -> 0.40909091 | V25: 11 | W25: =IF(W$16="","",IFERROR(INDEX('Daily Tracker'!$E11:$FA11,1,MATCH(W$16,'Daily Tracker'!$E$2:$FA$2,0)),0)) -> 11 | X25: =IF(X$16="","",IFERROR(INDEX('Daily Tracker'!$E11:$FA11,1,MATCH(X$16,'Daily Tracker'!$E$2:$FA$2,0)),0)) -> 13 | Y25: =IF(Y$16="","",IFERROR(INDEX('Daily Tracker'!$E11:$FA11,1,MATCH(Y$16,'Daily Tracker'!$E$2:$FA$2,0)),0)) -> 0 | Z25: =IF(Z$16="","",IFERROR(INDEX('Daily Tracker'!$E11:$FA11,1,MATCH(Z$16,'Daily Tracker'!$E$2:$FA$2,0)),0)) -> 14 | AA25: =IF(AA$16="","",IFERROR(INDEX('Daily Tracker'!$E11:$FA11,1,MATCH(AA$16,'Daily Tracker'!$E$2:$FA$2,0)),0)) -> 13 | AB25: =IF(AB$16="","",IFERROR(INDEX('Daily Tracker'!$E11:$FA11,1,MATCH(AB$16,'Daily Tracker'!$E$2:$FA$2,0)),0)) -> 10 | AC25: =IF(AC$16="","",IFERROR(INDEX('Daily Tracker'!$E11:$FA11,1,MATCH(AC$16,'Daily Tracker'!$E$2:$FA$2,0)),0)) -> 17 | AD25: =IF(AD$16="","",IFERROR(INDEX('Daily Tracker'!$E11:$FA11,1,MATCH(AD$16,'Daily Tracker'!$E$2:$FA$2,0)),0)) -> 10 | ... AJ25: =IF(AJ$16="","",IFERROR(INDEX('Daily Tracker'!$E11:$FA11,1,MATCH(AJ$16,'Daily Tracker'!$E$2:$FA$2,0)),0)) -> 9 | FZ25: Lab
A26: Production | B26: =IF('Daily Tracker'!B12="",A26,'Daily Tracker'!B12) -> C6 | C26: ='Daily Tracker'!C12 -> C6 - Atta - 1 | D26: ='Daily Tracker'!D12 -> 14 | E26: =IFERROR(INDEX('Daily Tracker'!$E12:$FA12,1,MATCH($B$4,'Daily Tracker'!$E$2:$FA$2,0)),0) -> 16 | F26: =D26-E26 -> -2 | G26: =IFERROR(E26/D26,0) -> 1.1428571 | V26: 12 | W26: =IF(W$16="","",IFERROR(INDEX('Daily Tracker'!$E12:$FA12,1,MATCH(W$16,'Daily Tracker'!$E$2:$FA$2,0)),0)) -> 16 | X26: =IF(X$16="","",IFERROR(INDEX('Daily Tracker'!$E12:$FA12,1,MATCH(X$16,'Daily Tracker'!$E$2:$FA$2,0)),0)) -> 17 | Y26: =IF(Y$16="","",IFERROR(INDEX('Daily Tracker'!$E12:$FA12,1,MATCH(Y$16,'Daily Tracker'!$E$2:$FA$2,0)),0)) -> 0 | Z26: =IF(Z$16="","",IFERROR(INDEX('Daily Tracker'!$E12:$FA12,1,MATCH(Z$16,'Daily Tracker'!$E$2:$FA$2,0)),0)) -> 16 | AA26: =IF(AA$16="","",IFERROR(INDEX('Daily Tracker'!$E12:$FA12,1,MATCH(AA$16,'Daily Tracker'!$E$2:$FA$2,0)),0)) -> 0 | AB26: =IF(AB$16="","",IFERROR(INDEX('Daily Tracker'!$E12:$FA12,1,MATCH(AB$16,'Daily Tracker'!$E$2:$FA$2,0)),0)) -> 17 | AC26: =IF(AC$16="","",IFERROR(INDEX('Daily Tracker'!$E12:$FA12,1,MATCH(AC$16,'Daily Tracker'!$E$2:$FA$2,0)),0)) -> 16 | AD26: =IF(AD$16="","",IFERROR(INDEX('Daily Tracker'!$E12:$FA12,1,MATCH(AD$16,'Daily Tracker'!$E$2:$FA$2,0)),0)) -> 16 | ... AJ26: =IF(AJ$16="","",IFERROR(INDEX('Daily Tracker'!$E12:$FA12,1,MATCH(AJ$16,'Daily Tracker'!$E$2:$FA$2,0)),0)) -> 16 | FZ26: Project
A27: Production | B27: =IF('Daily Tracker'!B13="",A27,'Daily Tracker'!B13) -> C6 | C27: ='Daily Tracker'!C13 -> C6 Atta - 2 | D27: ='Daily Tracker'!D13 -> 11 | E27: =IFERROR(INDEX('Daily Tracker'!$E13:$FA13,1,MATCH($B$4,'Daily Tracker'!$E$2:$FA$2,0)),0) -> 5 | F27: =D27-E27 -> 6 | G27: =IFERROR(E27/D27,0) -> 0.45454545 | V27: 13 | W27: =IF(W$16="","",IFERROR(INDEX('Daily Tracker'!$E13:$FA13,1,MATCH(W$16,'Daily Tracker'!$E$2:$FA$2,0)),0)) -> 5 | X27: =IF(X$16="","",IFERROR(INDEX('Daily Tracker'!$E13:$FA13,1,MATCH(X$16,'Daily Tracker'!$E$2:$FA$2,0)),0)) -> 4 | Y27: =IF(Y$16="","",IFERROR(INDEX('Daily Tracker'!$E13:$FA13,1,MATCH(Y$16,'Daily Tracker'!$E$2:$FA$2,0)),0)) -> 0 | Z27: =IF(Z$16="","",IFERROR(INDEX('Daily Tracker'!$E13:$FA13,1,MATCH(Z$16,'Daily Tracker'!$E$2:$FA$2,0)),0)) -> 5 | AA27: =IF(AA$16="","",IFERROR(INDEX('Daily Tracker'!$E13:$FA13,1,MATCH(AA$16,'Daily Tracker'!$E$2:$FA$2,0)),0)) -> 0 | AB27: =IF(AB$16="","",IFERROR(INDEX('Daily Tracker'!$E13:$FA13,1,MATCH(AB$16,'Daily Tracker'!$E$2:$FA$2,0)),0)) -> 4 | AC27: =IF(AC$16="","",IFERROR(INDEX('Daily Tracker'!$E13:$FA13,1,MATCH(AC$16,'Daily Tracker'!$E$2:$FA$2,0)),0)) -> 4 | AD27: =IF(AD$16="","",IFERROR(INDEX('Daily Tracker'!$E13:$FA13,1,MATCH(AD$16,'Daily Tracker'!$E$2:$FA$2,0)),0)) -> 4 | ... AJ27: =IF(AJ$16="","",IFERROR(INDEX('Daily Tracker'!$E13:$FA13,1,MATCH(AJ$16,'Daily Tracker'!$E$2:$FA$2,0)),0)) -> 5 | FZ27: Accounts
A28: Production | B28: =IF('Daily Tracker'!B14="",A28,'Daily Tracker'!B14) -> FRM | C28: ='Daily Tracker'!C14 -> FRM - Khapal-Khapli | D28: ='Daily Tracker'!D14 -> 0 | E28: =IFERROR(INDEX('Daily Tracker'!$E14:$FA14,1,MATCH($B$4,'Daily Tracker'!$E$2:$FA$2,0)),0) -> 0 | F28: =D28-E28 -> 0 | G28: =IFERROR(E28/D28,0) -> 0 | V28: 14 | W28: =IF(W$16="","",IFERROR(INDEX('Daily Tracker'!$E14:$FA14,1,MATCH(W$16,'Daily Tracker'!$E$2:$FA$2,0)),0)) -> 0 | X28: =IF(X$16="","",IFERROR(INDEX('Daily Tracker'!$E14:$FA14,1,MATCH(X$16,'Daily Tracker'!$E$2:$FA$2,0)),0)) -> 0 | Y28: =IF(Y$16="","",IFERROR(INDEX('Daily Tracker'!$E14:$FA14,1,MATCH(Y$16,'Daily Tracker'!$E$2:$FA$2,0)),0)) -> 0 | Z28: =IF(Z$16="","",IFERROR(INDEX('Daily Tracker'!$E14:$FA14,1,MATCH(Z$16,'Daily Tracker'!$E$2:$FA$2,0)),0)) -> 0 | AA28: =IF(AA$16="","",IFERROR(INDEX('Daily Tracker'!$E14:$FA14,1,MATCH(AA$16,'Daily Tracker'!$E$2:$FA$2,0)),0)) -> 0 | AB28: =IF(AB$16="","",IFERROR(INDEX('Daily Tracker'!$E14:$FA14,1,MATCH(AB$16,'Daily Tracker'!$E$2:$FA$2,0)),0)) -> 0 | AC28: =IF(AC$16="","",IFERROR(INDEX('Daily Tracker'!$E14:$FA14,1,MATCH(AC$16,'Daily Tracker'!$E$2:$FA$2,0)),0)) -> 0 | AD28: =IF(AD$16="","",IFERROR(INDEX('Daily Tracker'!$E14:$FA14,1,MATCH(AD$16,'Daily Tracker'!$E$2:$FA$2,0)),0)) -> 0 | ... AJ28: =IF(AJ$16="","",IFERROR(INDEX('Daily Tracker'!$E14:$FA14,1,MATCH(AJ$16,'Daily Tracker'!$E$2:$FA$2,0)),0)) -> 0 | FZ28: IT
... A30: Production | B30: =IF('Daily Tracker'!B16="",A30,'Daily Tracker'!B16) -> Ghee | C30: ='Daily Tracker'!C16 -> Night MP Total Ghee | D30: ='Daily Tracker'!D16 -> 5 | E30: =IFERROR(INDEX('Daily Tracker'!$E16:$FA16,1,MATCH($B$4,'Daily Tracker'!$E$2:$FA$2,0)),0) -> 0 | F30: =D30-E30 -> 5 | G30: =IFERROR(E30/D30,0) -> 0 | V30: 16 | W30: =IF(W$16="","",IFERROR(INDEX('Daily Tracker'!$E16:$FA16,1,MATCH(W$16,'Daily Tracker'!$E$2:$FA$2,0)),0)) -> 17 | X30: =IF(X$16="","",IFERROR(INDEX('Daily Tracker'!$E16:$FA16,1,MATCH(X$16,'Daily Tracker'!$E$2:$FA$2,0)),0)) -> 15 | Y30: =IF(Y$16="","",IFERROR(INDEX('Daily Tracker'!$E16:$FA16,1,MATCH(Y$16,'Daily Tracker'!$E$2:$FA$2,0)),0)) -> 0 | Z30: =IF(Z$16="","",IFERROR(INDEX('Daily Tracker'!$E16:$FA16,1,MATCH(Z$16,'Daily Tracker'!$E$2:$FA$2,0)),0)) -> 11 | AA30: =IF(AA$16="","",IFERROR(INDEX('Daily Tracker'!$E16:$FA16,1,MATCH(AA$16,'Daily Tracker'!$E$2:$FA$2,0)),0)) -> 11 | AB30: =IF(AB$16="","",IFERROR(INDEX('Daily Tracker'!$E16:$FA16,1,MATCH(AB$16,'Daily Tracker'!$E$2:$FA$2,0)),0)) -> 11 | AC30: =IF(AC$16="","",IFERROR(INDEX('Daily Tracker'!$E16:$FA16,1,MATCH(AC$16,'Daily Tracker'!$E$2:$FA$2,0)),0)) -> 16 | AD30: =IF(AD$16="","",IFERROR(INDEX('Daily Tracker'!$E16:$FA16,1,MATCH(AD$16,'Daily Tracker'!$E$2:$FA$2,0)),0)) -> 16 | ... AJ30: =IF(AJ$16="","",IFERROR(INDEX('Daily Tracker'!$E16:$FA16,1,MATCH(AJ$16,'Daily Tracker'!$E$2:$FA$2,0)),0)) -> 0 | FZ30: FRM
A31: Production | B31: =IF('Daily Tracker'!B17="",A31,'Daily Tracker'!B17) -> C6 | C31: ='Daily Tracker'!C17 -> Total C6 Night MP | D31: ='Daily Tracker'!D17 -> 7 | E31: =IFERROR(INDEX('Daily Tracker'!$E17:$FA17,1,MATCH($B$4,'Daily Tracker'!$E$2:$FA$2,0)),0) -> 5 | F31: =D31-E31 -> 2 | G31: =IFERROR(E31/D31,0) -> 0.71428571 | V31: 17 | W31: =IF(W$16="","",IFERROR(INDEX('Daily Tracker'!$E17:$FA17,1,MATCH(W$16,'Daily Tracker'!$E$2:$FA$2,0)),0)) -> 3 | X31: =IF(X$16="","",IFERROR(INDEX('Daily Tracker'!$E17:$FA17,1,MATCH(X$16,'Daily Tracker'!$E$2:$FA$2,0)),0)) -> 5 | Y31: =IF(Y$16="","",IFERROR(INDEX('Daily Tracker'!$E17:$FA17,1,MATCH(Y$16,'Daily Tracker'!$E$2:$FA$2,0)),0)) -> 0 | Z31: =IF(Z$16="","",IFERROR(INDEX('Daily Tracker'!$E17:$FA17,1,MATCH(Z$16,'Daily Tracker'!$E$2:$FA$2,0)),0)) -> 0 | AA31: =IF(AA$16="","",IFERROR(INDEX('Daily Tracker'!$E17:$FA17,1,MATCH(AA$16,'Daily Tracker'!$E$2:$FA$2,0)),0)) -> 7 | AB31: =IF(AB$16="","",IFERROR(INDEX('Daily Tracker'!$E17:$FA17,1,MATCH(AB$16,'Daily Tracker'!$E$2:$FA$2,0)),0)) -> 0 | AC31: =IF(AC$16="","",IFERROR(INDEX('Daily Tracker'!$E17:$FA17,1,MATCH(AC$16,'Daily Tracker'!$E$2:$FA$2,0)),0)) -> 6 | AD31: =IF(AD$16="","",IFERROR(INDEX('Daily Tracker'!$E17:$FA17,1,MATCH(AD$16,'Daily Tracker'!$E$2:$FA$2,0)),0)) -> 9 | ... AJ31: =IF(AJ$16="","",IFERROR(INDEX('Daily Tracker'!$E17:$FA17,1,MATCH(AJ$16,'Daily Tracker'!$E$2:$FA$2,0)),0)) -> 5
A32: Production | B32: =IF('Daily Tracker'!B18="",A32,'Daily Tracker'!B18) -> C39 | C32: ='Daily Tracker'!C18 -> Total C39 Night MP | D32: ='Daily Tracker'!D18 -> 21 | E32: =IFERROR(INDEX('Daily Tracker'!$E18:$FA18,1,MATCH($B$4,'Daily Tracker'!$E$2:$FA$2,0)),0) -> 22 | F32: =D32-E32 -> -1 | G32: =IFERROR(E32/D32,0) -> 1.047619 | V32: 18 | W32: =IF(W$16="","",IFERROR(INDEX('Daily Tracker'!$E18:$FA18,1,MATCH(W$16,'Daily Tracker'!$E$2:$FA$2,0)),0)) -> 15 | X32: =IF(X$16="","",IFERROR(INDEX('Daily Tracker'!$E18:$FA18,1,MATCH(X$16,'Daily Tracker'!$E$2:$FA$2,0)),0)) -> 16 | Y32: =IF(Y$16="","",IFERROR(INDEX('Daily Tracker'!$E18:$FA18,1,MATCH(Y$16,'Daily Tracker'!$E$2:$FA$2,0)),0)) -> 0 | Z32: =IF(Z$16="","",IFERROR(INDEX('Daily Tracker'!$E18:$FA18,1,MATCH(Z$16,'Daily Tracker'!$E$2:$FA$2,0)),0)) -> 0 | AA32: =IF(AA$16="","",IFERROR(INDEX('Daily Tracker'!$E18:$FA18,1,MATCH(AA$16,'Daily Tracker'!$E$2:$FA$2,0)),0)) -> 22 | AB32: =IF(AB$16="","",IFERROR(INDEX('Daily Tracker'!$E18:$FA18,1,MATCH(AB$16,'Daily Tracker'!$E$2:$FA$2,0)),0)) -> 0 | AC32: =IF(AC$16="","",IFERROR(INDEX('Daily Tracker'!$E18:$FA18,1,MATCH(AC$16,'Daily Tracker'!$E$2:$FA$2,0)),0)) -> 24 | AD32: =IF(AD$16="","",IFERROR(INDEX('Daily Tracker'!$E18:$FA18,1,MATCH(AD$16,'Daily Tracker'!$E$2:$FA$2,0)),0)) -> 21 | ... AJ32: =IF(AJ$16="","",IFERROR(INDEX('Daily Tracker'!$E18:$FA18,1,MATCH(AJ$16,'Daily Tracker'!$E$2:$FA$2,0)),0)) -> 22
A33: Support | B33: =IF('Daily Tracker'!B20="",A33,'Daily Tracker'!B20) -> Support | C33: ='Daily Tracker'!C20 -> Supervisors + Executive+AM +HR | D33: ='Daily Tracker'!D20 -> 21 | E33: =IFERROR(INDEX('Daily Tracker'!$E20:$FA20,1,MATCH($B$4,'Daily Tracker'!$E$2:$FA$2,0)),0) -> 13 | F33: =D33-E33 -> 8 | G33: =IFERROR(E33/D33,0) -> 0.61904762 | V33: 20 | W33: =IF(W$16="","",IFERROR(INDEX('Daily Tracker'!$E20:$FA20,1,MATCH(W$16,'Daily Tracker'!$E$2:$FA$2,0)),0)) -> 11 | X33: =IF(X$16="","",IFERROR(INDEX('Daily Tracker'!$E20:$FA20,1,MATCH(X$16,'Daily Tracker'!$E$2:$FA$2,0)),0)) -> 11 | Y33: =IF(Y$16="","",IFERROR(INDEX('Daily Tracker'!$E20:$FA20,1,MATCH(Y$16,'Daily Tracker'!$E$2:$FA$2,0)),0)) -> 0 | Z33: =IF(Z$16="","",IFERROR(INDEX('Daily Tracker'!$E20:$FA20,1,MATCH(Z$16,'Daily Tracker'!$E$2:$FA$2,0)),0)) -> 8 | AA33: =IF(AA$16="","",IFERROR(INDEX('Daily Tracker'!$E20:$FA20,1,MATCH(AA$16,'Daily Tracker'!$E$2:$FA$2,0)),0)) -> 0 | AB33: =IF(AB$16="","",IFERROR(INDEX('Daily Tracker'!$E20:$FA20,1,MATCH(AB$16,'Daily Tracker'!$E$2:$FA$2,0)),0)) -> 10 | AC33: =IF(AC$16="","",IFERROR(INDEX('Daily Tracker'!$E20:$FA20,1,MATCH(AC$16,'Daily Tracker'!$E$2:$FA$2,0)),0)) -> 11 | AD33: =IF(AD$16="","",IFERROR(INDEX('Daily Tracker'!$E20:$FA20,1,MATCH(AD$16,'Daily Tracker'!$E$2:$FA$2,0)),0)) -> 11 | ... AJ33: =IF(AJ$16="","",IFERROR(INDEX('Daily Tracker'!$E20:$FA20,1,MATCH(AJ$16,'Daily Tracker'!$E$2:$FA$2,0)),0)) -> 13
A34: Support | B34: =IF('Daily Tracker'!B21="",A34,'Daily Tracker'!B21) -> Support | C34: ='Daily Tracker'!C21 -> C39-HK | D34: ='Daily Tracker'!D21 -> 5 | E34: =IFERROR(INDEX('Daily Tracker'!$E21:$FA21,1,MATCH($B$4,'Daily Tracker'!$E$2:$FA$2,0)),0) -> 5 | F34: =D34-E34 -> 0 | G34: =IFERROR(E34/D34,0) -> 1 | V34: 21 | W34: =IF(W$16="","",IFERROR(INDEX('Daily Tracker'!$E21:$FA21,1,MATCH(W$16,'Daily Tracker'!$E$2:$FA$2,0)),0)) -> 5 | X34: =IF(X$16="","",IFERROR(INDEX('Daily Tracker'!$E21:$FA21,1,MATCH(X$16,'Daily Tracker'!$E$2:$FA$2,0)),0)) -> 4 | Y34: =IF(Y$16="","",IFERROR(INDEX('Daily Tracker'!$E21:$FA21,1,MATCH(Y$16,'Daily Tracker'!$E$2:$FA$2,0)),0)) -> 0 | Z34: =IF(Z$16="","",IFERROR(INDEX('Daily Tracker'!$E21:$FA21,1,MATCH(Z$16,'Daily Tracker'!$E$2:$FA$2,0)),0)) -> 5 | AA34: =IF(AA$16="","",IFERROR(INDEX('Daily Tracker'!$E21:$FA21,1,MATCH(AA$16,'Daily Tracker'!$E$2:$FA$2,0)),0)) -> 3 | AB34: =IF(AB$16="","",IFERROR(INDEX('Daily Tracker'!$E21:$FA21,1,MATCH(AB$16,'Daily Tracker'!$E$2:$FA$2,0)),0)) -> 6 | AC34: =IF(AC$16="","",IFERROR(INDEX('Daily Tracker'!$E21:$FA21,1,MATCH(AC$16,'Daily Tracker'!$E$2:$FA$2,0)),0)) -> 4 | AD34: =IF(AD$16="","",IFERROR(INDEX('Daily Tracker'!$E21:$FA21,1,MATCH(AD$16,'Daily Tracker'!$E$2:$FA$2,0)),0)) -> 5 | ... AJ34: =IF(AJ$16="","",IFERROR(INDEX('Daily Tracker'!$E21:$FA21,1,MATCH(AJ$16,'Daily Tracker'!$E$2:$FA$2,0)),0)) -> 5
A35: Support | B35: =IF('Daily Tracker'!B22="",A35,'Daily Tracker'!B22) -> Support | C35: ='Daily Tracker'!C22 -> C6-HK | D35: ='Daily Tracker'!D22 -> 9 | E35: =IFERROR(INDEX('Daily Tracker'!$E22:$FA22,1,MATCH($B$4,'Daily Tracker'!$E$2:$FA$2,0)),0) -> 9 | F35: =D35-E35 -> 0 | G35: =IFERROR(E35/D35,0) -> 1 | V35: 22 | W35: =IF(W$16="","",IFERROR(INDEX('Daily Tracker'!$E22:$FA22,1,MATCH(W$16,'Daily Tracker'!$E$2:$FA$2,0)),0)) -> 9 | X35: =IF(X$16="","",IFERROR(INDEX('Daily Tracker'!$E22:$FA22,1,MATCH(X$16,'Daily Tracker'!$E$2:$FA$2,0)),0)) -> 9 | Y35: =IF(Y$16="","",IFERROR(INDEX('Daily Tracker'!$E22:$FA22,1,MATCH(Y$16,'Daily Tracker'!$E$2:$FA$2,0)),0)) -> 0 | Z35: =IF(Z$16="","",IFERROR(INDEX('Daily Tracker'!$E22:$FA22,1,MATCH(Z$16,'Daily Tracker'!$E$2:$FA$2,0)),0)) -> 8 | AA35: =IF(AA$16="","",IFERROR(INDEX('Daily Tracker'!$E22:$FA22,1,MATCH(AA$16,'Daily Tracker'!$E$2:$FA$2,0)),0)) -> 6 | AB35: =IF(AB$16="","",IFERROR(INDEX('Daily Tracker'!$E22:$FA22,1,MATCH(AB$16,'Daily Tracker'!$E$2:$FA$2,0)),0)) -> 8 | AC35: =IF(AC$16="","",IFERROR(INDEX('Daily Tracker'!$E22:$FA22,1,MATCH(AC$16,'Daily Tracker'!$E$2:$FA$2,0)),0)) -> 8 | AD35: =IF(AD$16="","",IFERROR(INDEX('Daily Tracker'!$E22:$FA22,1,MATCH(AD$16,'Daily Tracker'!$E$2:$FA$2,0)),0)) -> 8 | ... AJ35: =IF(AJ$16="","",IFERROR(INDEX('Daily Tracker'!$E22:$FA22,1,MATCH(AJ$16,'Daily Tracker'!$E$2:$FA$2,0)),0)) -> 9
A36: Support | B36: =IF('Daily Tracker'!B23="",A36,'Daily Tracker'!B23) -> Support | C36: ='Daily Tracker'!C23 -> Maintenance-C6&C39 | D36: ='Daily Tracker'!D23 -> 6 | E36: =IFERROR(INDEX('Daily Tracker'!$E23:$FA23,1,MATCH($B$4,'Daily Tracker'!$E$2:$FA$2,0)),0) -> 5 | F36: =D36-E36 -> 1 | G36: =IFERROR(E36/D36,0) -> 0.83333333 | V36: 23 | W36: =IF(W$16="","",IFERROR(INDEX('Daily Tracker'!$E23:$FA23,1,MATCH(W$16,'Daily Tracker'!$E$2:$FA$2,0)),0)) -> 4 | X36: =IF(X$16="","",IFERROR(INDEX('Daily Tracker'!$E23:$FA23,1,MATCH(X$16,'Daily Tracker'!$E$2:$FA$2,0)),0)) -> 4 | Y36: =IF(Y$16="","",IFERROR(INDEX('Daily Tracker'!$E23:$FA23,1,MATCH(Y$16,'Daily Tracker'!$E$2:$FA$2,0)),0)) -> 0 | Z36: =IF(Z$16="","",IFERROR(INDEX('Daily Tracker'!$E23:$FA23,1,MATCH(Z$16,'Daily Tracker'!$E$2:$FA$2,0)),0)) -> 5 | AA36: =IF(AA$16="","",IFERROR(INDEX('Daily Tracker'!$E23:$FA23,1,MATCH(AA$16,'Daily Tracker'!$E$2:$FA$2,0)),0)) -> 3 | AB36: =IF(AB$16="","",IFERROR(INDEX('Daily Tracker'!$E23:$FA23,1,MATCH(AB$16,'Daily Tracker'!$E$2:$FA$2,0)),0)) -> 4 | AC36: =IF(AC$16="","",IFERROR(INDEX('Daily Tracker'!$E23:$FA23,1,MATCH(AC$16,'Daily Tracker'!$E$2:$FA$2,0)),0)) -> 4 | AD36: =IF(AD$16="","",IFERROR(INDEX('Daily Tracker'!$E23:$FA23,1,MATCH(AD$16,'Daily Tracker'!$E$2:$FA$2,0)),0)) -> 1 | ... AJ36: =IF(AJ$16="","",IFERROR(INDEX('Daily Tracker'!$E23:$FA23,1,MATCH(AJ$16,'Daily Tracker'!$E$2:$FA$2,0)),0)) -> 5
A37: Support | B37: =IF('Daily Tracker'!B24="",A37,'Daily Tracker'!B24) -> Support | C37: ='Daily Tracker'!C24 -> Admin | D37: ='Daily Tracker'!D24 -> 4 | E37: =IFERROR(INDEX('Daily Tracker'!$E24:$FA24,1,MATCH($B$4,'Daily Tracker'!$E$2:$FA$2,0)),0) -> 3 | F37: =D37-E37 -> 1 | G37: =IFERROR(E37/D37,0) -> 0.75 | V37: 24 | W37: =IF(W$16="","",IFERROR(INDEX('Daily Tracker'!$E24:$FA24,1,MATCH(W$16,'Daily Tracker'!$E$2:$FA$2,0)),0)) -> 3 | X37: =IF(X$16="","",IFERROR(INDEX('Daily Tracker'!$E24:$FA24,1,MATCH(X$16,'Daily Tracker'!$E$2:$FA$2,0)),0)) -> 3 | Y37: =IF(Y$16="","",IFERROR(INDEX('Daily Tracker'!$E24:$FA24,1,MATCH(Y$16,'Daily Tracker'!$E$2:$FA$2,0)),0)) -> 0 | Z37: =IF(Z$16="","",IFERROR(INDEX('Daily Tracker'!$E24:$FA24,1,MATCH(Z$16,'Daily Tracker'!$E$2:$FA$2,0)),0)) -> 3 | AA37: =IF(AA$16="","",IFERROR(INDEX('Daily Tracker'!$E24:$FA24,1,MATCH(AA$16,'Daily Tracker'!$E$2:$FA$2,0)),0)) -> 1 | AB37: =IF(AB$16="","",IFERROR(INDEX('Daily Tracker'!$E24:$FA24,1,MATCH(AB$16,'Daily Tracker'!$E$2:$FA$2,0)),0)) -> 3 | AC37: =IF(AC$16="","",IFERROR(INDEX('Daily Tracker'!$E24:$FA24,1,MATCH(AC$16,'Daily Tracker'!$E$2:$FA$2,0)),0)) -> 3 | AD37: =IF(AD$16="","",IFERROR(INDEX('Daily Tracker'!$E24:$FA24,1,MATCH(AD$16,'Daily Tracker'!$E$2:$FA$2,0)),0)) -> 3 | ... AJ37: =IF(AJ$16="","",IFERROR(INDEX('Daily Tracker'!$E24:$FA24,1,MATCH(AJ$16,'Daily Tracker'!$E$2:$FA$2,0)),0)) -> 3
A38: Support | B38: =IF('Daily Tracker'!B25="",A38,'Daily Tracker'!B25) -> Support | C38: ='Daily Tracker'!C25 -> Lab | D38: ='Daily Tracker'!D25 -> 1 | E38: =IFERROR(INDEX('Daily Tracker'!$E25:$FA25,1,MATCH($B$4,'Daily Tracker'!$E$2:$FA$2,0)),0) -> 1 | F38: =D38-E38 -> 0 | G38: =IFERROR(E38/D38,0) -> 1 | V38: 25 | W38: =IF(W$16="","",IFERROR(INDEX('Daily Tracker'!$E25:$FA25,1,MATCH(W$16,'Daily Tracker'!$E$2:$FA$2,0)),0)) -> 1 | X38: =IF(X$16="","",IFERROR(INDEX('Daily Tracker'!$E25:$FA25,1,MATCH(X$16,'Daily Tracker'!$E$2:$FA$2,0)),0)) -> 1 | Y38: =IF(Y$16="","",IFERROR(INDEX('Daily Tracker'!$E25:$FA25,1,MATCH(Y$16,'Daily Tracker'!$E$2:$FA$2,0)),0)) -> 0 | Z38: =IF(Z$16="","",IFERROR(INDEX('Daily Tracker'!$E25:$FA25,1,MATCH(Z$16,'Daily Tracker'!$E$2:$FA$2,0)),0)) -> 0 | AA38: =IF(AA$16="","",IFERROR(INDEX('Daily Tracker'!$E25:$FA25,1,MATCH(AA$16,'Daily Tracker'!$E$2:$FA$2,0)),0)) -> 0 | AB38: =IF(AB$16="","",IFERROR(INDEX('Daily Tracker'!$E25:$FA25,1,MATCH(AB$16,'Daily Tracker'!$E$2:$FA$2,0)),0)) -> 1 | AC38: =IF(AC$16="","",IFERROR(INDEX('Daily Tracker'!$E25:$FA25,1,MATCH(AC$16,'Daily Tracker'!$E$2:$FA$2,0)),0)) -> 1 | AD38: =IF(AD$16="","",IFERROR(INDEX('Daily Tracker'!$E25:$FA25,1,MATCH(AD$16,'Daily Tracker'!$E$2:$FA$2,0)),0)) -> 1 | ... AJ38: =IF(AJ$16="","",IFERROR(INDEX('Daily Tracker'!$E25:$FA25,1,MATCH(AJ$16,'Daily Tracker'!$E$2:$FA$2,0)),0)) -> 1
A39: Support | B39: =IF('Daily Tracker'!B26="",A39,'Daily Tracker'!B26) -> Support | C39: ='Daily Tracker'!C26 -> Project | D39: ='Daily Tracker'!D26 -> 2 | E39: =IFERROR(INDEX('Daily Tracker'!$E26:$FA26,1,MATCH($B$4,'Daily Tracker'!$E$2:$FA$2,0)),0) -> 1 | F39: =D39-E39 -> 1 | G39: =IFERROR(E39/D39,0) -> 0.5 | V39: 26 | W39: =IF(W$16="","",IFERROR(INDEX('Daily Tracker'!$E26:$FA26,1,MATCH(W$16,'Daily Tracker'!$E$2:$FA$2,0)),0)) -> 2 | X39: =IF(X$16="","",IFERROR(INDEX('Daily Tracker'!$E26:$FA26,1,MATCH(X$16,'Daily Tracker'!$E$2:$FA$2,0)),0)) -> 2 | Y39: =IF(Y$16="","",IFERROR(INDEX('Daily Tracker'!$E26:$FA26,1,MATCH(Y$16,'Daily Tracker'!$E$2:$FA$2,0)),0)) -> 0 | Z39: =IF(Z$16="","",IFERROR(INDEX('Daily Tracker'!$E26:$FA26,1,MATCH(Z$16,'Daily Tracker'!$E$2:$FA$2,0)),0)) -> 1 | AA39: =IF(AA$16="","",IFERROR(INDEX('Daily Tracker'!$E26:$FA26,1,MATCH(AA$16,'Daily Tracker'!$E$2:$FA$2,0)),0)) -> 0 | AB39: =IF(AB$16="","",IFERROR(INDEX('Daily Tracker'!$E26:$FA26,1,MATCH(AB$16,'Daily Tracker'!$E$2:$FA$2,0)),0)) -> 0 | AC39: =IF(AC$16="","",IFERROR(INDEX('Daily Tracker'!$E26:$FA26,1,MATCH(AC$16,'Daily Tracker'!$E$2:$FA$2,0)),0)) -> 1 | AD39: =IF(AD$16="","",IFERROR(INDEX('Daily Tracker'!$E26:$FA26,1,MATCH(AD$16,'Daily Tracker'!$E$2:$FA$2,0)),0)) -> 0 | ... AJ39: =IF(AJ$16="","",IFERROR(INDEX('Daily Tracker'!$E26:$FA26,1,MATCH(AJ$16,'Daily Tracker'!$E$2:$FA$2,0)),0)) -> 1
A40: Support | B40: =IF('Daily Tracker'!B27="",A40,'Daily Tracker'!B27) -> Support | C40: ='Daily Tracker'!C27 -> Accounts | D40: ='Daily Tracker'!D27 -> 2 | E40: =IFERROR(INDEX('Daily Tracker'!$E27:$FA27,1,MATCH($B$4,'Daily Tracker'!$E$2:$FA$2,0)),0) -> 1 | F40: =D40-E40 -> 1 | G40: =IFERROR(E40/D40,0) -> 0.5 | V40: 27 | W40: =IF(W$16="","",IFERROR(INDEX('Daily Tracker'!$E27:$FA27,1,MATCH(W$16,'Daily Tracker'!$E$2:$FA$2,0)),0)) -> 2 | X40: =IF(X$16="","",IFERROR(INDEX('Daily Tracker'!$E27:$FA27,1,MATCH(X$16,'Daily Tracker'!$E$2:$FA$2,0)),0)) -> 1 | Y40: =IF(Y$16="","",IFERROR(INDEX('Daily Tracker'!$E27:$FA27,1,MATCH(Y$16,'Daily Tracker'!$E$2:$FA$2,0)),0)) -> 0 | Z40: =IF(Z$16="","",IFERROR(INDEX('Daily Tracker'!$E27:$FA27,1,MATCH(Z$16,'Daily Tracker'!$E$2:$FA$2,0)),0)) -> 1 | AA40: =IF(AA$16="","",IFERROR(INDEX('Daily Tracker'!$E27:$FA27,1,MATCH(AA$16,'Daily Tracker'!$E$2:$FA$2,0)),0)) -> 0 | AB40: =IF(AB$16="","",IFERROR(INDEX('Daily Tracker'!$E27:$FA27,1,MATCH(AB$16,'Daily Tracker'!$E$2:$FA$2,0)),0)) -> 2 | AC40: =IF(AC$16="","",IFERROR(INDEX('Daily Tracker'!$E27:$FA27,1,MATCH(AC$16,'Daily Tracker'!$E$2:$FA$2,0)),0)) -> 1 | AD40: =IF(AD$16="","",IFERROR(INDEX('Daily Tracker'!$E27:$FA27,1,MATCH(AD$16,'Daily Tracker'!$E$2:$FA$2,0)),0)) -> 2 | ... AJ40: =IF(AJ$16="","",IFERROR(INDEX('Daily Tracker'!$E27:$FA27,1,MATCH(AJ$16,'Daily Tracker'!$E$2:$FA$2,0)),0)) -> 1
A41: Support | B41: =IF('Daily Tracker'!B28="",A41,'Daily Tracker'!B28) -> Support | C41: ='Daily Tracker'!C28 -> IT | D41: ='Daily Tracker'!D28 -> 2 | E41: =IFERROR(INDEX('Daily Tracker'!$E28:$FA28,1,MATCH($B$4,'Daily Tracker'!$E$2:$FA$2,0)),0) -> 1 | F41: =D41-E41 -> 1 | G41: =IFERROR(E41/D41,0) -> 0.5 | V41: 28 | W41: =IF(W$16="","",IFERROR(INDEX('Daily Tracker'!$E28:$FA28,1,MATCH(W$16,'Daily Tracker'!$E$2:$FA$2,0)),0)) -> 1 | X41: =IF(X$16="","",IFERROR(INDEX('Daily Tracker'!$E28:$FA28,1,MATCH(X$16,'Daily Tracker'!$E$2:$FA$2,0)),0)) -> 0 | Y41: =IF(Y$16="","",IFERROR(INDEX('Daily Tracker'!$E28:$FA28,1,MATCH(Y$16,'Daily Tracker'!$E$2:$FA$2,0)),0)) -> 0 | Z41: =IF(Z$16="","",IFERROR(INDEX('Daily Tracker'!$E28:$FA28,1,MATCH(Z$16,'Daily Tracker'!$E$2:$FA$2,0)),0)) -> 0 | AA41: =IF(AA$16="","",IFERROR(INDEX('Daily Tracker'!$E28:$FA28,1,MATCH(AA$16,'Daily Tracker'!$E$2:$FA$2,0)),0)) -> 0 | AB41: =IF(AB$16="","",IFERROR(INDEX('Daily Tracker'!$E28:$FA28,1,MATCH(AB$16,'Daily Tracker'!$E$2:$FA$2,0)),0)) -> 1 | AC41: =IF(AC$16="","",IFERROR(INDEX('Daily Tracker'!$E28:$FA28,1,MATCH(AC$16,'Daily Tracker'!$E$2:$FA$2,0)),0)) -> 1 | AD41: =IF(AD$16="","",IFERROR(INDEX('Daily Tracker'!$E28:$FA28,1,MATCH(AD$16,'Daily Tracker'!$E$2:$FA$2,0)),0)) -> 2 | ... AJ41: =IF(AJ$16="","",IFERROR(INDEX('Daily Tracker'!$E28:$FA28,1,MATCH(AJ$16,'Daily Tracker'!$E$2:$FA$2,0)),0)) -> 1
...

Sheet Daily Tracker
C1: Over sections: | E1: {=IFERROR(_xlfn.TEXTJOIN(", ",TRUE,IF(#REF!>#REF!,#REF!,"")),"")} | F1: {=IFERROR(_xlfn.TEXTJOIN(", ",TRUE,IF(#REF!>#REF!,#REF!,"")),"")} | G1: {=IFERROR(_xlfn.TEXTJOIN(", ",TRUE,IF(#REF!>#REF!,#REF!,"")),"")} | H1: {=IFERROR(_xlfn.TEXTJOIN(", ",TRUE,IF(#REF!>#REF!,#REF!,"")),"")} | I1: {=IFERROR(_xlfn.TEXTJOIN(", ",TRUE,IF(#REF!>#REF!,#REF!,"")),"")} | J1: {=IFERROR(_xlfn.TEXTJOIN(", ",TRUE,IF(#REF!>#REF!,#REF!,"")),"")} | K1: {=IFERROR(_xlfn.TEXTJOIN(", ",TRUE,IF(#REF!>#REF!,#REF!,"")),"")} | L1: {=IFERROR(_xlfn.TEXTJOIN(", ",TRUE,IF(#REF!>#REF!,#REF!,"")),"")} | ... Q1: {=IFERROR(_xlfn.TEXTJOIN(", ",TRUE,IF(#REF!>#REF!,#REF!,"")),"")} | R1: =IFERROR(_xlfn.TEXTJOIN(", ",TRUE,IF(#REF!>#REF!,#REF!,"")),"") | S1: {=IFERROR(_xlfn.TEXTJOIN(", ",TRUE,IF(#REF!>#REF!,#REF!,"")),"")} | T1: {=IFERROR(_xlfn.TEXTJOIN(", ",TRUE,IF(#REF!>#REF!,#REF!,"")),"")} | U1: {=IFERROR(_xlfn.TEXTJOIN(", ",TRUE,IF(#REF!>#REF!,#REF!,"")),"")} | V1: =IFERROR(_xlfn.TEXTJOIN(", ",TRUE,IF(#REF!>#REF!,#REF!,"")),"") | W1: {=IFERROR(_xlfn.TEXTJOIN(", ",TRUE,IF(#REF!>#REF!,#REF!,"")),"")} | X1: {=IFERROR(_xlfn.TEXTJOIN(", ",TRUE,IF(#REF!>#REF!,#REF!,"")),"")} | Y1: {=IFERROR(_xlfn.TEXTJOIN(", ",TRUE,IF(#REF!>#REF!,#REF!,"")),"")} | Z1: {=IFERROR(_xlfn.TEXTJOIN(", ",TRUE,IF(#REF!>#REF!,#REF!,"")),"")} | AA1: {=IFERROR(_xlfn.TEXTJOIN(", ",TRUE,IF(#REF!>#REF!,#REF!,"")),"")} | AB1: =IFERROR(_xlfn.TEXTJOIN(", ",TRUE,IF(#REF!>#REF!,#REF!,"")),"") | AC1: {=IFERROR(_xlfn.TEXTJOIN(", ",TRUE,IF(#REF!>#REF!,#REF!,"")),"")} | AD1: {=IFERROR(_xlfn.TEXTJOIN(", ",TRUE,IF(#REF!>#REF!,#REF!,"")),"")} | AE1: {=IFERROR(_xlfn.TEXTJOIN(", ",TRUE,IF(#REF!>#REF!,#REF!,"")),"")} | AF1: {=IFERROR(_xlfn.TEXTJOIN(", ",TRUE,IF(#REF!>#REF!,#REF!,"")),"")} | AG1: {=IFERROR(_xlfn.TEXTJOIN(", ",TRUE,IF(#REF!>#REF!,#REF!,"")),"")} | AH1: {=IFERROR(_xlfn.TEXTJOIN(", ",TRUE,IF(#REF!>#REF!,#REF!,"")),"")} | AI1: {=IFERROR(_xlfn.TEXTJOIN(", ",TRUE,IF(#REF!>#REF!,#REF!,"")),"")} | AJ1: {=IFERROR(_xlfn.TEXTJOIN(", ",TRUE,IF(#REF!>#REF!,#REF!,"")),"")} | ... BL1: {=IFERROR(_xlfn.TEXTJOIN(", ",TRUE,IF(#REF!>#REF!,#REF!,"")),"")}
A2: Category | B2: Plant | C2: Section | D2: Plan (MP) | E2: 46174 | F2: =E2+1 -> 46175 | G2: =F2+1 -> 46176 | H2: =G2+1 -> 46177 | I2: =H2+1 -> 46178 | J2: =I2+1 -> 46179 | K2: =J2+1 -> 46180 | L2: =K2+1 -> 46181 | M2: =L2+1 -> 46182 | ... AL2: =AK2+1 -> 46207 | AM2: 46208 | AN2: =AM2+1 -> 46209 | AO2: 46210 | AP2: =AO2+1 -> 46211 | AQ2: =AP2+1 -> 46212 | AR2: =AQ2+1 -> 46213 | AS2: =AR2+1 -> 46214 | AT2: =AS2+1 -> 46215 | AU2: =AT2+1 -> 46216 | AV2: =AU2+1 -> 46217 | AW2: =AV2+1 -> 46218 | ... FA2: =EZ2+1 -> 46326
A3: Production | B3: C6 | C3: =Master!B3 -> C6 - Oil | D3: =Master!C3 -> 14 | E3: 3 | F3: 2 | G3: 3 | H3: 8 | I3: 1 | J3: 13 | L3: 4 | M3: 12 | N3: 6 | O3: 10 | P3: 14 | Q3: 10 | S3: 11 | T3: 12 | U3: 12 | V3: 17 | W3: 20 | X3: 14 | Z3: 20 | AA3: 18 | AB3: 11 | AC3: 12 | AD3: 13 | AE3: 10 | AF3: 12 | AH3: 12 | AI3: 12 | AJ3: 14 | AK3: 11 | AL3: 12 | AN3: 17 | AO3: 18 | AP3: 9 | AQ3: 13 | AR3: 19 | AS3: 19 | AU3: 18 | AV3: 18 | AW3: 17 | AX3: 15 | AY3: 20 | AZ3: 6 | BA3: 4 | BB3: 17 | BC3: 17 | BD3: 13 | BE3: =14 -> 14 | BF3: =13 -> 13 | BG3: =12 -> 12 | BH3: 12 | BI3: 10 | BJ3: 12 | BK3: =12+12 -> 24 | BL3: =12+11 -> 23 | BM3: =12+12 -> 24 | BN3: =24+12 -> 36 | BO3: 13 | BP3: 18 | BQ3: =18+11 -> 29 | BR3: =19+10 -> 29 | BS3: 10 | BT3: =10+9 -> 19 | BU3: =19+10 -> 29 | BV3: =9+10 -> 19 | BW3: 15 | BX3: =17+9 -> 26 | BY3: =3+12 -> 15 | BZ3: =5+10+10 -> 25 | CA3: =17+9 -> 26 | CC3: 11 | CD3: 10 | CE3: =18+13 -> 31 | CF3: =20+15 -> 35 | CG3: =15+14 -> 29 | CH3: =18+15 -> 33 | CI3: =17+13 -> 30 | CJ3: 16 | CK3: 16 | CL3: =15+10 -> 25 | CM3: =14+8 -> 22 | CN3: 11 | CO3: =7+7 -> 14 | CP3: =9+9 -> 18 | CR3: 8 | CS3: =11+8 -> 19 | CT3: =6+7 -> 13 | CU3: 11 | CV3: =11+8 -> 19 | CW3: =12+8 -> 20 | CX3: =12+8 -> 20 | CY3: 9 | CZ3: =10+6 -> 16 | DA3: =10+6 -> 16 | DB3: =12+8 -> 20 | DC3: =12+10 -> 22 | DD3: =10+9 -> 19 | DE3: 9 | DG3: 10 | DH3: =9+9 -> 18 | DI3: 9 | DJ3: =9+8 -> 17 | DK3: =11+10 -> 21 | DL3: 9 | DM3: 11 | DN3: 12 | DO3: 14 | DQ3: 13 | DR3: 13 | DS3: 10 | DT3: 12 | DU3: 10 | DV3: 11 | DW3: 11 | DY3: 12 | EA3: 12 | EB3: 13 | EC3: 14 | ED3: 1 | EE3: 12 | EF3: 9 | EH3: 10 | EI3: 11
B4: Ghee | C4: =Master!B4 -> C6 - Ghee | D4: =Master!C4 -> 24 | E4: =22+8 -> 30 | F4: =24+9 -> 33 | G4: =25+9 -> 34 | H4: =30+9 -> 39 | I4: =27+9 -> 36 | J4: 32 | L4: =20+7 -> 27 | M4: =21+12 -> 33 | N4: =27+12 -> 39 | O4: =22+13 -> 35 | P4: =23+12 -> 35 | Q4: =22+13 -> 35 | R4: =11+8 -> 19 | S4: =22+11 -> 33 | T4: =17+10 -> 27 | U4: =21+13 -> 34 | V4: =21+12 -> 33 | W4: =24+13 -> 37 | X4: =26+13 -> 39 | Y4: =12+10 -> 22 | Z4: 28 | AA4: =19+11 -> 30 | AB4: =22+9 -> 31 | AC4: =25+12 -> 37 | AD4: =21+12 -> 33 | AE4: =25+12 -> 37 | AF4: =13+11 -> 24 | AG4: =8+11 -> 19 | AH4: =24+13 -> 37 | AI4: =22+13 -> 35 | AJ4: =24+12 -> 36 | AK4: =25+13 -> 38 | AL4: =24+13 -> 37 | AM4: =12+9 -> 21 | AN4: =24+14 -> 38 | AO4: =21+15 -> 36 | AP4: =20+9 -> 29 | AQ4: =21+16 -> 37 | AR4: =26+11 -> 37 | AS4: =23+15 -> 38 | AT4: =9+14 -> 23 | AU4: =23+14 -> 37 | AV4: =20+15 -> 35 | AW4: =24+15 -> 39 | AX4: =21+17 -> 38 | AY4: =23+12 -> 35 | AZ4: =21+16 -> 37 | BA4: =12+16 -> 28 | BB4: 26 | BC4: =21+17 -> 38 | BD4: =24+17 -> 41 | BE4: =22+18 -> 40 | BF4: =24+18 -> 42 | BG4: =20+18 -> 38 | BH4: 23 | BI4: =20+10 -> 30 | BJ4: =19+17 -> 36 | BK4: =19+18 -> 37 | BL4: =21+14 -> 35 | BM4: =16+15 -> 31 | BN4: 21 | BO4: =6+11 -> 17 | BP4: =19+14 -> 33 | BQ4: =21+14 -> 35 | BR4: =20+17 -> 37 | BS4: =19+18 -> 37 | BT4: =19+18 -> 37 | BU4: =21+13 -> 34 | BV4: =7+17 -> 24 | BW4: =20+13 -> 33 | BX4: =20+12 -> 32 | BY4: =21+12 -> 33 | BZ4: =23+11 -> 34 | CA4: =22+11 -> 33 | CB4: 13 | CC4: =20+11 -> 31 | CD4: =11+16 -> 27 | CE4: =20+18 -> 38 | CF4: =20+15 -> 35 | CG4: =22+16 -> 38 | CH4: =21+10 -> 31 | CI4: =23+15 -> 38 | CJ4: =11+16 -> 27 | CK4: =19+10 -> 29 | CL4: =17+16 -> 33 | CM4: =19+15 -> 34 | CN4: =21+19 -> 40 | CO4: =17+17 -> 34 | CP4: =20+11 -> 31 | CQ4: =11+14 -> 25 | CR4: =20+10 -> 30 | CS4: =22+15 -> 37 | CT4: =20+16 -> 36 | CU4: =21+15 -> 36 | CV4: =17+18 -> 35 | CW4: =19+15 -> 34 | CX4: =5+18 -> 23 | CY4: =15+11 -> 26 | CZ4: =15+17 -> 32 | DA4: =20+15 -> 35 | DB4: =17+14 -> 31 | DC4: =19+17 -> 36 | DD4: =22+19 -> 41 | DE4: =18+18 -> 36 | DF4: =11+6 -> 17 | DG4: =21+10 -> 31 | DH4: =23+15 -> 38 | DI4: =23+19 -> 42 | DJ4: =19+14 -> 33 | DK4: =19+15 -> 34 | DL4: =11+11 -> 22 | DM4: =19+7 -> 26 | DN4: 21 | DO4: 23 | DP4: 16 | DQ4: 19 | DR4: 19 | DS4: 18 | DT4: 20 | DU4: 17 | DV4: 18 | DW4: 20 | DY4: 19 | DZ4: 9 | EA4: 19 | EB4: 17 | EC4: 16 | ED4: 20 | EE4: 18 | EF4: 13 | EG4: 6 | EH4: 19 | EI4: 21
B5: C39 | C5: =Master!B5 -> C39 - MG batch Making | D5: =Master!C5 -> 7 | E5: 10 | F5: 21 | G5: 11 | H5: 16 | I5: 18 | J5: 14 | L5: 16 | M5: 12 | N5: 12 | O5: 12 | P5: 6 | Q5: 3 | S5: 7 | T5: 0 | U5: 7 | V5: 5 | W5: 9 | X5: 0 | Z5: 0 | AA5: 9 | AB5: 7 | AC5: 6 | AD5: 9 | AE5: 9 | AF5: 9 | AH5: 12 | AI5: 14 | AJ5: 12 | AK5: 13 | AL5: 8 | AN5: 8 | AO5: 12 | AP5: 11 | AQ5: 13 | AR5: 9 | AS5: 9 | AU5: 8 | AV5: 8 | AW5: 11 | AX5: 6 | AY5: 0 | AZ5: 0 | BA5: 0 | BB5: 8 | BC5: 14 | BD5: 13 | BE5: 9 | BF5: 9 | BG5: 9 | BI5: 11 | BJ5: 8 | BK5: 8 | BL5: 9 | BM5: 13 | BN5: 12 | BP5: 17 | BQ5: 12 | BR5: 11 | BT5: 8 | BU5: 9 | BV5: 12 | BW5: 12 | BX5: 14 | BY5: 12 | BZ5: 13 | CA5: 11 | CC5: 0 | CD5: 11 | CE5: 12 | CF5: 14 | CG5: 12 | CH5: 11 | CI5: 13 | CK5: 10 | CL5: 14 | CM5: 9 | CN5: 11 | CO5: 8 | CP5: 7 | CR5: 8 | CS5: 6 | CT5: 11 | CU5: 12 | CV5: 9 | CW5: 11 | CX5: 0 | CY5: 6 | CZ5: 10 | DA5: 11 | DB5: 12 | DC5: 9 | DD5: 10 | DG5: 8 | DH5: 9 | DJ5: 9 | DK5: 10 | DL5: 5 | DM5: 7 | DN5: 10 | DO5: 9 | DQ5: 10 | DR5: 9 | DS5: 0 | DT5: 9 | DU5: 9 | DV5: 9 | DW5: 9 | DY5: 9 | DZ5: 2 | EA5: 10 | EB5: 6 | EC5: 9 | EE5: 10 | EF5: 8 | EH5: 7 | EI5: 8
B6: Supply | C6: =Master!B6 -> Supply/ Dispatch (Common) | D6: =Master!C6 -> 11 | E6: 13 | F6: 17 | G6: 16 | H6: 11 | I6: 13 | J6: 11 | L6: 11 | M6: 11 | N6: 11 | O6: 10 | P6: 11 | Q6: 16 | S6: 13 | T6: 11 | U6: 11 | V6: 12 | W6: 12 | X6: 11 | Z6: 11 | AA6: 11 | AB6: 11 | AC6: 11 | AD6: 11 | AE6: 11 | AF6: 10 | AH6: 11 | AI6: 12 | AJ6: 11 | AK6: 11 | AL6: 11 | AN6: 11 | AO6: 11 | AP6: 11 | AQ6: 10 | AR6: 10 | AS6: 11 | AU6: 11 | AV6: 11 | AW6: 11 | AX6: 11 | AY6: 10 | AZ6: 5 | BA6: 4 | BB6: 11 | BC6: 11 | BD6: 11 | BE6: 11 | BF6: =11+8 -> 19 | BG6: 5 | BH6: 6 | BI6: 11 | BJ6: 10 | BK6: 11 | BL6: 11 | BM6: 9 | BN6: 11 | BO6: 6 | BP6: 11 | BQ6: 10 | BR6: 11 | BS6: 11 | BT6: 11 | BU6: 11 | BV6: 4 | BW6: 10 | BX6: 11 | BY6: 11 | BZ6: 11 | CA6: 11 | CC6: 0 | CD6: 11 | CE6: 10 | CF6: 11 | CG6: 11 | CH6: 10 | CI6: 11 | CK6: 11 | CL6: 11 | CM6: 11 | CN6: 11 | CO6: 11 | CP6: 9 | CR6: 11 | CS6: 11 | CT6: 11 | CU6: 11 | CV6: 12 | CW6: 11 | CX6: 7 | CY6: 12 | CZ6: 11 | DA6: 10 | DB6: 11 | DC6: 11 | DD6: 11 | DG6: 11 | DH6: 11 | DI6: 10 | DJ6: 11 | DK6: 11 | DL6: 4 | DM6: 11 | DN6: 11 | DO6: 12 | DP6: 11 | DQ6: 11 | DR6: 13 | DS6: 11 | DT6: 12 | DU6: 6 | DV6: =7+5 -> 12 | DW6: 11 | DY6: 6 | DZ6: 6 | EA6: 15 | EB6: 15 | EC6: 15 | ED6: 15 | EE6: 15 | EF6: 15 | EG6: 4 | EH6: 15 | EI6: 6
B7: Printer | C7: =Master!B7 -> Printer (Common) | D7: =Master!C7 -> 6 | E7: 6 | F7: 7 | G7: 7 | H7: 7 | I7: 6 | J7: 6 | L7: 5 | M7: 7 | N7: 7 | O7: 6 | P7: 7 | Q7: 6 | S7: 5 | T7: 7 | U7: 6 | V7: 7 | W7: 7 | X7: 7 | Z7: 6 | AA7: 6 | AB7: 5 | AC7: 5 | AD7: 4 | AE7: 7 | AF7: 5 | AH7: 7 | AI7: 7 | AJ7: 6 | AK7: 5 | AL7: 7 | AN7: 7 | AO7: 6 | AP7: 8 | AQ7: 8 | AR7: 7 | AS7: 8 | AU7: 6 | AV7: 7 | AW7: 6 | AX7: 7 | AY7: 7 | AZ7: 1 | BA7: 2 | BB7: 6 | BC7: 6 | BD7: 6 | BE7: 7 | BF7: 6 | BG7: 6 | BI7: 7 | BJ7: =1+6 -> 7 | BK7: 6 | BL7: 5 | BM7: 6 | BN7: 7 | BP7: 7 | BQ7: 7 | BR7: 7 | BS7: 1 | BT7: 6 | BU7: 7 | BV7: 5 | BW7: 7 | BX7: 5 | BY7: 7 | BZ7: 6 | CA7: 8 | CC7: 1 | CD7: 6 | CE7: 8 | CF7: 7 | CG7: 8 | CH7: 9 | CI7: 8 | CK7: 7 | CL7: 7 | CM7: 7 | CN7: 7 | CO7: 7 | CP7: 5 | CR7: 7 | CS7: 7 | CT7: 7 | CU7: 8 | CV7: 7 | CW7: 5 | CY7: 6 | CZ7: 5 | DA7: 7 | DB7: 7 | DC7: 6 | DD7: 7 | DE7: 3 | DG7: 6 | DH7: 8 | DJ7: 7 | DK7: 8 | DL7: 2 | DM7: 7 | DN7: 6 | DO7: 6 | DQ7: 6 | DR7: 5 | DS7: 5 | DT7: 6 | DU7: 6 | DV7: 7 | DW7: 8 | DY7: 7 | DZ7: 3 | EA7: 6 | EB7: 6 | EC7: 5 | ED7: 2 | EE7: 5 | EF7: 4 | EG7: 1 | EH7: 6 | EI7: 8
B8: C6 | C8: =Master!B8 -> C6 - Raw Agri (Millets) | D8: =Master!C8 -> 16 | E8: 13 | F8: 14 | G8: 20 | H8: 16 | I8: 14 | J8: 15 | L8: 12 | M8: 13 | N8: 20 | O8: 17 | P8: 13 | Q8: 14 | S8: 15 | T8: 9 | U8: 14 | V8: 6 | W8: 10 | X8: 11 | Z8: 11 | AA8: 16 | AB8: 20 | AC8: 22 | AD8: 17 | AE8: 16 | AF8: 14 | AH8: 18 | AI8: 17 | AJ8: 16 | AK8: 20 | AL8: 18 | AN8: 9 | AO8: 5 | AP8: 19 | AQ8: 14 | AR8: 12 | AS8: 12 | AU8: 8 | AV8: 10 | AW8: 10 | AX8: 10 | AY8: 5 | AZ8: 3 | BA8: 4 | BB8: 10 | BC8: 13 | BD8: 20 | BE8: 14 | BF8: 13 | BG8: 10 | BI8: 15 | BJ8: 13 | BK8: 12 | BL8: 12 | BM8: 19 | BN8: 21 | BP8: 25 | BQ8: 18 | BR8: 21 | BT8: 20 | BU8: 19 | BV8: 15 | BW8: 21 | BX8: 15 | BY8: 23 | BZ8: 21 | CA8: 23 | CC8: 23 | CD8: 14 | CE8: 26 | CF8: 23 | CG8: 8 | CH8: 18 | CI8: 8 | CK8: 20 | CL8: 16 | CM8: 17 | CN8: 24 | CO8: 9 | CP8: 17 | CR8: 21 | CS8: 15 | CT8: 20 | CU8: 19 | CV8: 22 | CW8: 16 | CY8: 19 | CZ8: 17 | DA8: 19 | DB8: 18 | DC8: 15 | DD8: 17 | DG8: 19 | DH8: 18 | DJ8: 14 | DK8: 15 | DL8: 0 | DM8: 16 | DN8: 18 | DO8: 17 | DQ8: 19 | DR8: 17 | DS8: 12 | DT8: 18 | DU8: 17 | DV8: 18 | DW8: 19 | DY8: 23 | EA8: 18 | EB8: 18 | EC8: 15 | EE8: 14 | EF8: 11 | EG8: 7 | EH8: 21 | EI8: 22
B9: C39 | C9: =Master!B9 -> C39 - Honey / all Spices | D9: =Master!C9 -> 22 | E9: 10 | F9: 7 | G9: 13 | H9: 11 | I9: 8 | J9: 10 | L9: 16 | M9: 7 | N9: 16 | O9: 16 | P9: 21 | Q9: 10 | S9: 10 | T9: 13 | U9: 13 | V9: 12 | W9: 10 | X9: 13 | Z9: 10 | AA9: 9 | AB9: 14 | AC9: 11 | AD9: 16 | AE9: 10 | AF9: 8 | AH9: 6 | AI9: 8 | AJ9: 19 | AK9: 14 | AL9: 10 | AN9: 13 | AO9: 17 | AP9: 14 | AQ9: 13 | AR9: 15 | AS9: 11 | AU9: 10 | AV9: 12 | AW9: 16 | AX9: 14 | AY9: 15 | AZ9: 0 | BA9: 2 | BB9: 19 | BC9: 13 | BD9: =12+22 -> 34 | BE9: 14 | BF9: 11 | BG9: 11 | BI9: 9 | BJ9: 16 | BK9: 17 | BL9: 12 | BM9: 11 | BN9: 16 | BP9: 14 | BQ9: 10 | BR9: 15 | BT9: 10 | BU9: 13 | BV9: 10 | BW9: 9 | BX9: 9 | BY9: 18 | BZ9: 13 | CA9: 13 | CC9: 0 | CD9: 7 | CE9: 11 | CF9: 9 | CG9: 12 | CH9: 15 | CI9: 13 | CK9: 16 | CL9: 15 | CM9: 15 | CN9: 12 | CO9: 12 | CP9: 9 | CR9: 17 | CS9: 16 | CT9: 11 | CU9: 14 | CV9: 9 | CW9: 10 | CY9: 10 | CZ9: 14 | DA9: 17 | DB9: 14 | DC9: 17 | DD9: 15 | DE9: 8 | DG9: 18 | DH9: 15 | DJ9: 11 | DK9: 15 | DL9: 7 | DM9: 14 | DN9: 18 | DO9: 16 | DQ9: 14 | DR9: 14 | DS9: 10 | DT9: 16 | DU9: 18 | DV9: 15 | DW9: 19 | DY9: 18 | EA9: 15 | EB9: 11 | EC9: 16 | EE9: 12 | EF9: 13 | EH9: 16 | EI9: 18
B10: C39 | C10: =Master!B10 -> C39 - Jaggery | D10: =Master!C10 -> 9 | E10: 16 | F10: 18 | G10: 10 | H10: 14 | I10: 12 | J10: 14 | L10: 10 | M10: 16 | N10: 9 | O10: 8 | P10: 0 | Q10: 13 | S10: 14 | T10: 15 | U10: 15 | V10: 15 | W10: 15 | X10: 12 | Z10: 15 | AA10: 13 | AB10: 12 | AC10: 13 | AD10: 8 | AE10: 15 | AF10: 13 | AH10: 17 | AI10: 20 | AJ10: 12 | AK10: 17 | AL10: 19 | AN10: 14 | AO10: 10 | AP10: 15 | AQ10: 16 | AR10: 12 | AS10: 17 | AU10: 16 | AV10: 17 | AW10: 13 | AX10: 15 | AY10: 13 | AZ10: 2 | BA10: 3 | BB10: 15 | BC10: 15 | BD10: 16 | BE10: 14 | BF10: 17 | BG10: 15 | BI10: 13 | BJ10: 11 | BK10: 11 | BL10: 20 | BM10: =16+2 -> 18 | BN10: 14 | BO10: 5 | BP10: 15 | BQ10: 12 | BR10: 14 | BT10: 16 | BU10: 15 | BV10: 14 | BW10: 19 | BX10: 14 | BY10: 10 | BZ10: 17 | CA10: 15 | CC10: 0 | CD10: 14 | CE10: 15 | CF10: 19 | CG10: 15 | CH10: 15 | CI10: 18 | CK10: 15 | CL10: 16 | CM10: 14 | CN10: 16 | CO10: 15 | CP10: 14 | CR10: 11 | CS10: 11 | CT10: 18 | CU10: 15 | CV10: 20 | CY10: 18 | CZ10: 16 | DA10: 17 | DB10: 17 | DC10: 16 | DD10: 19 | DE10: 8 | DG10: 16 | DH10: 14 | DJ10: 9 | DK10: 14 | DL10: 12 | DM10: 13 | DN10: 16 | DO10: 17 | DQ10: 17 | DR10: 19 | DS10: 13 | DT10: 15 | DU10: 15 | DV10: 20 | DW10: 14 | DY10: 15 | DZ10: 15 | EA10: 17 | EB10: 16 | EC10: 15 | EE10: 17 | EF10: 20 | EH10: 19 | EI10: 19
B11: C39 | C11: =Master!B11 -> C39 - Atta | D11: =Master!C11 -> 22 | E11: 29 | F11: 26 | G11: 30 | H11: 29 | I11: 25 | J11: 25 | L11: 25 | M11: 27 | N11: 23 | O11: 22 | P11: 24 | Q11: 18 | S11: 23 | T11: 29 | U11: 30 | V11: 26 | W11: 25 | X11: 9 | Z11: 30 | AA11: 22 | AB11: 26 | AC11: 24 | AD11: 20 | AE11: 18 | AF11: 23 | AG11: 3 | AH11: 26 | AI11: 26 | AJ11: 25 | AK11: 23 | AL11: 27 | AN11: 24 | AO11: 27 | AP11: =27 -> 27 | AQ11: 17 | AR11: 21 | AS11: =29+15 -> 44 | AT11: 9 | AU11: 24 | AV11: =30 -> 30 | AW11: =27 -> 27 | AX11: =33 -> 33 | AY11: =29 -> 29 | AZ11: =4+16 -> 20 | BA11: 16 | BB11: 24 | BC11: =26 -> 26 | BD11: 24 | BE11: =31 -> 31 | BF11: 34 | BG11: 31 | BH11: 9 | BI11: 25 | BJ11: =31 -> 31 | BK11: 26 | BL11: 23 | BM11: 19 | BN11: 28 | BP11: 24 | BQ11: 27 | BR11: 27 | BS11: 17 | BT11: 32 | BU11: 28 | BV11: 19 | BW11: 26 | BX11: 22 | BY11: 25 | BZ11: 21 | CA11: 24 | CC11: 10 | CD11: 22 | CE11: 27 | CF11: 21 | CG11: 21 | CH11: 19 | CI11: 19 | CJ11: 13 | CK11: 19 | CL11: 18 | CM11: 19 | CN11: =18+7 -> 25 | CO11: 18 | CP11: 22 | CQ11: 9 | CR11: 21 | CS11: 25 | CT11: 23 | CU11: 17 | CV11: 18 | CW11: 17 | CX11: 11 | CY11: 22 | CZ11: 12 | DA11: 12 | DB11: 13 | DC11: 16 | DD11: 15 | DE11: 9 | DG11: 8 | DH11: 12 | DI11: 18 | DJ11: 13 | DK11: 14 | DL11: 15 | DM11: 15 | DN11: 11 | DO11: 9 | DP11: 12 | DQ11: 11 | DR11: 13 | DS11: 4 | DT11: 12 | DU11: 12 | DV11: 11 | DW11: 13 | DY11: 14 | DZ11: 13 | EA11: 10 | EB11: 17 | EC11: 10 | ED11: 12 | EE11: 12 | EF11: 10 | EG11: 11 | EH11: 10 | EI11: 9
B12: C6 | C12: =Master!B12 -> C6 - Atta - 1 | D12: =Master!C12 -> 14 | E12: 13 | F12: 8 | G12: 11 | H12: 10 | I12: 4 | J12: 8 | L12: 10 | M12: 10 | N12: 12 | O12: 11 | P12: 13 | Q12: 15 | S12: 14 | T12: 16 | U12: 15 | V12: 11 | W12: 12 | X12: 11 | Z12: 9 | AA12: 9 | AB12: 13 | AC12: 5 | AD12: 10 | AE12: 7 | AF12: 9 | AH12: 8 | AI12: 11 | AJ12: 12 | AK12: 9 | AL12: 11 | AM12: 2 | AN12: 9 | AO12: 8 | AP12: 6 | AQ12: 21 | AR12: 5 | AS12: 2 | AU12: 14 | AV12: 12 | AW12: 8 | AX12: 13 | AY12: 17 | AZ12: 1 | BA12: 7 | BB12: 5 | BC12: 5 | BD12: 0 | BE12: 11 | BF12: 11 | BG12: 9 | BI12: 11 | BJ12: =7+12 -> 19 | BK12: =10+12 -> 22 | BL12: 9 | BM12: =12+12 -> 24 | BN12: 13 | BP12: 12 | BQ12: 14 | BR12: 18 | BT12: 18 | BU12: 20 | BV12: 9 | BW12: 19 | BX12: 11 | BY12: 19 | BZ12: 13 | CA12: 20 | CC12: 0 | CD12: 9 | CE12: 12 | CF12: 11 | CG12: 21 | CH12: 14 | CI12: 15 | CK12: 14 | CL12: 16 | CM12: 14 | CN12: 17 | CO12: 11 | CP12: 11 | CR12: 13 | CS12: 21 | CT12: 19 | CU12: 18 | CV12: 17 | CW12: 15 | CY12: 15 | CZ12: 16 | DA12: 15 | DB12: 20 | DC12: 15 | DD12: 18 | DG12: 15 | DH12: 17 | DI12: 6 | DJ12: 17 | DK12: 18 | DL12: 0 | DM12: 16 | DN12: 18 | DO12: 18 | DQ12: 15 | DR12: 14 | DS12: 12 | DT12: 17 | DU12: 18 | DV12: 16 | DW12: 17 | DY12: 16 | EA12: 17 | EB12: 16 | EC12: 16 | ED12: 12 | EE12: 15 | EF12: 17 | EG12: 14 | EH12: 15 | EI12: 16
